Workbook

Sheet Hoja3
A1: NACIONAL 2026 | E1: Piso | G1: Arzon | I1: Anillos | K1: Salto | M1: Paralelas | O1: Barra Fija | Q1: AA | R1: Porcentaje de efectividad | S1: LUGAR | T1: RUTINAS
A2: NOMBRE | B2: NIVEL | C2: Objetivo | D2: DIF | E2: NP | F2: NF | G2: NP | H2: NF | I2: NP | J2: NF | K2: NP | L2: NF | M2: NP | N2: NF | O2: NP | P2: NF | Q2: TOTAL
E3: DED | F3: % | G3: DED | H3: % | I3: DED | J3: % | K3: DED | L3: % | M3: DED | N3: % | O3: DED | P3: %
A4: YERIK | B4: 7 | C4: 72 | D4: =Q4-C4 -> -7.002 | E4: 12.3 | F4: 11.2 | G4: 12.1 | H4: 10.666 | I4: 12.2 | J4: 11.2 | K4: 12.4 | L4: 10.033 | M4: 12.2 | N4: 11.033 | O4: 12.1 | P4: 10.866 | Q4: =F4+H4+J4+L4+N4+P4 -> 64.998 | R4: =((F5+H5+J5+L5+N5+P5)/6)*0.01 -> 0.8869272 | S4: 1 | T4: LIBRES
E5: =E4-F4 -> 1.1 | F5: =(Hoja2!J45/E4)*F4 -> 91.056911 | G5: =G4-H4 -> 1.434 | H5: =(Hoja2!K45/G4)*H4 -> 88.14876 | I5: =I4-J4 -> 1 | J5: =(Hoja2!L45/I4)*J4 -> 91.803279 | K5: =K4-L4 -> 2.367 | L5: =(Hoja2!M45/K4)*L4 -> 80.91129 | M5: =M4-N4 -> 1.167 | N5: =(Hoja2!N45/M4)*N4 -> 90.434426 | O5: =O4-P4 -> 1.234 | P5: =(Hoja2!O45/O4)*P4 -> 89.801653
A6: MIKEL | B6: 9 | C6: 70 | D6: =Q6-C6 -> -6.635 | E6: 12.8 | F6: 11.2 | G6: 11.9 | H6: 9.7 | I6: 12.8 | J6: 10.733 | K6: 12.8 | L6: 11.133 | M6: 12.3 | N6: 9.966 | O6: 12.3 | P6: 10.633 | Q6: =F6+H6+J6+L6+N6+P6 -> 63.365 | R6: =((F7+L7+N7+P7+H7+J7)/6)*0.01 -> 0.84434508 | S6: 2
E7: =E6-F6 -> 1.6 | F7: =(Hoja2!J40/E6)*F6 -> 87.5 | G7: =G6-H6 -> 2.2 | H7: =(Hoja2!K40/G6)*H6 -> 80.165289 | I7: =I6-J6 -> 2.067 | J7: =(Hoja2!L40/I6)*J6 -> 83.851562 | K7: =K6-L6 -> 1.667 | L7: =(Hoja2!M40/K6)*L6 -> 86.976562 | M7: =M6-N6 -> 2.334 | N7: =(Hoja2!N40/M6)*N6 -> 82.363636 | O7: =O6-P6 -> 1.667 | P7: =(Hoja2!O40/O6)*P6 -> 85.75
A8: RICHIE | B8: 10 | C8: 72 | D8: =Q8-C8 -> -3.402 | E8: 14.2 | F8: 11.933 | G8: 13.8 | H8: 11.233 | I8: 13.1 | J8: 11.366 | K8: 13.6 | L8: 10.933 | M8: 13.2 | N8: 11.1 | O8: 13.5 | P8: 12.033 | Q8: =F8+H8+J8+L8+N8+P8 -> 68.598 | R8: =((F9+H9+J9+L9+N9+P9)/6)*0.01 -> 0.84107319 | S8: 3
E9: =E8-F8 -> 2.267 | F9: =(Hoja2!J38/E8)*F8 -> 82.868056 | G9: =G8-H8 -> 2.567 | H9: =(Hoja2!K38/G8)*H8 -> 81.398551 | I9: =I8-J8 -> 1.734 | J9: =(Hoja2!L38/I8)*J8 -> 86.763359 | K9: =K8-L8 -> 2.667 | L9: =(Hoja2!M38/K8)*L8 -> 80.389706 | M9: =M8-N8 -> 2.1 | N9: =(Hoja2!N38/M8)*N8 -> 84.090909 | O9: =O8-P8 -> 1.467 | P9: =(Hoja2!O38/O8)*P8 -> 89.133333
A10: VELA | B10: 8 | C10: 72 | D10: =Q10-C10 -> -7.068 | E10: 13.3 | F10: 11.866 | G10: 12.6 | H10: 9.9 | I10: 12.8 | J10: 10.5 | K10: 12.4 | L10: 10.8 | M10: 13.2 | N10: 11 | O10: 12.7 | P10: 10.866 | Q10: =F10+H10+J10+L10+N10+P10 -> 64.932 | R10: =((F11+H11+J11+L11+N11+P11)/6)*0.01 -> 0.84004326 | S10: 4
E11: =E10-F10 -> 1.434 | F11: =(Hoja2!J43/E10)*F10 -> 89.218045 | G11: =G10-H10 -> 2.7 | H11: =(Hoja2!K43/G10)*H10 -> 76.153846 | I11: =I10-J10 -> 2.3 | J11: =(Hoja2!L43/I10)*J10 -> 81.395349 | K11: =K10-L10 -> 1.6 | L11: =(Hoja2!M43/K10)*L10 -> 87.096774 | M11: =M10-N10 -> 2.2 | N11: =(Hoja2!N43/M10)*N10 -> 85.271318 | O11: =O10-P10 -> 1.834 | P11: =(Hoja2!O43/O10)*P10 -> 84.890625
A12: DIEGO | B12: 10 | C12: 72 | D12: =Q12-C12 -> -23.368 | E12: 0.1 | F12: 0 | G12: 14.6 | H12: 12.133 | I12: 14.5 | J12: 13.233 | K12: 0.1 | L12: 0 | M12: 14.5 | N12: 12.2 | O12: 14.1 | P12: 11.066 | Q12: =F12+H12+J12+L12+N12+P12 -> 48.632 | R12: =((F13+H13+J13+L13+N13+P13)/4)*0.01 -> 0.82743679 | S12: 5
E13: =E12-F12 -> 0.1 | F13: =(Hoja2!J37/E12)*F12 -> 0 | G13: =G12-H12 -> 2.467 | H13: =(Hoja2!K37/G12)*H12 -> 81.42953 | I13: =I12-J12 -> 1.267 | J13: =(Hoja2!L37/I12)*J12 -> 90.636986 | K13: =K12-L12 -> 0.1 | L13: =(Hoja2!M37/K12)*L12 -> 0 | M13: =M12-N12 -> 2.3 | N13: =(Hoja2!N37/M12)*N12 -> 84.137931 | O13: =O12-P12 -> 3.034 | P13: =(Hoja2!O37/O12)*P12 -> 74.77027
A14: ISAAC | B14: 9 | C14: 70 | D14: =Q14-C14 -> -8.835 | E14: 12.4 | F14: 10.3 | G14: 12 | H14: 9.566 | I14: 12.4 | J14: 10.666 | K14: 12 | L14: 10.3 | M14: 12.2 | N14: 10.9 | O14: 12.6 | P14: 9.433 | Q14: =F14+H14+J14+L14+N14+P14 -> 61.165 | R14: =((F15+L15+N15+P15+H15+J15)/6)*0.01 -> 0.82060819 | S14: 6
E15: =E14-F14 -> 2.1 | F15: =(Hoja2!J42/E14)*F14 -> 82.4 | G15: =G14-H14 -> 2.434 | H15: =(Hoja2!K42/G14)*H14 -> 78.409836 | I15: =I14-J14 -> 1.734 | J15: =(Hoja2!L42/I14)*J14 -> 82.682171 | K15: =K14-L14 -> 1.7 | L15: =(Hoja2!M42/K14)*L14 -> 85.833333 | M15: =M14-N14 -> 1.3 | N15: =(Hoja2!N42/M14)*N14 -> 89.344262 | O15: =O14-P14 -> 3.167 | P15: =(Hoja2!O42/O14)*P14 -> 73.695312
A16: FER | B16: 7 | C16: 68 | D16: =Q16-C16 -> -8.601 | E16: 12.3 | F16: 10.666 | G16: 12.1 | H16: 10.233 | I16: 12.2 | J16: 11.1 | K16: 12.2 | L16: 9 | M16: 12.3 | N16: 9.8 | O16: 12.2 | P16: 8.6 | Q16: =F16+H16+J16+L16+N16+P16 -> 59.399 | R16: =((F17+L17+N17+P17+H17+J17)/6)*0.01 -> 0.80581568 | S16: 7
E17: =E16-F16 -> 1.634 | F17: =(Hoja2!J44/E16)*F16 -> 86.016129 | G17: =G16-H16 -> 1.867 | H17: =(Hoja2!K44/G16)*H16 -> 83.195122 | I17: =I16-J16 -> 1.1 | J17: =(Hoja2!L44/I16)*J16 -> 90.983607 | K17: =K16-L16 -> 3.2 | L17: =(Hoja2!M44/K16)*L16 -> 73.770492 | M17: =M16-N16 -> 2.5 | N17: =(Hoja2!N44/M16)*N16 -> 79.032258 | O17: =O16-P16 -> 3.6 | P17: =(Hoja2!O44/O16)*P16 -> 70.491803
A18: ALONSO | B18: 10 | C18: 72 | D18: =Q18-C18 -> -10.835 | E18: 14.2 | F18: 11.7 | G18: 8.4 | H18: 5.433 | I18: 12.5 | J18: 10.666 | K18: 13.6 | L18: 11.733 | M18: 13 | N18: 10.733 | O18: 13 | P18: 10.9 | Q18: =F18+H18+J18+L18+N18+P18 -> 61.165 | R18: =((F19+L19+J19+N19+P19+H19)/6)*0.01 -> 0.80234396 | S18: 8
E19: =E18-F18 -> 2.5 | F19: =(Hoja2!J39/E18)*F18 -> 81.818182 | G19: =G18-H18 -> 2.967 | H19: =(Hoja2!J39/G18)*H18 -> 64.226274 | I19: =I18-J18 -> 1.834 | J19: =(Hoja2!L39/I18)*J18 -> 82.682171 | K19: =K18-L18 -> 1.867 | L19: =(Hoja2!M39/K18)*L18 -> 86.272059 | M19: =M18-N18 -> 2.267 | N19: =(Hoja2!N39/M18)*N18 -> 82.561538 | O19: =O18-P18 -> 2.1 | P19: =(Hoja2!O39/O18)*P18 -> 83.846154
A20: CHAMPI | B20: 9 | C20: 70 | D20: =Q20-C20 -> -70 | E20: 0.1 | F20: 0 | G20: 0.1 | H20: 0 | I20: 0.1 | J20: 0 | K20: 0.1 | L20: 0 | M20: 0.1 | N20: 0 | O20: 0.1 | P20: 0 | Q20: =F20+H20+J20+L20+N20+P20 -> 0 | R20: =((F21+L21+N21+P21+J21+H21)/6)*0.01 -> 0
E21: =E20-F20 -> 0.1 | F21: =(Hoja2!J42/E20)*F20 -> 0 | G21: =G20-H20 -> 0.1 | H21: =(Hoja2!K42/G20)*H20 -> 0 | I21: =I20-J20 -> 0.1 | J21: =(Hoja2!L42/I20)*J20 -> 0 | K21: =K20-L20 -> 0.1 | L21: =(Hoja2!M42/K20)*L20 -> 0 | M21: =M20-N20 -> 0.1 | N21: =(Hoja2!N42/M20)*N20 -> 0 | O21: =O20-P20 -> 0.1 | P21: =(Hoja2!O42/O20)*P20 -> 0
A23: LEITO | B23: 4 | C23: 54 | D23: =Q23-C23 -> -0.502 | E23: 10 | F23: 8.966 | G23: 9.9 | H23: 8.8 | I23: 10 | J23: 9.066 | K23: 9.9 | L23: 8.733 | M23: 9.9 | N23: 9.033 | O23: 9.7 | P23: 8.9 | Q23: =F23+H23+J23+L23+N23+P23 -> 53.498 | R23: =((F24+H24+J24+L24+N24+P24)/6)*0.01 -> 0.89163333 | S23: 1 | T23: OBLIGATORIOS
E24: =E23-F23 -> 1.034 | F24: =((E23*10)/E23)*F23 -> 89.66 | G24: =G23-H23 -> 1.1 | H24: =((G23*10)/G23)*H23 -> 88 | I24: =I23-J23 -> 0.934 | J24: =((I23*10)/I23)*J23 -> 90.66 | K24: =K23-L23 -> 1.167 | L24: =((K23*10)/K23)*L23 -> 87.33 | M24: =M23-N23 -> 0.867 | N24: =((M23*10)/M23)*N23 -> 90.33 | O24: =O23-P23 -> 0.8 | P24: =((O23*10)/O23)*P23 -> 89
A25: CHAVEZ | B25: 4 | C25: 54 | D25: =Q25-C25 -> -1.234 | E25: 9.6 | F25: 8.233 | G25: 9.9 | H25: 8.933 | I25: 10 | J25: 8.533 | K25: 10 | L25: 9.3 | M25: 9.6 | N25: 8.767 | O25: 9.9 | P25: 9 | Q25: =F25+H25+J25+L25+N25+P25 -> 52.766 | R25: =((F26+H26+J26+L26+N26+P26)/6)*0.01 -> 0.87943333 | S25: 2
E26: =E25-F25 -> 1.367 | F26: =((E25*10)/E25)*F25 -> 82.33 | G26: =G25-H25 -> 0.967 | H26: =((G25*10)/G25)*H25 -> 89.33 | I26: =I25-J25 -> 1.467 | J26: =((I25*10)/I25)*J25 -> 85.33 | K26: =K25-L25 -> 0.7 | L26: =((K25*10)/K25)*L25 -> 93 | M26: =M25-N25 -> 0.833 | N26: =((M25*10)/M25)*N25 -> 87.67 | O26: =O25-P25 -> 0.9 | P26: =((O25*10)/O25)*P25 -> 90
A27: NIQUITO | B27: 4 | C27: 54 | D27: =Q27-C27 -> -1.868 | E27: 10 | F27: 8.966 | G27: 9.6 | H27: 8.4 | I27: 10 | J27: 8.666 | K27: 9.9 | L27: 8.8 | M27: 10 | N27: 8.9 | O27: 9.6 | P27: 8.4 | Q27: =F27+H27+J27+L27+N27+P27 -> 52.132 | R27: =((F28+H28+J28+L28+N28+P28)/6)*0.01 -> 0.86886667 | S27: 3
E28: =E27-F27 -> 1.034 | F28: =((E27*10)/E27)*F27 -> 89.66 | G28: =G27-H27 -> 1.2 | H28: =((G27*10)/G27)*H27 -> 84 | I28: =I27-J27 -> 1.334 | J28: =((I27*10)/I27)*J27 -> 86.66 | K28: =K27-L27 -> 1.1 | L28: =((K27*10)/K27)*L27 -> 88 | M28: =M27-N27 -> 1.1 | N28: =((M27*10)/M27)*N27 -> 89 | O28: =O27-P27 -> 1.2 | P28: =((O27*10)/O27)*P27 -> 84
A29: SANTI POWER | B29: 4 | C29: 54 | D29: =Q29-C29 -> -2.101 | E29: 9.9 | F29: 8.466 | G29: 9.6 | H29: 8.333 | I29: 9.9 | J29: 8.566 | K29: 9.9 | L29: 8.966 | M29: 9.9 | N29: 8.534 | O29: 10 | P29: 9.034 | Q29: =F29+H29+J29+L29+N29+P29 -> 51.899 | R29: =((F30+H30+J30+L30+N30+P30)/6)*0.01 -> 0.86498333 | S29: 4
E30: =E29-F29 -> 1.434 | F30: =((E29*10)/E29)*F29 -> 84.66 | G30: =G29-H29 -> 1.267 | H30: =((G29*10)/G29)*H29 -> 83.33 | I30: =I29-J29 -> 1.334 | J30: =((I29*10)/I29)*J29 -> 85.66 | K30: =K29-L29 -> 0.934 | L30: =((K29*10)/K29)*L29 -> 89.66 | M30: =M29-N29 -> 1.366 | N30: =((M29*10)/M29)*N29 -> 85.34 | O30: =O29-P29 -> 0.966 | P30: =((O29*10)/O29)*P29 -> 90.34
A31: CHEMA | B31: 4 | C31: 54 | D31: =Q31-C31 -> -2.802 | E31: 9.7 | F31: 8.433 | G31: 9.7 | H31: 8.433 | I31: 9.7 | J31: 8.3 | K31: 9.9 | L31: 8.966 | M31: 9.4 | N31: 8.266 | O31: 10 | P31: 8.8 | Q31: =F31+H31+J31+L31+N31+P31 -> 51.198 | R31: =((F32+H32+J32+L32+N32+P32)/6)*0.01 -> 0.8533 | S31: 5
E32: =E31-F31 -> 1.267 | F32: =((E31*10)/E31)*F31 -> 84.33 | G32: =G31-H31 -> 1.267 | H32: =((G31*10)/G31)*H31 -> 84.33 | I32: =I31-J31 -> 1.4 | J32: =((I31*10)/I31)*J31 -> 83 | K32: =K31-L31 -> 0.934 | L32: =((K31*10)/K31)*L31 -> 89.66 | M32: =M31-N31 -> 1.134 | N32: =((M31*10)/M31)*N31 -> 82.66 | O32: =O31-P31 -> 1.2 | P32: =((O31*10)/O31)*P31 -> 88
A33: ALFRED | B33: 4 | C33: 54 | D33: =Q33-C33 -> -3.002 | E33: 9.3 | F33: 7.866 | G33: 10 | H33: 9.2 | I33: 9.9 | J33: 8.7 | K33: 9.9 | L33: 9.266 | M33: 9.4 | N33: 8.366 | O33: 10 | P33: 7.6 | Q33: =F33+H33+J33+L33+N33+P33 -> 50.998 | R33: =((F34+H34+J34+L34+N34+P34)/6)*0.01 -> 0.84996667 | S33: 6
E34: =E33-F33 -> 1.434 | F34: =((E33*10)/E33)*F33 -> 78.66 | G34: =G33-H33 -> 0.8 | H34: =((G33*10)/G33)*H33 -> 92 | I34: =I33-J33 -> 1.2 | J34: =((I33*10)/I33)*J33 -> 87 | K34: =K33-L33 -> 0.634 | L34: =((K33*10)/K33)*L33 -> 92.66 | M34: =M33-N33 -> 1.034 | N34: =((M33*10)/M33)*N33 -> 83.66 | O34: =O33-P33 -> 2.4 | P34: =((O33*10)/O33)*P33 -> 76
A35: CHARLY | B35: 4 | C35: 54 | D35: =Q35-C35 -> -3.101 | E35: 9.4 | F35: 7.8 | G35: 9.6 | H35: 8.633 | I35: 9.7 | J35: 8.4 | K35: 9.9 | L35: 8.533 | M35: 9.7 | N35: 8.833 | O35: 9.9 | P35: 8.7 | Q35: =F35+H35+J35+L35+N35+P35 -> 50.899 | R35: =((F36+H36+J36+L36+N36+P36)/6)*0.01 -> 0.84831667 | S35: 7
E36: =E35-F35 -> 1.6 | F36: =((E35*10)/E35)*F35 -> 78 | G36: =G35-H35 -> 0.967 | H36: =((G35*10)/G35)*H35 -> 86.33 | I36: =I35-J35 -> 1.3 | J36: =((I35*10)/I35)*J35 -> 84 | K36: =K35-L35 -> 1.367 | L36: =((K35*10)/K35)*L35 -> 85.33 | M36: =M35-N35 -> 0.867 | N36: =((M35*10)/M35)*N35 -> 88.33 | O36: =O35-P35 -> 1.2 | P36: =((O35*10)/O35)*P35 -> 87
A37: NICO CAPI | B37: 5 | C37: 54 | D37: =Q37-C37 -> -3.771 | E37: 9.6 | F37: 7.466 | G37: 10 | H37: 9.066 | I37: 9.6 | J37: 8.334 | K37: 9.9 | L37: 9.13 | M37: 9.3 | N37: 8.2 | O37: 9.3 | P37: 8.033 | Q37: =F37+H37+J37+L37+N37+P37 -> 50.229 | R37: =((F38+H38+J38+L38+N38+P38)/6)*0.01 -> 0.83715 | S37: 8
E38: =E37-F37 -> 2.134 | F38: =((E37*10)/E37)*F37 -> 74.66 | G38: =G37-H37 -> 0.934 | H38: =((G37*10)/G37)*H37 -> 90.66 | I38: =I37-J37 -> 1.266 | J38: =((I37*10)/I37)*J37 -> 83.34 | K38: =K37-L37 -> 0.77 | L38: =((K37*10)/K37)*L37 -> 91.3 | M38: =M37-N37 -> 1.1 | N38: =((M37*10)/M37)*N37 -> 82 | O38: =O37-P37 -> 1.267 | P38: =((O37*10)/O37)*P37 -> 80.33
A39: EMI | B39: 4 | C39: 54 | D39: =Q39-C39 -> -3.802 | E39: 9.9 | F39: 8.466 | G39: 10 | H39: 8.7 | I39: 10 | J39: 8.566 | K39: 9.9 | L39: 8.533 | M39: 9.3 | N39: 8.033 | O39: 9.6 | P39: 7.9 | Q39: =F39+H39+J39+L39+N39+P39 -> 50.198 | R39: =((F40+H40+J40+L40+N40+P40)/6)*0.01 -> 0.83663333 | S39: 9
E40: =E39-F39 -> 1.434 | F40: =((E39*10)/E39)*F39 -> 84.66 | G40: =G39-H39 -> 1.3 | H40: =((G39*10)/G39)*H39 -> 87 | I40: =I39-J39 -> 1.434 | J40: =((I39*10)/I39)*J39 -> 85.66 | K40: =K39-L39 -> 1.367 | L40: =((K39*10)/K39)*L39 -> 85.33 | M40: =M39-N39 -> 1.267 | N40: =((M39*10)/M39)*N39 -> 80.33 | O40: =O39-P39 -> 1.7 | P40: =((O39*10)/O39)*P39 -> 79
A41: CUEVAS | B41: 4 | C41: 54 | D41: =Q41-C41 -> -4.536 | E41: 9.6 | F41: 7.4 | G41: 9.6 | H41: 8.633 | I41: 9.9 | J41: 8.366 | K41: 9.9 | L41: 8.833 | M41: 9.3 | N41: 8.066 | O41: 9.6 | P41: 8.166 | Q41: =F41+H41+J41+L41+N41+P41 -> 49.464 | R41: =((F42+H42+J42+L42+N42+P42)/6)*0.01 -> 0.8244 | S41: 10
...

Sheet Hoja2
A1: ATLETA | B1: EVENTO | C1: NIVEL | D1: CAT | E1: Piso | F1: Arzon | G1: Anillos | H1: Salto | I1: Paralelas | J1: Barra Fija | K1: AA
A2: =Hoja3!A29 -> SANTI POWER | B2: =Hoja3!A1 -> NACIONAL 2026 | C2: 4 | D2: A | E2: =Hoja3!F29 -> 8.466 | F2: =Hoja3!H29 -> 8.333 | G2: =Hoja3!J29 -> 8.566 | H2: =Hoja3!L29 -> 8.966 | I2: =Hoja3!N29 -> 8.534 | J2: =Hoja3!P29 -> 9.034 | K2: =SUM(E2:J2) -> 51.899
A3: =Hoja3!A47 -> DAVID | B3: =Hoja3!A1 -> NACIONAL 2026 | C3: 4 | D3: B | E3: =Hoja3!F47 -> 7.533 | F3: =Hoja3!H47 -> 8.066 | G3: =Hoja3!J47 -> 8.133 | H3: =Hoja3!L47 -> 8.733 | I3: =Hoja3!N47 -> 7.733 | J3: =Hoja3!P47 -> 8.133 | K3: =SUM(E3:J3) -> 48.331
A4: =Hoja3!A39 -> EMI | B4: =Hoja3!A1 -> NACIONAL 2026 | C4: 4 | D4: B | E4: =Hoja3!F39 -> 8.466 | F4: =Hoja3!H39 -> 8.7 | G4: =Hoja3!J39 -> 8.566 | H4: =Hoja3!L39 -> 8.533 | I4: =Hoja3!N39 -> 8.033 | J4: =Hoja3!P39 -> 7.9 | K4: =SUM(E4:J4) -> 50.198
A5: =Hoja3!A23 -> LEITO | B5: =Hoja3!A1 -> NACIONAL 2026 | C5: 4 | D5: B | E5: =Hoja3!F23 -> 8.966 | F5: =Hoja3!H23 -> 8.8 | G5: =Hoja3!J23 -> 9.066 | H5: =Hoja3!L23 -> 8.733 | I5: =Hoja3!N23 -> 9.033 | J5: =Hoja3!P23 -> 8.9 | K5: =SUM(E5:J5) -> 53.498
A6: =Hoja3!A27 -> NIQUITO | B6: =Hoja3!A1 -> NACIONAL 2026 | C6: 4 | D6: B | E6: =Hoja3!F27 -> 8.966 | F6: =Hoja3!H27 -> 8.4 | G6: =Hoja3!J27 -> 8.666 | H6: =Hoja3!L27 -> 8.8 | I6: =Hoja3!N27 -> 8.9 | J6: =Hoja3!P27 -> 8.4 | K6: =SUM(E6:J6) -> 52.132
A7: =Hoja3!A41 -> CUEVAS | B7: =Hoja3!A1 -> NACIONAL 2026 | C7: 4 | D7: B | E7: =Hoja3!F41 -> 7.4 | F7: =Hoja3!H41 -> 8.633 | G7: =Hoja3!J41 -> 8.366 | H7: =Hoja3!L41 -> 8.833 | I7: =Hoja3!N41 -> 8.066 | J7: =Hoja3!P41 -> 8.166 | K7: =SUM(E7:J7) -> 49.464
A8: =Hoja3!A35 -> CHARLY | B8: =Hoja3!A1 -> NACIONAL 2026 | C8: 4 | D8: B | E8: =Hoja3!F35 -> 7.8 | F8: =Hoja3!H35 -> 8.633 | G8: =Hoja3!J35 -> 8.4 | H8: =Hoja3!L35 -> 8.533 | I8: =Hoja3!N35 -> 8.833 | J8: =Hoja3!P35 -> 8.7 | K8: =SUM(E8:J8) -> 50.899
A9: =Hoja3!A59 -> BRUNO BAEZ | B9: =Hoja3!A1 -> NACIONAL 2026 | C9: 4 | D9: C | E9: =Hoja3!F59 -> 0 | F9: =Hoja3!H59 -> 0 | G9: =Hoja3!J59 -> 0 | H9: =Hoja3!L59 -> 0 | I9: =Hoja3!N59 -> 0 | J9: =Hoja3!P59 -> 0 | K9: =SUM(E9:J9) -> 0
A10: =Hoja3!A31 -> CHEMA | B10: =Hoja3!A1 -> NACIONAL 2026 | C10: 4 | D10: C | E10: =Hoja3!F31 -> 8.433 | F10: =Hoja3!H31 -> 8.433 | G10: =Hoja3!J31 -> 8.3 | H10: =Hoja3!L31 -> 8.966 | I10: =Hoja3!N31 -> 8.266 | J10: =Hoja3!P31 -> 8.8 | K10: =SUM(E10:J10) -> 51.198
A11: =Hoja3!A33 -> ALFRED | B11: =Hoja3!A1 -> NACIONAL 2026 | C11: 4 | D11: C | E11: =Hoja3!F33 -> 7.866 | F11: =Hoja3!H33 -> 9.2 | G11: =Hoja3!J33 -> 8.7 | H11: =Hoja3!L33 -> 9.266 | I11: =Hoja3!N33 -> 8.366 | J11: =Hoja3!P33 -> 7.6 | K11: =SUM(E11:J11) -> 50.998
A12: =Hoja3!A43 -> MAURO | B12: =Hoja3!A1 -> NACIONAL 2026 | C12: 4 | D12: D | E12: =Hoja3!F43 -> 7.766 | F12: =Hoja3!H43 -> 8.6 | G12: =Hoja3!J43 -> 7.867 | H12: =Hoja3!L43 -> 8.6 | I12: =Hoja3!N43 -> 7.934 | J12: =Hoja3!P43 -> 8.666 | K12: =SUM(E12:J12) -> 49.433
A13: =Hoja3!A25 -> CHAVEZ | B13: =Hoja3!A1 -> NACIONAL 2026 | C13: 4 | D13: D | E13: =Hoja3!F25 -> 8.233 | F13: =Hoja3!H25 -> 8.933 | G13: =Hoja3!J25 -> 8.533 | H13: =Hoja3!L25 -> 9.3 | I13: =Hoja3!N25 -> 8.767 | J13: =Hoja3!P25 -> 9 | K13: =SUM(E13:J13) -> 52.766
A14: =Hoja3!A57 -> PATO | B14: =Hoja3!A1 -> NACIONAL 2026 | C14: 5 | D14: C | E14: =Hoja3!F57 -> 0 | F14: =Hoja3!H57 -> 0 | G14: =Hoja3!J57 -> 0 | H14: =Hoja3!L57 -> 0 | I14: =Hoja3!N57 -> 0 | J14: =Hoja3!P57 -> 0 | K14: =SUM(E14:J14) -> 0
A15: =Hoja3!A45 -> BRUNITO | B15: =Hoja3!A1 -> NACIONAL 2026 | C15: 5 | D15: A | E15: =Hoja3!F45 -> 7.866 | F15: =Hoja3!H45 -> 8.866 | G15: =Hoja3!J45 -> 8.034 | H15: =Hoja3!L45 -> 8.033 | I15: =Hoja3!N45 -> 8.9 | J15: =Hoja3!P45 -> 7.5 | K15: =SUM(E15:J15) -> 49.199
A16: =Hoja3!A37 -> NICO CAPI | B16: =Hoja3!A1 -> NACIONAL 2026 | C16: 5 | D16: B | E16: =Hoja3!F37 -> 7.466 | F16: =Hoja3!H37 -> 9.066 | G16: =Hoja3!J37 -> 8.334 | H16: =Hoja3!L37 -> 9.13 | I16: =Hoja3!N37 -> 8.2 | J16: =Hoja3!P37 -> 8.033 | K16: =SUM(E16:J16) -> 50.229
A17: =Hoja3!A49 -> BRITTAN | B17: =Hoja3!A1 -> NACIONAL 2026 | C17: 5 | D17: C | E17: =Hoja3!F49 -> 7.8 | F17: =Hoja3!H49 -> 7.666 | G17: =Hoja3!J49 -> 7.5 | H17: =Hoja3!L49 -> 8.266 | I17: =Hoja3!N49 -> 8.066 | J17: =Hoja3!P49 -> 7.1 | K17: =SUM(E17:J17) -> 46.398
A18: =Hoja3!A55 -> MARIO | B18: =Hoja3!A1 -> NACIONAL 2026 | C18: 6 | D18: A | E18: =Hoja3!F55 -> 7.433 | F18: =Hoja3!H55 -> 6.033 | G18: =Hoja3!J55 -> 6.8 | H18: =Hoja3!L55 -> 8.2 | I18: =Hoja3!N55 -> 6.166 | J18: =Hoja3!P55 -> 7.03 | K18: =SUM(E18:J18) -> 41.662
A19: =Hoja3!A51 -> SANTI LEE | B19: =Hoja3!A1 -> NACIONAL 2026 | C19: 6 | D19: B | E19: =Hoja3!F51 -> 6.834 | F19: =Hoja3!H51 -> 8.6 | G19: =Hoja3!J51 -> 7.95 | H19: =Hoja3!L51 -> 8.64 | I19: =Hoja3!N51 -> 7.4 | J19: =Hoja3!P51 -> 6.733 | K19: =SUM(E19:J19) -> 46.157
A20: =Hoja3!A53 -> MAX | B20: =Hoja3!A1 -> NACIONAL 2026 | C20: 6 | D20: B | E20: =Hoja3!F53 -> 7.44 | F20: =Hoja3!H53 -> 6.166 | G20: =Hoja3!J53 -> 7.5 | H20: =Hoja3!L53 -> 8.7 | I20: =Hoja3!N53 -> 6.866 | J20: =Hoja3!P53 -> 6.4 | K20: =SUM(E20:J20) -> 43.072
A21: =Hoja3!A4 -> YERIK | B21: =Hoja3!A1 -> NACIONAL 2026 | C21: 7 | D21: B | E21: =Hoja3!F4 -> 11.2 | F21: =Hoja3!H4 -> 10.666 | G21: =Hoja3!J4 -> 11.2 | H21: =Hoja3!L4 -> 10.033 | I21: =Hoja3!N4 -> 11.033 | J21: =Hoja3!P4 -> 10.866 | K21: =SUM(E21:J21) -> 64.998
A22: =Hoja3!A16 -> FER | B22: =Hoja3!A1 -> NACIONAL 2026 | C22: 7 | D22: B | E22: =Hoja3!F16 -> 10.666 | F22: =Hoja3!H16 -> 10.233 | G22: =Hoja3!J16 -> 11.1 | H22: =Hoja3!L16 -> 9 | I22: =Hoja3!N16 -> 9.8 | J22: =Hoja3!P16 -> 8.6 | K22: =SUM(E22:J22) -> 59.399
A23: =Hoja3!A10 -> VELA | B23: =Hoja3!A1 -> NACIONAL 2026 | C23: 8 | D23: A | E23: =Hoja3!F10 -> 11.866 | F23: =Hoja3!H10 -> 9.9 | G23: =Hoja3!J10 -> 10.5 | H23: =Hoja3!L10 -> 10.8 | I23: =Hoja3!N10 -> 11 | J23: =Hoja3!P10 -> 10.866 | K23: =SUM(E23:J23) -> 64.932
A24: =Hoja3!A14 -> ISAAC | B24: =Hoja3!A1 -> NACIONAL 2026 | C24: 9 | D24: A | E24: =Hoja3!F14 -> 10.3 | F24: =Hoja3!H14 -> 9.566 | G24: =Hoja3!J14 -> 10.666 | H24: =Hoja3!L14 -> 10.3 | I24: =Hoja3!N14 -> 10.9 | J24: =Hoja3!P14 -> 9.433 | K24: =SUM(E24:J24) -> 61.165
A25: =Hoja3!A20 -> CHAMPI | B25: =Hoja3!A1 -> NACIONAL 2026 | C25: 9 | D25: A | E25: =Hoja3!F20 -> 0 | F25: =Hoja3!H20 -> 0 | G25: =Hoja3!J20 -> 0 | H25: =Hoja3!L20 -> 0 | I25: =Hoja3!N20 -> 0 | J25: =Hoja3!P20 -> 0 | K25: =SUM(E25:J25) -> 0
A26: =Hoja3!A6 -> MIKEL | B26: =Hoja3!A1 -> NACIONAL 2026 | C26: 9 | D26: A | E26: =Hoja3!F6 -> 11.2 | F26: =Hoja3!H6 -> 9.7 | G26: =Hoja3!J6 -> 10.733 | H26: =Hoja3!L6 -> 11.133 | I26: =Hoja3!N6 -> 9.966 | J26: =Hoja3!P6 -> 10.633 | K26: =SUM(E26:J26) -> 63.365
A27: =Hoja3!A18 -> ALONSO | B27: =Hoja3!A1 -> NACIONAL 2026 | C27: 10 | D27: A | E27: =Hoja3!F18 -> 11.7 | F27: =Hoja3!H18 -> 5.433 | G27: =Hoja3!J18 -> 10.666 | H27: =Hoja3!L18 -> 11.733 | I27: =Hoja3!N18 -> 10.733 | J27: =Hoja3!P18 -> 10.9 | K27: =SUM(E27:J27) -> 61.165
A28: =Hoja3!A8 -> RICHIE | B28: =Hoja3!A1 -> NACIONAL 2026 | C28: 10 | D28: A | E28: =Hoja3!F8 -> 11.933 | F28: =Hoja3!H8 -> 11.233 | G28: =Hoja3!J8 -> 11.366 | H28: =Hoja3!L8 -> 10.933 | I28: =Hoja3!N8 -> 11.1 | J28: =Hoja3!P8 -> 12.033 | K28: =SUM(E28:J28) -> 68.598
A29: =Hoja3!A12 -> DIEGO | B29: =Hoja3!A1 -> NACIONAL 2026 | C29: 10 | D29: A | E29: =Hoja3!F12 -> 0 | F29: =Hoja3!H12 -> 12.133 | G29: =Hoja3!J12 -> 13.233 | H29: =Hoja3!L12 -> 0 | I29: =Hoja3!N12 -> 12.2 | J29: =Hoja3!P12 -> 11.066 | K29: =SUM(E29:J29) -> 48.632
B36: NOTAS DE PARTIDA DESEADAS | J36: PORCENTAJE OBTENIDO
B37: {=[1]NP!$A$2:$H$11} -> DIEGO J | C37: 15 | D37: 14.9 | E37: 14.6 | F37: 13.8 | G37: 14.5 | H37: 14.8 | I37: 78.8 | J37: =(100/C37)*Hoja3!E12 -> 0.66666667 | K37: =(100/D37)*Hoja3!G12 -> 97.986577 | L37: =(100/E37)*Hoja3!I12 -> 99.315068 | M37: =(100/F37)*Hoja3!K12 -> 0.72463768 | N37: =(100/G37)*Hoja3!M12 -> 100 | O37: =(100/H37)*Hoja3!O12 -> 95.27027
B38: RICHIE | C38: 14.4 | D38: 13.8 | E38: 13.1 | F38: 13.6 | G38: 13.2 | H38: 13.5 | I38: 72.8 | J38: =(100/C38)*Hoja3!E8 -> 98.611111 | K38: =(100/D38)*Hoja3!G8 -> 100 | L38: =(100/E38)*Hoja3!I8 -> 100 | M38: =(100/F38)*Hoja3!K8 -> 100 | N38: =(100/G38)*Hoja3!M8 -> 100 | O38: =(100/H38)*Hoja3!O8 -> 100
B39: ALONSO | C39: 14.3 | D39: 11.6 | E39: 12.9 | F39: 13.6 | G39: 13 | H39: 13 | I39: 69.6 | J39: =(100/C39)*Hoja3!E18 -> 99.300699 | K39: =(100/D39)*Hoja3!G18 -> 72.413793 | L39: =(100/E39)*Hoja3!I18 -> 96.899225 | M39: =(100/F39)*Hoja3!K18 -> 100 | N39: =(100/G39)*Hoja3!M18 -> 100 | O39: =(100/H39)*Hoja3!O18 -> 100
B40: MIKEL | C40: 12.8 | D40: 12.1 | E40: 12.8 | F40: 12.8 | G40: 12.1 | H40: 12.4 | I40: 66.2 | J40: =(100/C40)*Hoja3!E6 -> 100 | K40: =(100/D40)*Hoja3!G6 -> 98.347107 | L40: =(100/E40)*Hoja3!I6 -> 100 | M40: =(100/F40)*Hoja3!K6 -> 100 | N40: =(100/G40)*Hoja3!M6 -> 101.65289 | O40: =(100/H40)*Hoja3!O6 -> 99.193548
B41: CHAMPI | C41: 13.4 | D41: 11.8 | E41: 12.5 | F41: 11.8 | G41: 12.2 | H41: 13 | I41: 65.9 | J41: =(100/C41)*Hoja3!E20 -> 0.74626866 | K41: =(100/D41)*Hoja3!G20 -> 0.84745763 | L41: =(100/E41)*Hoja3!I20 -> 0.8 | M41: =(100/F41)*Hoja3!K20 -> 0.84745763 | N41: =(100/G41)*Hoja3!M20 -> 0.81967213 | O41: =(100/H41)*Hoja3!O20 -> 0.76923077
B42: ISAAC | C42: 12.5 | D42: 12.2 | E42: 12.9 | F42: 12 | G42: 12.2 | H42: 12.8 | I42: 65.8 | J42: =(100/C42)*Hoja3!E14 -> 99.2 | K42: =(100/D42)*Hoja3!G14 -> 98.360656 | L42: =(100/E42)*Hoja3!I14 -> 96.124031 | M42: =(100/F42)*Hoja3!K14 -> 100 | N42: =(100/G42)*Hoja3!M14 -> 100 | O42: =(100/H42)*Hoja3!O14 -> 98.4375
B43: VELA | C43: 13.3 | D43: 13 | E43: 12.9 | F43: 12.4 | G43: 12.9 | H43: 12.8 | I43: 68.5 | J43: =(100/C43)*Hoja3!E10 -> 100 | K43: =(100/D43)*Hoja3!G10 -> 96.923077 | L43: =(100/E43)*Hoja3!I10 -> 99.224806 | M43: =(100/F43)*Hoja3!K10 -> 100 | N43: =(100/G43)*Hoja3!M10 -> 102.32558 | O43: =(100/H43)*Hoja3!O10 -> 99.21875
B44: FER | C44: 12.4 | D44: 12.3 | E44: 12.2 | F44: 12.2 | G44: 12.4 | H44: 12.2 | I44: 67.7 | J44: =(100/C44)*Hoja3!E16 -> 99.193548 | K44: =(100/D44)*Hoja3!G16 -> 98.373984 | L44: =(100/E44)*Hoja3!I16 -> 100 | M44: =(100/F44)*Hoja3!K16 -> 100 | N44: =(100/G44)*Hoja3!M16 -> 99.193548 | O44: =(100/H44)*Hoja3!O16 -> 100
B45: YERIK | C45: 12.3 | D45: 12.1 | E45: 12.2 | F45: 12.4 | G45: 12.2 | H45: 12.1 | I45: 67.3 | J45: =(100/C45)*Hoja3!E4 -> 100 | K45: =(100/D45)*Hoja3!G4 -> 100 | L45: =(100/E45)*Hoja3!I4 -> 100 | M45: =(100/F45)*Hoja3!K4 -> 100 | N45: =(100/G45)*Hoja3!M4 -> 100 | O45: =(100/H45)*Hoja3!O4 -> 100
B46: 0 | C46: 0 | D46: 0 | E46: 0 | F46: 0 | G46: 0 | H46: 0 | I46: 0
