Workbook

Sheet NORMATIVOS
B1: Consolidado = 🟩 Proyeccion = 🟦 En Proceso = 🟨 No Adquirido = 🟥 | C1: Diego Jaime | D1: Ricardo Jimenez | E1: Alonso Ahedo | F1: Mikel Larrinua | G1: Diego Rodriguez | H1: Isaac Martinez | I1: Diego Vela | J1: Yerik Guerra | K1: Fernando Talavera | L1: Diego Chavez | M1: Mario Bisteni | N1: Maximiliano Diaz | O1: Santiago Sigler | P1: Nicolas Capitanacci | Q1: Bruno Jacobo | R1: Santi Camacho | S1: Leo Camacho | T1: Nico Flores | U1: Carlos Aznar | V1: Emi Gonzalez | W1: David Rangel | X1: Diego Cuevas | Y1: Jose Ma Robles | Z1: Mauro Regand | AA1: Bruno Baez | AB1: Brittan Akim | AC1: Alfredo Jacobo | AD1: Erik Lopez | AE1: Leo Lazaro | AF1: Isaac Rangel
A2: PISO
A3: POSICIONES BÁSICAS Y FUERZA | B3: Postura de pie firme | C3: Consolidado | D3: Consolidado | E3: Consolidado | F3: Consolidado | G3: Consolidado | H3: Consolidado | I3: Consolidado | J3: Consolidado | K3: Consolidado | L3: Consolidado | M3: Consolidado | N3: Consolidado | O3: Consolidado | P3: Consolidado | Q3: Consolidado | R3: Consolidado | S3: Consolidado | T3: Consolidado | U3: Consolidado | V3: Consolidado | W3: Consolidado | X3: Consolidado | Y3: Consolidado | Z3: Consolidado | AA3: Consolidado | AB3: Consolidado | AC3: Consolidado | AD3: Consolidado | AE3: Consolidado | AF3: En proceso | AG3: Nivel 3 | AH3: Nivel 4 | AI3: Nivel 5 | AJ3: Nivel 6 | AK3: Nivel 7 | AL3: Nivel 8 | AM3: Nivel 9 | AN3: Nivel 10 Jr | AO3: Nivel 10 FIG
B4: Parado de hombros | C4: Consolidado | D4: Consolidado | E4: Consolidado | F4: Consolidado | G4: Consolidado | H4: Consolidado | I4: Consolidado | J4: Consolidado | K4: Consolidado | L4: Consolidado | M4: Consolidado | N4: Consolidado | O4: Consolidado | P4: Consolidado | Q4: Consolidado | R4: Consolidado | S4: Consolidado | T4: Consolidado | U4: Consolidado | V4: Consolidado | W4: Consolidado | X4: Consolidado | Y4: Consolidado | Z4: Consolidado | AA4: Consolidado | AB4: Consolidado | AC4: Consolidado | AD4: Consolidado | AE4: Consolidado | AF4: En proceso
B5: Parado de antebrazos | C5: Consolidado | D5: Consolidado | E5: Consolidado | F5: Consolidado | G5: Consolidado | H5: Consolidado | I5: Consolidado | J5: Consolidado | K5: Consolidado | L5: Consolidado | M5: Consolidado | N5: Consolidado | O5: Consolidado | P5: Consolidado | Q5: Consolidado | R5: Consolidado | S5: Consolidado | T5: Consolidado | U5: Consolidado | V5: Consolidado | W5: Consolidado | X5: Consolidado | Y5: Consolidado | Z5: Consolidado | AA5: Consolidado | AB5: Consolidado | AC5: Consolidado | AD5: Consolidado | AE5: Consolidado | AF5: En proceso
B6: Parado de cabeza | C6: Consolidado | D6: Consolidado | E6: Consolidado | F6: Consolidado | G6: Consolidado | H6: Consolidado | I6: Consolidado | J6: Consolidado | K6: Consolidado | L6: Consolidado | M6: Consolidado | N6: Consolidado | O6: Consolidado | P6: Consolidado | Q6: Consolidado | R6: Consolidado | S6: Consolidado | T6: Consolidado | U6: Consolidado | V6: Consolidado | W6: Consolidado | X6: Consolidado | Y6: Consolidado | Z6: Consolidado | AA6: Consolidado | AB6: Consolidado | AC6: Consolidado | AD6: Consolidado | AE6: Consolidado | AF6: En proceso
B7: Parado de manos en apoyo | C7: Consolidado | D7: Consolidado | E7: Consolidado | F7: Consolidado | G7: Consolidado | H7: Consolidado | I7: Consolidado | J7: Consolidado | K7: Consolidado | L7: Consolidado | M7: Consolidado | N7: Consolidado | O7: Consolidado | P7: Consolidado | Q7: Consolidado | R7: Consolidado | S7: Consolidado | T7: Consolidado | U7: Consolidado | V7: Consolidado | W7: Consolidado | X7: Consolidado | Y7: Consolidado | Z7: Consolidado | AA7: Consolidado | AB7: Consolidado | AC7: Consolidado | AD7: Consolidado | AE7: Consolidado | AF7: Consolidado
B8: Parado de Manos | C8: Consolidado | D8: Consolidado | E8: Consolidado | F8: Consolidado | G8: Consolidado | H8: Consolidado | I8: Consolidado | J8: Consolidado | K8: Consolidado | L8: Consolidado | M8: Consolidado | N8: Consolidado | O8: Consolidado | P8: Consolidado | Q8: Consolidado | R8: Consolidado | S8: Consolidado | T8: Consolidado | U8: Consolidado | V8: Consolidado | W8: Consolidado | X8: Consolidado | Y8: Consolidado | Z8: Consolidado | AA8: Consolidado | AB8: Consolidado | AC8: Consolidado | AD8: En proceso | AE8: En proceso | AF8: En proceso
B9: Split | C9: Consolidado | D9: Consolidado | E9: En proceso | F9: En proceso | G9: Consolidado | H9: En proceso | I9: Consolidado | J9: Consolidado | K9: N/A | L9: N/A | M9: En proceso | N9: En proceso | O9: En proceso | P9: En proceso | Q9: En proceso | R9: En proceso | S9: En proceso | T9: En proceso | U9: En proceso | V9: En proceso | W9: En proceso | X9: En proceso | Y9: En proceso | Z9: En proceso | AA9: En proceso | AB9: En proceso | AC9: En proceso | AD9: En proceso | AE9: En proceso | AF9: En proceso
B10: Squat | C10: Consolidado | D10: Consolidado | E10: En proceso | F10: En proceso | G10: Consolidado | H10: En proceso | I10: Consolidado | J10: Consolidado | K10: N/A | L10: N/A | M10: En proceso | N10: En proceso | O10: En proceso | P10: En proceso | Q10: En proceso | R10: En proceso | S10: En proceso | T10: En proceso | U10: En proceso | V10: En proceso | W10: En proceso | X10: En proceso | Y10: En proceso | Z10: En proceso | AA10: En proceso | AB10: En proceso | AC10: En proceso | AD10: En proceso | AE10: En proceso | AF10: En proceso
B11: Equilibrio a un pie (arabesca) | C11: Consolidado | D11: Consolidado | E11: Consolidado | F11: Consolidado | G11: Consolidado | H11: Consolidado | I11: Consolidado | J11: Consolidado | K11: Consolidado | L11: Consolidado | M11: Consolidado | N11: Consolidado | O11: Consolidado | P11: Consolidado | Q11: En proceso | R11: En proceso | S11: En proceso | T11: En proceso | U11: En proceso | V11: En proceso | W11: En proceso | X11: En proceso | Y11: En proceso | Z11: En proceso | AA11: En proceso | AB11: En proceso | AC11: En proceso | AD11: Proyección | AE11: Proyección | AF11: Proyección
B12: L sit | C12: Consolidado | D12: Consolidado | E12: Consolidado | F12: Consolidado | G12: Consolidado | H12: Consolidado | I12: Consolidado | J12: Consolidado | K12: Consolidado | L12: En proceso | M12: En proceso | N12: En proceso | O12: En proceso | P12: En proceso | Q12: Consolidado | R12: Consolidado | S12: Consolidado | T12: Consolidado | U12: En proceso | V12: Consolidado | W12: Consolidado | X12: En proceso | Y12: En proceso | Z12: En proceso | AA12: En proceso | AB12: Consolidado | AC12: En proceso | AD12: En proceso | AE12: En proceso | AF12: En proceso
B13: Sustentación en Arco | C13: Consolidado | D13: Consolidado | E13: En proceso | F13: En proceso | G13: Consolidado | H13: Consolidado | I13: Consolidado | J13: Consolidado | K13: N/A | L13: N/A | M13: En proceso | N13: En proceso | O13: En proceso | P13: En proceso | Q13: Consolidado | R13: Consolidado | S13: Consolidado | T13: Consolidado | U13: En proceso | V13: Consolidado | W13: Consolidado | X13: En proceso | Y13: En proceso | Z13: En proceso | AA13: En proceso | AB13: Consolidado | AC13: En proceso | AD13: En proceso | AE13: En proceso | AF13: En proceso
B14: Soporte en escuadra endo | C14: Consolidado | D14: Consolidado | E14: En proceso | F14: Consolidado | G14: Consolidado | H14: Consolidado | I14: Consolidado | J14: Consolidado | K14: En proceso | L14: En proceso | M14: En proceso | N14: En proceso | O14: Consolidado | P14: En proceso | Q14: Consolidado | R14: En proceso | S14: Consolidado | T14: Consolidado | U14: En proceso | V14: Consolidado | W14: En proceso | X14: Consolidado | Y14: En proceso | Z14: En proceso | AA14: En proceso | AB14: Consolidado | AC14: En proceso | AD14: En proceso | AE14: En proceso | AF14: En proceso
B15: Kato de fuerza | C15: Consolidado | D15: Consolidado | E15: En proceso | F15: Consolidado | G15: Consolidado | H15: Consolidado | I15: Consolidado | J15: Consolidado | K15: En proceso | L15: En proceso | M15: Consolidado | N15: En proceso | O15: En proceso | P15: En proceso | Q15: Consolidado | R15: En proceso | S15: Consolidado | T15: Consolidado | U15: En proceso | V15: Consolidado | W15: En proceso | X15: En proceso | Y15: En proceso | Z15: En proceso | AA15: En proceso | AB15: En proceso | AC15: En proceso | AD15: En proceso | AE15: En proceso | AF15: En proceso
B16: Rodada Kato | C16: Consolidado | D16: Consolidado | E16: En proceso | F16: Consolidado | G16: Consolidado | H16: En proceso | I16: Consolidado | J16: En proceso | K16: En proceso | L16: En proceso | M16: Consolidado | N16: En proceso | O16: En proceso | P16: En proceso | Q16: Consolidado | R16: En proceso | S16: En proceso | T16: En proceso | U16: En proceso | V16: En proceso | W16: En proceso | X16: En proceso | Y16: En proceso | Z16: En proceso | AA16: En proceso | AB16: En proceso | AC16: En proceso | AD16: En proceso | AE16: Proyección | AF16: Proyección
A17: ACROBATICO HACÍA DELANTE | B17: Rodada adelanté | C17: Consolidado | D17: Consolidado | E17: Consolidado | F17: Consolidado | G17: Consolidado | H17: Consolidado | I17: Consolidado | J17: Consolidado | K17: Consolidado | L17: Consolidado | M17: Consolidado | N17: Consolidado | O17: Consolidado | P17: Consolidado | Q17: Consolidado | R17: Consolidado | S17: Consolidado | T17: Consolidado | U17: Consolidado | V17: Consolidado | W17: Consolidado | X17: Consolidado | Y17: Consolidado | Z17: Consolidado | AA17: Consolidado | AB17: Consolidado | AC17: Consolidado | AD17: Consolidado | AE17: Consolidado | AF17: Consolidado | AG17: Nivel 3 | AH17: Nivel 4 | AI17: Nivel 5 | AJ17: Nivel 6 | AK17: Nivel 7 | AL17: Nivel 8 | AM17: Nivel 9 | AN17: Nivel 10 Jr | AO17: Nivel 10 FIG
B18: Vuelta de carro | C18: Consolidado | D18: Consolidado | E18: Consolidado | F18: Consolidado | G18: Consolidado | H18: Consolidado | I18: Consolidado | J18: Consolidado | K18: Consolidado | L18: Consolidado | M18: Consolidado | N18: Consolidado | O18: Consolidado | P18: Consolidado | Q18: Consolidado | R18: Consolidado | S18: Consolidado | T18: Consolidado | U18: Consolidado | V18: Consolidado | W18: Consolidado | X18: Consolidado | Y18: Consolidado | Z18: Consolidado | AA18: Consolidado | AB18: Consolidado | AC18: Consolidado | AD18: Consolidado | AE18: Consolidado | AF18: En proceso
B19: Redondilla | C19: Consolidado | D19: Consolidado | E19: Consolidado | F19: Consolidado | G19: Consolidado | H19: Consolidado | I19: Consolidado | J19: Consolidado | K19: Consolidado | L19: Consolidado | M19: Consolidado | N19: Consolidado | O19: Consolidado | P19: Consolidado | Q19: Consolidado | R19: Consolidado | S19: Consolidado | T19: Consolidado | U19: Consolidado | V19: Consolidado | W19: Consolidado | X19: Consolidado | Y19: Consolidado | Z19: Consolidado | AA19: Consolidado | AB19: Consolidado | AC19: Consolidado | AD19: Consolidado | AE19: En proceso | AF19: En proceso
B20: Resorte a 2 pies | C20: Consolidado | D20: Consolidado | E20: Consolidado | F20: Consolidado | G20: Consolidado | H20: Consolidado | I20: Consolidado | J20: Consolidado | K20: Consolidado | L20: Consolidado | M20: Consolidado | N20: Consolidado | O20: Consolidado | P20: Consolidado | Q20: Consolidado | R20: Consolidado | S20: Consolidado | T20: Consolidado | U20: Consolidado | V20: Consolidado | W20: Consolidado | X20: Consolidado | Y20: Consolidado | Z20: Consolidado | AA20: Consolidado | AB20: Consolidado | AC20: Consolidado | AD20: En proceso | AE20: En proceso | AF20: Proyección
B21: Resorte a 1 pie | C21: Consolidado | D21: Consolidado | E21: Consolidado | F21: Consolidado | G21: Consolidado | H21: Consolidado | I21: Consolidado | J21: Consolidado | K21: Consolidado | L21: Consolidado | M21: Consolidado | N21: Consolidado | O21: Consolidado | P21: Consolidado | Q21: Consolidado | R21: Consolidado | S21: Consolidado | T21: Consolidado | U21: Consolidado | V21: Consolidado | W21: Consolidado | X21: Consolidado | Y21: Consolidado | Z21: Consolidado | AA21: Consolidado | AB21: Consolidado | AC21: Consolidado | AD21: En proceso | AE21: Proyección | AF21: Proyección
B22: Mortal adelante en C | C22: Consolidado | D22: Consolidado | E22: Consolidado | F22: Consolidado | G22: Consolidado | H22: Consolidado | I22: Consolidado | J22: Consolidado | K22: Consolidado | L22: Consolidado | M22: Consolidado | N22: Consolidado | O22: Consolidado | P22: Consolidado | Q22: Consolidado | R22: Consolidado | S22: En proceso | T22: En proceso | U22: Consolidado | V22: Consolidado | W22: Consolidado | X22: En proceso | Y22: Consolidado | Z22: En proceso | AA22: Consolidado | AB22: Consolidado | AC22: En proceso | AD22: En proceso | AE22: Proyección | AF22: Proyección
B23: Resorte 1 a 2 | C23: Consolidado | D23: Consolidado | E23: Consolidado | F23: Consolidado | G23: Consolidado | H23: En proceso | I23: Consolidado | J23: Consolidado | K23: Consolidado | L23: Consolidado | M23: Consolidado | N23: Consolidado | O23: En proceso | P23: En proceso | Q23: En proceso | R23: En proceso | S23: En proceso | T23: En proceso | U23: En proceso | V23: En proceso | W23: En proceso | X23: En proceso | Y23: En proceso | Z23: En proceso | AA23: En proceso | AB23: En proceso | AC23: En proceso | AD23: Proyección | AE23: Proyección | AF23: Proyección
B24: Mortal adelante en V | C24: Consolidado | D24: Consolidado | E24: Consolidado | F24: Consolidado | G24: Consolidado | H24: Consolidado | I24: Consolidado | J24: Consolidado | K24: Consolidado | L24: Consolidado | M24: Consolidado | N24: Consolidado | O24: En proceso | P24: En proceso | Q24: En proceso | R24: En proceso | S24: En proceso | T24: En proceso | U24: En proceso | V24: En proceso | W24: En proceso | X24: En proceso | Y24: En proceso | Z24: En proceso | AA24: En proceso | AB24: En proceso | AC24: En proceso | AD24: En proceso | AE24: Proyección | AF24: Proyección
B25: Mortal extendido | C25: Consolidado | D25: Consolidado | E25: Consolidado | F25: Consolidado | G25: Consolidado | H25: En proceso | I25: Consolidado | J25: Consolidado | K25: Consolidado | L25: Consolidado | M25: En proceso | N25: En proceso | O25: En proceso | P25: En proceso | Q25: En proceso | R25: Proyección | S25: Proyección | T25: Proyección | U25: Proyección | V25: Proyección | W25: Proyección | X25: Proyección | Y25: En proceso | Z25: Proyección | AA25: Proyección | AB25: Proyección | AC25: Proyección | AD25: Proyección | AE25: Proyección | AF25: Proyección
B26: Mortal rebote mortal | C26: Consolidado | D26: Consolidado | E26: Consolidado | F26: Consolidado | G26: Consolidado | H26: En proceso | I26: En proceso | J26: En proceso | K26: Consolidado | L26: Consolidado | M26: En proceso | N26: En proceso | O26: Proyección | P26: En proceso | Q26: Proyección | R26: Proyección | S26: Proyección | T26: Proyección | U26: Proyección | V26: Proyección | W26: Proyección | X26: Proyección | Y26: Proyección | Z26: Proyección | AA26: Proyección | AB26: Proyección | AC26: Proyección | AD26: Proyección | AE26: Proyección | AF26: Proyección
B27: Doble mortal en C adelanté | C27: Consolidado | D27: Consolidado | E27: Consolidado | F27: En proceso | G27: En proceso | H27: Proyección | I27: Proyección | J27: Proyección | K27: Proyección | L27: Proyección | M27: Proyección | N27: Proyección | O27: Proyección | P27: Proyección | Q27: Proyección | R27: Proyección | S27: Proyección | T27: Proyección | U27: Proyección | V27: Proyección | W27: Proyección | X27: Proyección | Y27: Proyección | Z27: Proyección | AA27: Proyección | AB27: Proyección | AC27: Proyección | AD27: Proyección | AE27: Proyección | AF27: Proyección
A28: ACROBATICO HACÍA ATRÁS | B28: Rodada atras | C28: Consolidado | D28: Consolidado | E28: Consolidado | F28: Consolidado | G28: Consolidado | H28: Consolidado | I28: Consolidado | J28: Consolidado | K28: Consolidado | L28: Consolidado | M28: Consolidado | N28: Consolidado | O28: Consolidado | P28: Consolidado | Q28: Consolidado | R28: Consolidado | S28: Consolidado | T28: Consolidado | U28: Consolidado | V28: Consolidado | W28: Consolidado | X28: Consolidado | Y28: Consolidado | Z28: Consolidado | AA28: Consolidado | AB28: Consolidado | AC28: Consolidado | AD28: Consolidado | AE28: Consolidado | AF28: Consolidado | AG28: Nivel 3 | AH28: Nivel 4 | AI28: Nivel 5 | AJ28: Nivel 6 | AK28: Nivel 7 | AL28: Nivel 8 | AM28: Nivel 9 | AN28: Nivel 10 Jr | AO28: Nivel 10 FIG
B29: Rodada atrás a parado de manos | C29: Consolidado | D29: Consolidado | E29: Consolidado | F29: Consolidado | G29: Consolidado | H29: Consolidado | I29: Consolidado | J29: Consolidado | K29: Consolidado | L29: Consolidado | M29: Consolidado | N29: Consolidado | O29: Consolidado | P29: Consolidado | Q29: Consolidado | R29: Consolidado | S29: Consolidado | T29: Consolidado | U29: Consolidado | V29: Consolidado | W29: Consolidado | X29: Consolidado | Y29: Consolidado | Z29: Consolidado | AA29: Consolidado | AB29: Consolidado | AC29: Consolidado | AD29: En proceso | AE29: En proceso | AF29: En proceso
B30: Flic flac | C30: Consolidado | D30: Consolidado | E30: Consolidado | F30: Consolidado | G30: Consolidado | H30: Consolidado | I30: Consolidado | J30: Consolidado | K30: Consolidado | L30: Consolidado | M30: Consolidado | N30: Consolidado | O30: Consolidado | P30: Consolidado | Q30: Consolidado | R30: Consolidado | S30: Consolidado | T30: Consolidado | U30: Consolidado | V30: Consolidado | W30: Consolidado | X30: Consolidado | Y30: Consolidado | Z30: Consolidado | AA30: Consolidado | AB30: Consolidado | AC30: Consolidado | AD30: En proceso | AE30: Proyección | AF30: Proyección
B31: Doble flic | C31: Consolidado | D31: Consolidado | E31: Consolidado | F31: Consolidado | G31: Consolidado | H31: Consolidado | I31: Consolidado | J31: Consolidado | K31: Consolidado | L31: Consolidado | M31: Consolidado | N31: Consolidado | O31: Consolidado | P31: Consolidado | Q31: Consolidado | R31: Consolidado | S31: Consolidado | T31: Consolidado | U31: Consolidado | V31: Consolidado | W31: Consolidado | X31: Consolidado | Y31: Consolidado | Z31: Consolidado | AA31: Consolidado | AB31: Consolidado | AC31: Consolidado | AD31: Proyección | AE31: Proyección | AF31: Proyección
B32: Mortal atras en C desde Redondilla | C32: Consolidado | D32: Consolidado | E32: Consolidado | F32: Consolidado | G32: Consolidado | H32: Consolidado | I32: Consolidado | J32: Consolidado | K32: Consolidado | L32: Consolidado | M32: Consolidado | N32: Consolidado | O32: Consolidado | P32: Consolidado | Q32: Consolidado | R32: Consolidado | S32: En proceso | T32: En proceso | U32: Consolidado | V32: Consolidado | W32: En proceso | X32: En proceso | Y32: Consolidado | Z32: Consolidado | AA32: Consolidado | AB32: Consolidado | AC32: En proceso | AD32: Proyección | AE32: Proyección | AF32: Proyección
B33: Mortal atras en C desde Flic flac | C33: Consolidado | D33: Consolidado | E33: Consolidado | F33: Consolidado | G33: Consolidado | H33: Consolidado | I33: Consolidado | J33: Consolidado | K33: Consolidado | L33: Consolidado | M33: Consolidado | N33: Consolidado | O33: Consolidado | P33: Consolidado | Q33: Consolidado | R33: Consolidado | S33: En proceso | T33: En proceso | U33: En proceso | V33: Consolidado | W33: En proceso | X33: En proceso | Y33: Consolidado | Z33: En proceso | AA33: En proceso | AB33: Consolidado | AC33: En proceso | AD33: Proyección | AE33: Proyección | AF33: Proyección
B34: Mortal en V atras | C34: Consolidado | D34: Consolidado | E34: Consolidado | F34: Consolidado | G34: Consolidado | H34: Consolidado | I34: Consolidado | J34: Consolidado | K34: Consolidado | L34: Consolidado | M34: Consolidado | N34: Consolidado | O34: En proceso | P34: En proceso | Q34: En proceso | R34: Proyección | S34: Proyección | T34: Proyección | U34: Proyección | V34: Proyección | W34: Proyección | X34: Proyección | Y34: En proceso | Z34: Proyección | AA34: Proyección | AB34: En proceso | AC34: Proyección | AD34: Proyección | AE34: Proyección | AF34: Proyección
B35: Mortal extendido atras | C35: Consolidado | D35: Consolidado | E35: Consolidado | F35: Consolidado | G35: Consolidado | H35: Consolidado | I35: Consolidado | J35: Consolidado | K35: Consolidado | L35: Consolidado | M35: Consolidado | N35: Consolidado | O35: En proceso | P35: En proceso | Q35: En proceso | R35: Proyección | S35: Proyección | T35: Proyección | U35: Proyección | V35: Proyección | W35: Proyección | X35: Proyección | Y35: En proceso | Z35: Proyección | AA35: Proyección | AB35: En proceso | AC35: Proyección | AD35: Proyección | AE35: Proyección | AF35: Proyección
B36: Power flic (Tempo) | C36: Consolidado | D36: Consolidado | E36: Consolidado | F36: N/A | G36: N/A | H36: N/A | I36: Consolidado | J36: N/A | K36: N/A | L36: Proyección | M36: En proceso | N36: En proceso | O36: Proyección | P36: Proyección | Q36: En proceso | R36: Proyección | S36: Proyección | T36: Proyección | U36: Proyección | V36: Proyección | W36: Proyección | X36: Proyección | Y36: Proyección | Z36: Proyección | AA36: Proyección | AB36: Proyección | AC36: Proyección | AD36: Proyección | AE36: Proyección | AF36: Proyección
B37: Doble mortal atrás en C | C37: Consolidado | D37: Consolidado | E37: Consolidado | F37: Consolidado | G37: En proceso | H37: En proceso | I37: En proceso | J37: En proceso | K37: En proceso | L37: Proyección | M37: Proyección | N37: Proyección | O37: Proyección | P37: Proyección | Q37: Proyección | R37: Proyección | S37: Proyección | T37: Proyección | U37: Proyección | V37: Proyección | W37: Proyección | X37: Proyección | Y37: Proyección | Z37: Proyección | AA37: Proyección | AB37: Proyección | AC37: Proyección | AD37: Proyección | AE37: Proyección | AF37: Proyección
A38: ACROBATICO CON GIRO | B38: Mortal extendido atras con 1/2 giro | C38: Consolidado | D38: Consolidado | E38: Consolidado | F38: Consolidado | G38: Consolidado | H38: N/A | I38: Consolidado | J38: Consolidado | K38: Consolidado | L38: En proceso | M38: Consolidado | N38: Consolidado | O38: En proceso | P38: En proceso | Q38: En proceso | R38: Proyección | S38: Proyección | T38: Proyección | U38: Proyección | V38: Proyección | W38: Proyección | X38: Proyección | Y38: Proyección | Z38: Proyección | AA38: Proyección | AB38: Proyección | AC38: Proyección | AD38: Proyección | AE38: Proyección | AF38: Proyección | AJ38: Nivel 6 | AK38: Nivel 7 | AL38: Nivel 8 | AM38: Nivel 9 | AN38: Nivel 10 Jr | AO38: Nivel 10 FIG
B39: Mortal extendido atras con un giro | C39: Consolidado | D39: Consolidado | E39: Consolidado | F39: Consolidado | G39: Consolidado | H39: Consolidado | I39: Consolidado | J39: Consolidado | K39: Consolidado | L39: En proceso | M39: Consolidado | N39: Consolidado | O39: En proceso | P39: En proceso | Q39: En proceso | R39: Proyección | S39: Proyección | T39: Proyección | U39: Proyección | V39: Proyección | W39: Proyección | X39: Proyección | Y39: Proyección | Z39: Proyección | AA39: Proyección | AB39: Proyección | AC39: Proyección | AD39: Proyección | AE39: Proyección | AF39: Proyección
B40: Mortal agrupado adelanté con 1/2 giro | C40: Consolidado | D40: Consolidado | E40: Consolidado | F40: Consolidado | G40: Consolidado | H40: Consolidado | I40: Consolidado | J40: Consolidado | K40: Consolidado | L40: En proceso | M40: Consolidado | N40: Consolidado | O40: En proceso | P40: En proceso | Q40: Proyección | R40: Proyección | S40: Proyección | T40: Proyección | U40: Proyección | V40: Proyección | W40: Proyección | X40: Proyección | Y40: En proceso | Z40: Proyección | AA40: Proyección | AB40: En proceso | AC40: Proyección | AD40: Proyección | AE40: Proyección | AF40: Proyección
...

Sheet FICHA DEL ATLETA
A1: FICHA INDIVIDUAL DE EVALUACIÓN
A3: Atleta: | B3: Diego Jaime
A5: RESUMEN | D5: Aparato | E5: Consolidado | F5: En proceso | G5: Proyección | H5: % dominio
A6: Elementos evaluados | B6: =INDEX(CONSOLIDADO!$B$4:$B$1048576,MATCH($B$3,CONSOLIDADO!$A$4:$A$1048576,0)) -> 267 | D6: POSICIONES BÁSICAS Y FUERZA | E6: =--(INDEX(NORMATIVOS!$C$3:$XFD$3,1,MATCH($B$3,NORMATIVOS!$C$1:$XFD$1,0))="Consolidado")+--(INDEX(NORMATIVOS!$C$4:$XFD$4,1,MATCH($B$3,NORMATIVOS!$C$1:$XFD$1,0))="Consolidado")+--(INDEX(NORMATIVOS!$C$5:$XFD$5,1,MATCH($B$3,NORMATIVOS!$C$1:$XFD$1,0))="Consolidado")+--(INDEX(NORMATIVOS!$C$6:$XFD$6,1,MATCH($B$3,NORMATIVOS!$C$1:$XFD$1,0))="Consolidado")+--(INDEX(NORMATIVOS!$C$7:$XFD$7,1,MATCH($B$3,NORMATIVOS!$C$1:$XFD$1,0))="Consolidado")+--(INDEX(NORMATIVOS!$C$8:$XFD$8,1,MATCH($B$3,NORMATIVOS!$C$1:$XFD$1,0))="Consolidado")+--(INDEX(NORMATIVOS!$C$9:$XFD$9,1,MATCH($B$3,NORMATIVOS!$C$1:$XFD$1,0))="Consolidado")+--(INDEX(NORMATIVOS!$C$10:$XFD$10,1,MATCH($B$3,NORMATIVOS!$C$1:$XFD$1,0))="Consolidado")+--(INDEX(NORMATIVOS!$C$11:$XFD$11,1,MATCH($B$3,NORMATIVOS!$C$1:$XFD$1,0))="Consolidado")+--(INDEX(NORMATIVOS!$C$12:$XFD$12,1,MATCH($B$3,NORMATIVOS!$C$1:$XFD$1,0))="Consolidado")+--(INDEX(NORMATIVOS!$C$13:$XFD$13,1,MATCH($B$3,NORMATIVOS!$C$1:$XFD$1,0))="Consolidado")+--(INDEX(NORMATIVOS!$C$14:$XFD$14,1,MATCH($B$3,NORMATIVOS!$C$1:$XFD$1,0))="Consolidado")+--(INDEX(NORMATIVOS!$C$15:$XFD$15,1,MATCH($B$3,NORMATIVOS!$C$1:$XFD$1,0))="Consolidado")+--(INDEX(NORMATIVOS!$C$16:$XFD$16,1,MATCH($B$3,NORMATIVOS!$C$1:$XFD$1,0))="Consolidado") -> 14 | F6: =--(INDEX(NORMATIVOS!$C$3:$XFD$3,1,MATCH($B$3,NORMATIVOS!$C$1:$XFD$1,0))="En proceso")+--(INDEX(NORMATIVOS!$C$4:$XFD$4,1,MATCH($B$3,NORMATIVOS!$C$1:$XFD$1,0))="En proceso")+--(INDEX(NORMATIVOS!$C$5:$XFD$5,1,MATCH($B$3,NORMATIVOS!$C$1:$XFD$1,0))="En proceso")+--(INDEX(NORMATIVOS!$C$6:$XFD$6,1,MATCH($B$3,NORMATIVOS!$C$1:$XFD$1,0))="En proceso")+--(INDEX(NORMATIVOS!$C$7:$XFD$7,1,MATCH($B$3,NORMATIVOS!$C$1:$XFD$1,0))="En proceso")+--(INDEX(NORMATIVOS!$C$8:$XFD$8,1,MATCH($B$3,NORMATIVOS!$C$1:$XFD$1,0))="En proceso")+--(INDEX(NORMATIVOS!$C$9:$XFD$9,1,MATCH($B$3,NORMATIVOS!$C$1:$XFD$1,0))="En proceso")+--(INDEX(NORMATIVOS!$C$10:$XFD$10,1,MATCH($B$3,NORMATIVOS!$C$1:$XFD$1,0))="En proceso")+--(INDEX(NORMATIVOS!$C$11:$XFD$11,1,MATCH($B$3,NORMATIVOS!$C$1:$XFD$1,0))="En proceso")+--(INDEX(NORMATIVOS!$C$12:$XFD$12,1,MATCH($B$3,NORMATIVOS!$C$1:$XFD$1,0))="En proceso")+--(INDEX(NORMATIVOS!$C$13:$XFD$13,1,MATCH($B$3,NORMATIVOS!$C$1:$XFD$1,0))="En proceso")+--(INDEX(NORMATIVOS!$C$14:$XFD$14,1,MATCH($B$3,NORMATIVOS!$C$1:$XFD$1,0))="En proceso")+--(INDEX(NORMATIVOS!$C$15:$XFD$15,1,MATCH($B$3,NORMATIVOS!$C$1:$XFD$1,0))="En proceso")+--(INDEX(NORMATIVOS!$C$16:$XFD$16,1,MATCH($B$3,NORMATIVOS!$C$1:$XFD$1,0))="En proceso") -> 0 | G6: =--(INDEX(NORMATIVOS!$C$3:$XFD$3,1,MATCH($B$3,NORMATIVOS!$C$1:$XFD$1,0))="Proyección")+--(INDEX(NORMATIVOS!$C$4:$XFD$4,1,MATCH($B$3,NORMATIVOS!$C$1:$XFD$1,0))="Proyección")+--(INDEX(NORMATIVOS!$C$5:$XFD$5,1,MATCH($B$3,NORMATIVOS!$C$1:$XFD$1,0))="Proyección")+--(INDEX(NORMATIVOS!$C$6:$XFD$6,1,MATCH($B$3,NORMATIVOS!$C$1:$XFD$1,0))="Proyección")+--(INDEX(NORMATIVOS!$C$7:$XFD$7,1,MATCH($B$3,NORMATIVOS!$C$1:$XFD$1,0))="Proyección")+--(INDEX(NORMATIVOS!$C$8:$XFD$8,1,MATCH($B$3,NORMATIVOS!$C$1:$XFD$1,0))="Proyección")+--(INDEX(NORMATIVOS!$C$9:$XFD$9,1,MATCH($B$3,NORMATIVOS!$C$1:$XFD$1,0))="Proyección")+--(INDEX(NORMATIVOS!$C$10:$XFD$10,1,MATCH($B$3,NORMATIVOS!$C$1:$XFD$1,0))="Proyección")+--(INDEX(NORMATIVOS!$C$11:$XFD$11,1,MATCH($B$3,NORMATIVOS!$C$1:$XFD$1,0))="Proyección")+--(INDEX(NORMATIVOS!$C$12:$XFD$12,1,MATCH($B$3,NORMATIVOS!$C$1:$XFD$1,0))="Proyección")+--(INDEX(NORMATIVOS!$C$13:$XFD$13,1,MATCH($B$3,NORMATIVOS!$C$1:$XFD$1,0))="Proyección")+--(INDEX(NORMATIVOS!$C$14:$XFD$14,1,MATCH($B$3,NORMATIVOS!$C$1:$XFD$1,0))="Proyección")+--(INDEX(NORMATIVOS!$C$15:$XFD$15,1,MATCH($B$3,NORMATIVOS!$C$1:$XFD$1,0))="Proyección")+--(INDEX(NORMATIVOS!$C$16:$XFD$16,1,MATCH($B$3,NORMATIVOS!$C$1:$XFD$1,0))="Proyección") -> 0 | H6: =IFERROR(E6/COUNTA(NORMATIVOS!$B$3:$B$16),0) -> 1
A7: Consolidados | B7: =INDEX(CONSOLIDADO!$C$4:$C$1048576,MATCH($B$3,CONSOLIDADO!$A$4:$A$1048576,0)) -> 227 | D7: ACROBATICO HACÍA DELANTE | E7: =--(INDEX(NORMATIVOS!$C$17:$XFD$17,1,MATCH($B$3,NORMATIVOS!$C$1:$XFD$1,0))="Consolidado")+--(INDEX(NORMATIVOS!$C$18:$XFD$18,1,MATCH($B$3,NORMATIVOS!$C$1:$XFD$1,0))="Consolidado")+--(INDEX(NORMATIVOS!$C$19:$XFD$19,1,MATCH($B$3,NORMATIVOS!$C$1:$XFD$1,0))="Consolidado")+--(INDEX(NORMATIVOS!$C$20:$XFD$20,1,MATCH($B$3,NORMATIVOS!$C$1:$XFD$1,0))="Consolidado")+--(INDEX(NORMATIVOS!$C$21:$XFD$21,1,MATCH($B$3,NORMATIVOS!$C$1:$XFD$1,0))="Consolidado")+--(INDEX(NORMATIVOS!$C$22:$XFD$22,1,MATCH($B$3,NORMATIVOS!$C$1:$XFD$1,0))="Consolidado")+--(INDEX(NORMATIVOS!$C$23:$XFD$23,1,MATCH($B$3,NORMATIVOS!$C$1:$XFD$1,0))="Consolidado")+--(INDEX(NORMATIVOS!$C$24:$XFD$24,1,MATCH($B$3,NORMATIVOS!$C$1:$XFD$1,0))="Consolidado")+--(INDEX(NORMATIVOS!$C$25:$XFD$25,1,MATCH($B$3,NORMATIVOS!$C$1:$XFD$1,0))="Consolidado")+--(INDEX(NORMATIVOS!$C$26:$XFD$26,1,MATCH($B$3,NORMATIVOS!$C$1:$XFD$1,0))="Consolidado")+--(INDEX(NORMATIVOS!$C$27:$XFD$27,1,MATCH($B$3,NORMATIVOS!$C$1:$XFD$1,0))="Consolidado") -> 11 | F7: =--(INDEX(NORMATIVOS!$C$17:$XFD$17,1,MATCH($B$3,NORMATIVOS!$C$1:$XFD$1,0))="En proceso")+--(INDEX(NORMATIVOS!$C$18:$XFD$18,1,MATCH($B$3,NORMATIVOS!$C$1:$XFD$1,0))="En proceso")+--(INDEX(NORMATIVOS!$C$19:$XFD$19,1,MATCH($B$3,NORMATIVOS!$C$1:$XFD$1,0))="En proceso")+--(INDEX(NORMATIVOS!$C$20:$XFD$20,1,MATCH($B$3,NORMATIVOS!$C$1:$XFD$1,0))="En proceso")+--(INDEX(NORMATIVOS!$C$21:$XFD$21,1,MATCH($B$3,NORMATIVOS!$C$1:$XFD$1,0))="En proceso")+--(INDEX(NORMATIVOS!$C$22:$XFD$22,1,MATCH($B$3,NORMATIVOS!$C$1:$XFD$1,0))="En proceso")+--(INDEX(NORMATIVOS!$C$23:$XFD$23,1,MATCH($B$3,NORMATIVOS!$C$1:$XFD$1,0))="En proceso")+--(INDEX(NORMATIVOS!$C$24:$XFD$24,1,MATCH($B$3,NORMATIVOS!$C$1:$XFD$1,0))="En proceso")+--(INDEX(NORMATIVOS!$C$25:$XFD$25,1,MATCH($B$3,NORMATIVOS!$C$1:$XFD$1,0))="En proceso")+--(INDEX(NORMATIVOS!$C$26:$XFD$26,1,MATCH($B$3,NORMATIVOS!$C$1:$XFD$1,0))="En proceso")+--(INDEX(NORMATIVOS!$C$27:$XFD$27,1,MATCH($B$3,NORMATIVOS!$C$1:$XFD$1,0))="En proceso") -> 0 | G7: =--(INDEX(NORMATIVOS!$C$17:$XFD$17,1,MATCH($B$3,NORMATIVOS!$C$1:$XFD$1,0))="Proyección")+--(INDEX(NORMATIVOS!$C$18:$XFD$18,1,MATCH($B$3,NORMATIVOS!$C$1:$XFD$1,0))="Proyección")+--(INDEX(NORMATIVOS!$C$19:$XFD$19,1,MATCH($B$3,NORMATIVOS!$C$1:$XFD$1,0))="Proyección")+--(INDEX(NORMATIVOS!$C$20:$XFD$20,1,MATCH($B$3,NORMATIVOS!$C$1:$XFD$1,0))="Proyección")+--(INDEX(NORMATIVOS!$C$21:$XFD$21,1,MATCH($B$3,NORMATIVOS!$C$1:$XFD$1,0))="Proyección")+--(INDEX(NORMATIVOS!$C$22:$XFD$22,1,MATCH($B$3,NORMATIVOS!$C$1:$XFD$1,0))="Proyección")+--(INDEX(NORMATIVOS!$C$23:$XFD$23,1,MATCH($B$3,NORMATIVOS!$C$1:$XFD$1,0))="Proyección")+--(INDEX(NORMATIVOS!$C$24:$XFD$24,1,MATCH($B$3,NORMATIVOS!$C$1:$XFD$1,0))="Proyección")+--(INDEX(NORMATIVOS!$C$25:$XFD$25,1,MATCH($B$3,NORMATIVOS!$C$1:$XFD$1,0))="Proyección")+--(INDEX(NORMATIVOS!$C$26:$XFD$26,1,MATCH($B$3,NORMATIVOS!$C$1:$XFD$1,0))="Proyección")+--(INDEX(NORMATIVOS!$C$27:$XFD$27,1,MATCH($B$3,NORMATIVOS!$C$1:$XFD$1,0))="Proyección") -> 0 | H7: =IFERROR(E7/COUNTA(NORMATIVOS!$B$17:$B$27),0) -> 1
A8: En proceso | B8: =INDEX(CONSOLIDADO!$D$4:$D$1048576,MATCH($B$3,CONSOLIDADO!$A$4:$A$1048576,0)) -> 7 | D8: ACROBATICO HACÍA ATRÁS | E8: =--(INDEX(NORMATIVOS!$C$28:$XFD$28,1,MATCH($B$3,NORMATIVOS!$C$1:$XFD$1,0))="Consolidado")+--(INDEX(NORMATIVOS!$C$29:$XFD$29,1,MATCH($B$3,NORMATIVOS!$C$1:$XFD$1,0))="Consolidado")+--(INDEX(NORMATIVOS!$C$30:$XFD$30,1,MATCH($B$3,NORMATIVOS!$C$1:$XFD$1,0))="Consolidado")+--(INDEX(NORMATIVOS!$C$31:$XFD$31,1,MATCH($B$3,NORMATIVOS!$C$1:$XFD$1,0))="Consolidado")+--(INDEX(NORMATIVOS!$C$32:$XFD$32,1,MATCH($B$3,NORMATIVOS!$C$1:$XFD$1,0))="Consolidado")+--(INDEX(NORMATIVOS!$C$33:$XFD$33,1,MATCH($B$3,NORMATIVOS!$C$1:$XFD$1,0))="Consolidado")+--(INDEX(NORMATIVOS!$C$34:$XFD$34,1,MATCH($B$3,NORMATIVOS!$C$1:$XFD$1,0))="Consolidado")+--(INDEX(NORMATIVOS!$C$35:$XFD$35,1,MATCH($B$3,NORMATIVOS!$C$1:$XFD$1,0))="Consolidado")+--(INDEX(NORMATIVOS!$C$36:$XFD$36,1,MATCH($B$3,NORMATIVOS!$C$1:$XFD$1,0))="Consolidado")+--(INDEX(NORMATIVOS!$C$37:$XFD$37,1,MATCH($B$3,NORMATIVOS!$C$1:$XFD$1,0))="Consolidado") -> 10 | F8: =--(INDEX(NORMATIVOS!$C$28:$XFD$28,1,MATCH($B$3,NORMATIVOS!$C$1:$XFD$1,0))="En proceso")+--(INDEX(NORMATIVOS!$C$29:$XFD$29,1,MATCH($B$3,NORMATIVOS!$C$1:$XFD$1,0))="En proceso")+--(INDEX(NORMATIVOS!$C$30:$XFD$30,1,MATCH($B$3,NORMATIVOS!$C$1:$XFD$1,0))="En proceso")+--(INDEX(NORMATIVOS!$C$31:$XFD$31,1,MATCH($B$3,NORMATIVOS!$C$1:$XFD$1,0))="En proceso")+--(INDEX(NORMATIVOS!$C$32:$XFD$32,1,MATCH($B$3,NORMATIVOS!$C$1:$XFD$1,0))="En proceso")+--(INDEX(NORMATIVOS!$C$33:$XFD$33,1,MATCH($B$3,NORMATIVOS!$C$1:$XFD$1,0))="En proceso")+--(INDEX(NORMATIVOS!$C$34:$XFD$34,1,MATCH($B$3,NORMATIVOS!$C$1:$XFD$1,0))="En proceso")+--(INDEX(NORMATIVOS!$C$35:$XFD$35,1,MATCH($B$3,NORMATIVOS!$C$1:$XFD$1,0))="En proceso")+--(INDEX(NORMATIVOS!$C$36:$XFD$36,1,MATCH($B$3,NORMATIVOS!$C$1:$XFD$1,0))="En proceso")+--(INDEX(NORMATIVOS!$C$37:$XFD$37,1,MATCH($B$3,NORMATIVOS!$C$1:$XFD$1,0))="En proceso") -> 0 | G8: =--(INDEX(NORMATIVOS!$C$28:$XFD$28,1,MATCH($B$3,NORMATIVOS!$C$1:$XFD$1,0))="Proyección")+--(INDEX(NORMATIVOS!$C$29:$XFD$29,1,MATCH($B$3,NORMATIVOS!$C$1:$XFD$1,0))="Proyección")+--(INDEX(NORMATIVOS!$C$30:$XFD$30,1,MATCH($B$3,NORMATIVOS!$C$1:$XFD$1,0))="Proyección")+--(INDEX(NORMATIVOS!$C$31:$XFD$31,1,MATCH($B$3,NORMATIVOS!$C$1:$XFD$1,0))="Proyección")+--(INDEX(NORMATIVOS!$C$32:$XFD$32,1,MATCH($B$3,NORMATIVOS!$C$1:$XFD$1,0))="Proyección")+--(INDEX(NORMATIVOS!$C$33:$XFD$33,1,MATCH($B$3,NORMATIVOS!$C$1:$XFD$1,0))="Proyección")+--(INDEX(NORMATIVOS!$C$34:$XFD$34,1,MATCH($B$3,NORMATIVOS!$C$1:$XFD$1,0))="Proyección")+--(INDEX(NORMATIVOS!$C$35:$XFD$35,1,MATCH($B$3,NORMATIVOS!$C$1:$XFD$1,0))="Proyección")+--(INDEX(NORMATIVOS!$C$36:$XFD$36,1,MATCH($B$3,NORMATIVOS!$C$1:$XFD$1,0))="Proyección")+--(INDEX(NORMATIVOS!$C$37:$XFD$37,1,MATCH($B$3,NORMATIVOS!$C$1:$XFD$1,0))="Proyección") -> 0 | H8: =IFERROR(E8/COUNTA(NORMATIVOS!$B$28:$B$37),0) -> 1
A9: Proyección | B9: =INDEX(CONSOLIDADO!$E$4:$E$1048576,MATCH($B$3,CONSOLIDADO!$A$4:$A$1048576,0)) -> 24 | D9: ACROBATICO CON GIRO | E9: =--(INDEX(NORMATIVOS!$C$38:$XFD$38,1,MATCH($B$3,NORMATIVOS!$C$1:$XFD$1,0))="Consolidado")+--(INDEX(NORMATIVOS!$C$39:$XFD$39,1,MATCH($B$3,NORMATIVOS!$C$1:$XFD$1,0))="Consolidado")+--(INDEX(NORMATIVOS!$C$40:$XFD$40,1,MATCH($B$3,NORMATIVOS!$C$1:$XFD$1,0))="Consolidado")+--(INDEX(NORMATIVOS!$C$41:$XFD$41,1,MATCH($B$3,NORMATIVOS!$C$1:$XFD$1,0))="Consolidado")+--(INDEX(NORMATIVOS!$C$42:$XFD$42,1,MATCH($B$3,NORMATIVOS!$C$1:$XFD$1,0))="Consolidado")+--(INDEX(NORMATIVOS!$C$43:$XFD$43,1,MATCH($B$3,NORMATIVOS!$C$1:$XFD$1,0))="Consolidado")+--(INDEX(NORMATIVOS!$C$44:$XFD$44,1,MATCH($B$3,NORMATIVOS!$C$1:$XFD$1,0))="Consolidado")+--(INDEX(NORMATIVOS!$C$45:$XFD$45,1,MATCH($B$3,NORMATIVOS!$C$1:$XFD$1,0))="Consolidado")+--(INDEX(NORMATIVOS!$C$46:$XFD$46,1,MATCH($B$3,NORMATIVOS!$C$1:$XFD$1,0))="Consolidado") -> 9 | F9: =--(INDEX(NORMATIVOS!$C$38:$XFD$38,1,MATCH($B$3,NORMATIVOS!$C$1:$XFD$1,0))="En proceso")+--(INDEX(NORMATIVOS!$C$39:$XFD$39,1,MATCH($B$3,NORMATIVOS!$C$1:$XFD$1,0))="En proceso")+--(INDEX(NORMATIVOS!$C$40:$XFD$40,1,MATCH($B$3,NORMATIVOS!$C$1:$XFD$1,0))="En proceso")+--(INDEX(NORMATIVOS!$C$41:$XFD$41,1,MATCH($B$3,NORMATIVOS!$C$1:$XFD$1,0))="En proceso")+--(INDEX(NORMATIVOS!$C$42:$XFD$42,1,MATCH($B$3,NORMATIVOS!$C$1:$XFD$1,0))="En proceso")+--(INDEX(NORMATIVOS!$C$43:$XFD$43,1,MATCH($B$3,NORMATIVOS!$C$1:$XFD$1,0))="En proceso")+--(INDEX(NORMATIVOS!$C$44:$XFD$44,1,MATCH($B$3,NORMATIVOS!$C$1:$XFD$1,0))="En proceso")+--(INDEX(NORMATIVOS!$C$45:$XFD$45,1,MATCH($B$3,NORMATIVOS!$C$1:$XFD$1,0))="En proceso")+--(INDEX(NORMATIVOS!$C$46:$XFD$46,1,MATCH($B$3,NORMATIVOS!$C$1:$XFD$1,0))="En proceso") -> 0 | G9: =--(INDEX(NORMATIVOS!$C$38:$XFD$38,1,MATCH($B$3,NORMATIVOS!$C$1:$XFD$1,0))="Proyección")+--(INDEX(NORMATIVOS!$C$39:$XFD$39,1,MATCH($B$3,NORMATIVOS!$C$1:$XFD$1,0))="Proyección")+--(INDEX(NORMATIVOS!$C$40:$XFD$40,1,MATCH($B$3,NORMATIVOS!$C$1:$XFD$1,0))="Proyección")+--(INDEX(NORMATIVOS!$C$41:$XFD$41,1,MATCH($B$3,NORMATIVOS!$C$1:$XFD$1,0))="Proyección")+--(INDEX(NORMATIVOS!$C$42:$XFD$42,1,MATCH($B$3,NORMATIVOS!$C$1:$XFD$1,0))="Proyección")+--(INDEX(NORMATIVOS!$C$43:$XFD$43,1,MATCH($B$3,NORMATIVOS!$C$1:$XFD$1,0))="Proyección")+--(INDEX(NORMATIVOS!$C$44:$XFD$44,1,MATCH($B$3,NORMATIVOS!$C$1:$XFD$1,0))="Proyección")+--(INDEX(NORMATIVOS!$C$45:$XFD$45,1,MATCH($B$3,NORMATIVOS!$C$1:$XFD$1,0))="Proyección")+--(INDEX(NORMATIVOS!$C$46:$XFD$46,1,MATCH($B$3,NORMATIVOS!$C$1:$XFD$1,0))="Proyección") -> 0 | H9: =IFERROR(E9/COUNTA(NORMATIVOS!$B$38:$B$46),0) -> 1
A10: N/A | B10: =INDEX(CONSOLIDADO!$F$4:$F$1048576,MATCH($B$3,CONSOLIDADO!$A$4:$A$1048576,0)) -> 9 | D10: HONGO | E10: =--(INDEX(NORMATIVOS!$C$49:$XFD$49,1,MATCH($B$3,NORMATIVOS!$C$1:$XFD$1,0))="Consolidado")+--(INDEX(NORMATIVOS!$C$50:$XFD$50,1,MATCH($B$3,NORMATIVOS!$C$1:$XFD$1,0))="Consolidado")+--(INDEX(NORMATIVOS!$C$51:$XFD$51,1,MATCH($B$3,NORMATIVOS!$C$1:$XFD$1,0))="Consolidado")+--(INDEX(NORMATIVOS!$C$52:$XFD$52,1,MATCH($B$3,NORMATIVOS!$C$1:$XFD$1,0))="Consolidado")+--(INDEX(NORMATIVOS!$C$53:$XFD$53,1,MATCH($B$3,NORMATIVOS!$C$1:$XFD$1,0))="Consolidado")+--(INDEX(NORMATIVOS!$C$54:$XFD$54,1,MATCH($B$3,NORMATIVOS!$C$1:$XFD$1,0))="Consolidado")+--(INDEX(NORMATIVOS!$C$55:$XFD$55,1,MATCH($B$3,NORMATIVOS!$C$1:$XFD$1,0))="Consolidado")+--(INDEX(NORMATIVOS!$C$56:$XFD$56,1,MATCH($B$3,NORMATIVOS!$C$1:$XFD$1,0))="Consolidado")+--(INDEX(NORMATIVOS!$C$57:$XFD$57,1,MATCH($B$3,NORMATIVOS!$C$1:$XFD$1,0))="Consolidado")+--(INDEX(NORMATIVOS!$C$58:$XFD$58,1,MATCH($B$3,NORMATIVOS!$C$1:$XFD$1,0))="Consolidado")+--(INDEX(NORMATIVOS!$C$59:$XFD$59,1,MATCH($B$3,NORMATIVOS!$C$1:$XFD$1,0))="Consolidado")+--(INDEX(NORMATIVOS!$C$60:$XFD$60,1,MATCH($B$3,NORMATIVOS!$C$1:$XFD$1,0))="Consolidado")+--(INDEX(NORMATIVOS!$C$61:$XFD$61,1,MATCH($B$3,NORMATIVOS!$C$1:$XFD$1,0))="Consolidado")+--(INDEX(NORMATIVOS!$C$62:$XFD$62,1,MATCH($B$3,NORMATIVOS!$C$1:$XFD$1,0))="Consolidado")+--(INDEX(NORMATIVOS!$C$63:$XFD$63,1,MATCH($B$3,NORMATIVOS!$C$1:$XFD$1,0))="Consolidado")+--(INDEX(NORMATIVOS!$C$64:$XFD$64,1,MATCH($B$3,NORMATIVOS!$C$1:$XFD$1,0))="Consolidado") -> 16 | F10: =--(INDEX(NORMATIVOS!$C$49:$XFD$49,1,MATCH($B$3,NORMATIVOS!$C$1:$XFD$1,0))="En proceso")+--(INDEX(NORMATIVOS!$C$50:$XFD$50,1,MATCH($B$3,NORMATIVOS!$C$1:$XFD$1,0))="En proceso")+--(INDEX(NORMATIVOS!$C$51:$XFD$51,1,MATCH($B$3,NORMATIVOS!$C$1:$XFD$1,0))="En proceso")+--(INDEX(NORMATIVOS!$C$52:$XFD$52,1,MATCH($B$3,NORMATIVOS!$C$1:$XFD$1,0))="En proceso")+--(INDEX(NORMATIVOS!$C$53:$XFD$53,1,MATCH($B$3,NORMATIVOS!$C$1:$XFD$1,0))="En proceso")+--(INDEX(NORMATIVOS!$C$54:$XFD$54,1,MATCH($B$3,NORMATIVOS!$C$1:$XFD$1,0))="En proceso")+--(INDEX(NORMATIVOS!$C$55:$XFD$55,1,MATCH($B$3,NORMATIVOS!$C$1:$XFD$1,0))="En proceso")+--(INDEX(NORMATIVOS!$C$56:$XFD$56,1,MATCH($B$3,NORMATIVOS!$C$1:$XFD$1,0))="En proceso")+--(INDEX(NORMATIVOS!$C$57:$XFD$57,1,MATCH($B$3,NORMATIVOS!$C$1:$XFD$1,0))="En proceso")+--(INDEX(NORMATIVOS!$C$58:$XFD$58,1,MATCH($B$3,NORMATIVOS!$C$1:$XFD$1,0))="En proceso")+--(INDEX(NORMATIVOS!$C$59:$XFD$59,1,MATCH($B$3,NORMATIVOS!$C$1:$XFD$1,0))="En proceso")+--(INDEX(NORMATIVOS!$C$60:$XFD$60,1,MATCH($B$3,NORMATIVOS!$C$1:$XFD$1,0))="En proceso")+--(INDEX(NORMATIVOS!$C$61:$XFD$61,1,MATCH($B$3,NORMATIVOS!$C$1:$XFD$1,0))="En proceso")+--(INDEX(NORMATIVOS!$C$62:$XFD$62,1,MATCH($B$3,NORMATIVOS!$C$1:$XFD$1,0))="En proceso")+--(INDEX(NORMATIVOS!$C$63:$XFD$63,1,MATCH($B$3,NORMATIVOS!$C$1:$XFD$1,0))="En proceso")+--(INDEX(NORMATIVOS!$C$64:$XFD$64,1,MATCH($B$3,NORMATIVOS!$C$1:$XFD$1,0))="En proceso") -> 0 | G10: =--(INDEX(NORMATIVOS!$C$49:$XFD$49,1,MATCH($B$3,NORMATIVOS!$C$1:$XFD$1,0))="Proyección")+--(INDEX(NORMATIVOS!$C$50:$XFD$50,1,MATCH($B$3,NORMATIVOS!$C$1:$XFD$1,0))="Proyección")+--(INDEX(NORMATIVOS!$C$51:$XFD$51,1,MATCH($B$3,NORMATIVOS!$C$1:$XFD$1,0))="Proyección")+--(INDEX(NORMATIVOS!$C$52:$XFD$52,1,MATCH($B$3,NORMATIVOS!$C$1:$XFD$1,0))="Proyección")+--(INDEX(NORMATIVOS!$C$53:$XFD$53,1,MATCH($B$3,NORMATIVOS!$C$1:$XFD$1,0))="Proyección")+--(INDEX(NORMATIVOS!$C$54:$XFD$54,1,MATCH($B$3,NORMATIVOS!$C$1:$XFD$1,0))="Proyección")+--(INDEX(NORMATIVOS!$C$55:$XFD$55,1,MATCH($B$3,NORMATIVOS!$C$1:$XFD$1,0))="Proyección")+--(INDEX(NORMATIVOS!$C$56:$XFD$56,1,MATCH($B$3,NORMATIVOS!$C$1:$XFD$1,0))="Proyección")+--(INDEX(NORMATIVOS!$C$57:$XFD$57,1,MATCH($B$3,NORMATIVOS!$C$1:$XFD$1,0))="Proyección")+--(INDEX(NORMATIVOS!$C$58:$XFD$58,1,MATCH($B$3,NORMATIVOS!$C$1:$XFD$1,0))="Proyección")+--(INDEX(NORMATIVOS!$C$59:$XFD$59,1,MATCH($B$3,NORMATIVOS!$C$1:$XFD$1,0))="Proyección")+--(INDEX(NORMATIVOS!$C$60:$XFD$60,1,MATCH($B$3,NORMATIVOS!$C$1:$XFD$1,0))="Proyección")+--(INDEX(NORMATIVOS!$C$61:$XFD$61,1,MATCH($B$3,NORMATIVOS!$C$1:$XFD$1,0))="Proyección")+--(INDEX(NORMATIVOS!$C$62:$XFD$62,1,MATCH($B$3,NORMATIVOS!$C$1:$XFD$1,0))="Proyección")+--(INDEX(NORMATIVOS!$C$63:$XFD$63,1,MATCH($B$3,NORMATIVOS!$C$1:$XFD$1,0))="Proyección")+--(INDEX(NORMATIVOS!$C$64:$XFD$64,1,MATCH($B$3,NORMATIVOS!$C$1:$XFD$1,0))="Proyección") -> 0 | H10: =IFERROR(E10/COUNTA(NORMATIVOS!$B$49:$B$64),0) -> 1
A11: % dominio | B11: =INDEX(CONSOLIDADO!$G$4:$G$1048576,MATCH($B$3,CONSOLIDADO!$A$4:$A$1048576,0)) -> 0.85018727 | D11: CABALLO SIN ARZON | E11: =--(INDEX(NORMATIVOS!$C$65:$XFD$65,1,MATCH($B$3,NORMATIVOS!$C$1:$XFD$1,0))="Consolidado")+--(INDEX(NORMATIVOS!$C$66:$XFD$66,1,MATCH($B$3,NORMATIVOS!$C$1:$XFD$1,0))="Consolidado")+--(INDEX(NORMATIVOS!$C$67:$XFD$67,1,MATCH($B$3,NORMATIVOS!$C$1:$XFD$1,0))="Consolidado")+--(INDEX(NORMATIVOS!$C$68:$XFD$68,1,MATCH($B$3,NORMATIVOS!$C$1:$XFD$1,0))="Consolidado")+--(INDEX(NORMATIVOS!$C$69:$XFD$69,1,MATCH($B$3,NORMATIVOS!$C$1:$XFD$1,0))="Consolidado")+--(INDEX(NORMATIVOS!$C$70:$XFD$70,1,MATCH($B$3,NORMATIVOS!$C$1:$XFD$1,0))="Consolidado")+--(INDEX(NORMATIVOS!$C$71:$XFD$71,1,MATCH($B$3,NORMATIVOS!$C$1:$XFD$1,0))="Consolidado")+--(INDEX(NORMATIVOS!$C$72:$XFD$72,1,MATCH($B$3,NORMATIVOS!$C$1:$XFD$1,0))="Consolidado")+--(INDEX(NORMATIVOS!$C$73:$XFD$73,1,MATCH($B$3,NORMATIVOS!$C$1:$XFD$1,0))="Consolidado")+--(INDEX(NORMATIVOS!$C$74:$XFD$74,1,MATCH($B$3,NORMATIVOS!$C$1:$XFD$1,0))="Consolidado")+--(INDEX(NORMATIVOS!$C$75:$XFD$75,1,MATCH($B$3,NORMATIVOS!$C$1:$XFD$1,0))="Consolidado")+--(INDEX(NORMATIVOS!$C$76:$XFD$76,1,MATCH($B$3,NORMATIVOS!$C$1:$XFD$1,0))="Consolidado")+--(INDEX(NORMATIVOS!$C$77:$XFD$77,1,MATCH($B$3,NORMATIVOS!$C$1:$XFD$1,0))="Consolidado")+--(INDEX(NORMATIVOS!$C$78:$XFD$78,1,MATCH($B$3,NORMATIVOS!$C$1:$XFD$1,0))="Consolidado") -> 14 | F11: =--(INDEX(NORMATIVOS!$C$65:$XFD$65,1,MATCH($B$3,NORMATIVOS!$C$1:$XFD$1,0))="En proceso")+--(INDEX(NORMATIVOS!$C$66:$XFD$66,1,MATCH($B$3,NORMATIVOS!$C$1:$XFD$1,0))="En proceso")+--(INDEX(NORMATIVOS!$C$67:$XFD$67,1,MATCH($B$3,NORMATIVOS!$C$1:$XFD$1,0))="En proceso")+--(INDEX(NORMATIVOS!$C$68:$XFD$68,1,MATCH($B$3,NORMATIVOS!$C$1:$XFD$1,0))="En proceso")+--(INDEX(NORMATIVOS!$C$69:$XFD$69,1,MATCH($B$3,NORMATIVOS!$C$1:$XFD$1,0))="En proceso")+--(INDEX(NORMATIVOS!$C$70:$XFD$70,1,MATCH($B$3,NORMATIVOS!$C$1:$XFD$1,0))="En proceso")+--(INDEX(NORMATIVOS!$C$71:$XFD$71,1,MATCH($B$3,NORMATIVOS!$C$1:$XFD$1,0))="En proceso")+--(INDEX(NORMATIVOS!$C$72:$XFD$72,1,MATCH($B$3,NORMATIVOS!$C$1:$XFD$1,0))="En proceso")+--(INDEX(NORMATIVOS!$C$73:$XFD$73,1,MATCH($B$3,NORMATIVOS!$C$1:$XFD$1,0))="En proceso")+--(INDEX(NORMATIVOS!$C$74:$XFD$74,1,MATCH($B$3,NORMATIVOS!$C$1:$XFD$1,0))="En proceso")+--(INDEX(NORMATIVOS!$C$75:$XFD$75,1,MATCH($B$3,NORMATIVOS!$C$1:$XFD$1,0))="En proceso")+--(INDEX(NORMATIVOS!$C$76:$XFD$76,1,MATCH($B$3,NORMATIVOS!$C$1:$XFD$1,0))="En proceso")+--(INDEX(NORMATIVOS!$C$77:$XFD$77,1,MATCH($B$3,NORMATIVOS!$C$1:$XFD$1,0))="En proceso")+--(INDEX(NORMATIVOS!$C$78:$XFD$78,1,MATCH($B$3,NORMATIVOS!$C$1:$XFD$1,0))="En proceso") -> 0 | G11: =--(INDEX(NORMATIVOS!$C$65:$XFD$65,1,MATCH($B$3,NORMATIVOS!$C$1:$XFD$1,0))="Proyección")+--(INDEX(NORMATIVOS!$C$66:$XFD$66,1,MATCH($B$3,NORMATIVOS!$C$1:$XFD$1,0))="Proyección")+--(INDEX(NORMATIVOS!$C$67:$XFD$67,1,MATCH($B$3,NORMATIVOS!$C$1:$XFD$1,0))="Proyección")+--(INDEX(NORMATIVOS!$C$68:$XFD$68,1,MATCH($B$3,NORMATIVOS!$C$1:$XFD$1,0))="Proyección")+--(INDEX(NORMATIVOS!$C$69:$XFD$69,1,MATCH($B$3,NORMATIVOS!$C$1:$XFD$1,0))="Proyección")+--(INDEX(NORMATIVOS!$C$70:$XFD$70,1,MATCH($B$3,NORMATIVOS!$C$1:$XFD$1,0))="Proyección")+--(INDEX(NORMATIVOS!$C$71:$XFD$71,1,MATCH($B$3,NORMATIVOS!$C$1:$XFD$1,0))="Proyección")+--(INDEX(NORMATIVOS!$C$72:$XFD$72,1,MATCH($B$3,NORMATIVOS!$C$1:$XFD$1,0))="Proyección")+--(INDEX(NORMATIVOS!$C$73:$XFD$73,1,MATCH($B$3,NORMATIVOS!$C$1:$XFD$1,0))="Proyección")+--(INDEX(NORMATIVOS!$C$74:$XFD$74,1,MATCH($B$3,NORMATIVOS!$C$1:$XFD$1,0))="Proyección")+--(INDEX(NORMATIVOS!$C$75:$XFD$75,1,MATCH($B$3,NORMATIVOS!$C$1:$XFD$1,0))="Proyección")+--(INDEX(NORMATIVOS!$C$76:$XFD$76,1,MATCH($B$3,NORMATIVOS!$C$1:$XFD$1,0))="Proyección")+--(INDEX(NORMATIVOS!$C$77:$XFD$77,1,MATCH($B$3,NORMATIVOS!$C$1:$XFD$1,0))="Proyección")+--(INDEX(NORMATIVOS!$C$78:$XFD$78,1,MATCH($B$3,NORMATIVOS!$C$1:$XFD$1,0))="Proyección") -> 0 | H11: =IFERROR(E11/COUNTA(NORMATIVOS!$B$65:$B$78),0) -> 1
D12: CABALLO CON ARZONES | E12: =--(INDEX(NORMATIVOS!$C$79:$XFD$79,1,MATCH($B$3,NORMATIVOS!$C$1:$XFD$1,0))="Consolidado")+--(INDEX(NORMATIVOS!$C$80:$XFD$80,1,MATCH($B$3,NORMATIVOS!$C$1:$XFD$1,0))="Consolidado")+--(INDEX(NORMATIVOS!$C$81:$XFD$81,1,MATCH($B$3,NORMATIVOS!$C$1:$XFD$1,0))="Consolidado")+--(INDEX(NORMATIVOS!$C$82:$XFD$82,1,MATCH($B$3,NORMATIVOS!$C$1:$XFD$1,0))="Consolidado")+--(INDEX(NORMATIVOS!$C$83:$XFD$83,1,MATCH($B$3,NORMATIVOS!$C$1:$XFD$1,0))="Consolidado")+--(INDEX(NORMATIVOS!$C$84:$XFD$84,1,MATCH($B$3,NORMATIVOS!$C$1:$XFD$1,0))="Consolidado")+--(INDEX(NORMATIVOS!$C$85:$XFD$85,1,MATCH($B$3,NORMATIVOS!$C$1:$XFD$1,0))="Consolidado")+--(INDEX(NORMATIVOS!$C$86:$XFD$86,1,MATCH($B$3,NORMATIVOS!$C$1:$XFD$1,0))="Consolidado")+--(INDEX(NORMATIVOS!$C$87:$XFD$87,1,MATCH($B$3,NORMATIVOS!$C$1:$XFD$1,0))="Consolidado")+--(INDEX(NORMATIVOS!$C$88:$XFD$88,1,MATCH($B$3,NORMATIVOS!$C$1:$XFD$1,0))="Consolidado")+--(INDEX(NORMATIVOS!$C$89:$XFD$89,1,MATCH($B$3,NORMATIVOS!$C$1:$XFD$1,0))="Consolidado")+--(INDEX(NORMATIVOS!$C$90:$XFD$90,1,MATCH($B$3,NORMATIVOS!$C$1:$XFD$1,0))="Consolidado")+--(INDEX(NORMATIVOS!$C$91:$XFD$91,1,MATCH($B$3,NORMATIVOS!$C$1:$XFD$1,0))="Consolidado")+--(INDEX(NORMATIVOS!$C$92:$XFD$92,1,MATCH($B$3,NORMATIVOS!$C$1:$XFD$1,0))="Consolidado")+--(INDEX(NORMATIVOS!$C$93:$XFD$93,1,MATCH($B$3,NORMATIVOS!$C$1:$XFD$1,0))="Consolidado")+--(INDEX(NORMATIVOS!$C$94:$XFD$94,1,MATCH($B$3,NORMATIVOS!$C$1:$XFD$1,0))="Consolidado")+--(INDEX(NORMATIVOS!$C$95:$XFD$95,1,MATCH($B$3,NORMATIVOS!$C$1:$XFD$1,0))="Consolidado")+--(INDEX(NORMATIVOS!$C$96:$XFD$96,1,MATCH($B$3,NORMATIVOS!$C$1:$XFD$1,0))="Consolidado")+--(INDEX(NORMATIVOS!$C$97:$XFD$97,1,MATCH($B$3,NORMATIVOS!$C$1:$XFD$1,0))="Consolidado")+--(INDEX(NORMATIVOS!$C$98:$XFD$98,1,MATCH($B$3,NORMATIVOS!$C$1:$XFD$1,0))="Consolidado")+--(INDEX(NORMATIVOS!$C$99:$XFD$99,1,MATCH($B$3,NORMATIVOS!$C$1:$XFD$1,0))="Consolidado")+--(INDEX(NORMATIVOS!$C$100:$XFD$100,1,MATCH($B$3,NORMATIVOS!$C$1:$XFD$1,0))="Consolidado")+--(INDEX(NORMATIVOS!$C$101:$XFD$101,1,MATCH($B$3,NORMATIVOS!$C$1:$XFD$1,0))="Consolidado")+--(INDEX(NORMATIVOS!$C$102:$XFD$102,1,MATCH($B$3,NORMATIVOS!$C$1:$XFD$1,0))="Consolidado")+--(INDEX(NORMATIVOS!$C$103:$XFD$103,1,MATCH($B$3,NORMATIVOS!$C$1:$XFD$1,0))="Consolidado")+--(INDEX(NORMATIVOS!$C$104:$XFD$104,1,MATCH($B$3,NORMATIVOS!$C$1:$XFD$1,0))="Consolidado")+--(INDEX(NORMATIVOS!$C$105:$XFD$105,1,MATCH($B$3,NORMATIVOS!$C$1:$XFD$1,0))="Consolidado") -> 24 | F12: =--(INDEX(NORMATIVOS!$C$79:$XFD$79,1,MATCH($B$3,NORMATIVOS!$C$1:$XFD$1,0))="En proceso")+--(INDEX(NORMATIVOS!$C$80:$XFD$80,1,MATCH($B$3,NORMATIVOS!$C$1:$XFD$1,0))="En proceso")+--(INDEX(NORMATIVOS!$C$81:$XFD$81,1,MATCH($B$3,NORMATIVOS!$C$1:$XFD$1,0))="En proceso")+--(INDEX(NORMATIVOS!$C$82:$XFD$82,1,MATCH($B$3,NORMATIVOS!$C$1:$XFD$1,0))="En proceso")+--(INDEX(NORMATIVOS!$C$83:$XFD$83,1,MATCH($B$3,NORMATIVOS!$C$1:$XFD$1,0))="En proceso")+--(INDEX(NORMATIVOS!$C$84:$XFD$84,1,MATCH($B$3,NORMATIVOS!$C$1:$XFD$1,0))="En proceso")+--(INDEX(NORMATIVOS!$C$85:$XFD$85,1,MATCH($B$3,NORMATIVOS!$C$1:$XFD$1,0))="En proceso")+--(INDEX(NORMATIVOS!$C$86:$XFD$86,1,MATCH($B$3,NORMATIVOS!$C$1:$XFD$1,0))="En proceso")+--(INDEX(NORMATIVOS!$C$87:$XFD$87,1,MATCH($B$3,NORMATIVOS!$C$1:$XFD$1,0))="En proceso")+--(INDEX(NORMATIVOS!$C$88:$XFD$88,1,MATCH($B$3,NORMATIVOS!$C$1:$XFD$1,0))="En proceso")+--(INDEX(NORMATIVOS!$C$89:$XFD$89,1,MATCH($B$3,NORMATIVOS!$C$1:$XFD$1,0))="En proceso")+--(INDEX(NORMATIVOS!$C$90:$XFD$90,1,MATCH($B$3,NORMATIVOS!$C$1:$XFD$1,0))="En proceso")+--(INDEX(NORMATIVOS!$C$91:$XFD$91,1,MATCH($B$3,NORMATIVOS!$C$1:$XFD$1,0))="En proceso")+--(INDEX(NORMATIVOS!$C$92:$XFD$92,1,MATCH($B$3,NORMATIVOS!$C$1:$XFD$1,0))="En proceso")+--(INDEX(NORMATIVOS!$C$93:$XFD$93,1,MATCH($B$3,NORMATIVOS!$C$1:$XFD$1,0))="En proceso")+--(INDEX(NORMATIVOS!$C$94:$XFD$94,1,MATCH($B$3,NORMATIVOS!$C$1:$XFD$1,0))="En proceso")+--(INDEX(NORMATIVOS!$C$95:$XFD$95,1,MATCH($B$3,NORMATIVOS!$C$1:$XFD$1,0))="En proceso")+--(INDEX(NORMATIVOS!$C$96:$XFD$96,1,MATCH($B$3,NORMATIVOS!$C$1:$XFD$1,0))="En proceso")+--(INDEX(NORMATIVOS!$C$97:$XFD$97,1,MATCH($B$3,NORMATIVOS!$C$1:$XFD$1,0))="En proceso")+--(INDEX(NORMATIVOS!$C$98:$XFD$98,1,MATCH($B$3,NORMATIVOS!$C$1:$XFD$1,0))="En proceso")+--(INDEX(NORMATIVOS!$C$99:$XFD$99,1,MATCH($B$3,NORMATIVOS!$C$1:$XFD$1,0))="En proceso")+--(INDEX(NORMATIVOS!$C$100:$XFD$100,1,MATCH($B$3,NORMATIVOS!$C$1:$XFD$1,0))="En proceso")+--(INDEX(NORMATIVOS!$C$101:$XFD$101,1,MATCH($B$3,NORMATIVOS!$C$1:$XFD$1,0))="En proceso")+--(INDEX(NORMATIVOS!$C$102:$XFD$102,1,MATCH($B$3,NORMATIVOS!$C$1:$XFD$1,0))="En proceso")+--(INDEX(NORMATIVOS!$C$103:$XFD$103,1,MATCH($B$3,NORMATIVOS!$C$1:$XFD$1,0))="En proceso")+--(INDEX(NORMATIVOS!$C$104:$XFD$104,1,MATCH($B$3,NORMATIVOS!$C$1:$XFD$1,0))="En proceso")+--(INDEX(NORMATIVOS!$C$105:$XFD$105,1,MATCH($B$3,NORMATIVOS!$C$1:$XFD$1,0))="En proceso") -> 0 | G12: =--(INDEX(NORMATIVOS!$C$79:$XFD$79,1,MATCH($B$3,NORMATIVOS!$C$1:$XFD$1,0))="Proyección")+--(INDEX(NORMATIVOS!$C$80:$XFD$80,1,MATCH($B$3,NORMATIVOS!$C$1:$XFD$1,0))="Proyección")+--(INDEX(NORMATIVOS!$C$81:$XFD$81,1,MATCH($B$3,NORMATIVOS!$C$1:$XFD$1,0))="Proyección")+--(INDEX(NORMATIVOS!$C$82:$XFD$82,1,MATCH($B$3,NORMATIVOS!$C$1:$XFD$1,0))="Proyección")+--(INDEX(NORMATIVOS!$C$83:$XFD$83,1,MATCH($B$3,NORMATIVOS!$C$1:$XFD$1,0))="Proyección")+--(INDEX(NORMATIVOS!$C$84:$XFD$84,1,MATCH($B$3,NORMATIVOS!$C$1:$XFD$1,0))="Proyección")+--(INDEX(NORMATIVOS!$C$85:$XFD$85,1,MATCH($B$3,NORMATIVOS!$C$1:$XFD$1,0))="Proyección")+--(INDEX(NORMATIVOS!$C$86:$XFD$86,1,MATCH($B$3,NORMATIVOS!$C$1:$XFD$1,0))="Proyección")+--(INDEX(NORMATIVOS!$C$87:$XFD$87,1,MATCH($B$3,NORMATIVOS!$C$1:$XFD$1,0))="Proyección")+--(INDEX(NORMATIVOS!$C$88:$XFD$88,1,MATCH($B$3,NORMATIVOS!$C$1:$XFD$1,0))="Proyección")+--(INDEX(NORMATIVOS!$C$89:$XFD$89,1,MATCH($B$3,NORMATIVOS!$C$1:$XFD$1,0))="Proyección")+--(INDEX(NORMATIVOS!$C$90:$XFD$90,1,MATCH($B$3,NORMATIVOS!$C$1:$XFD$1,0))="Proyección")+--(INDEX(NORMATIVOS!$C$91:$XFD$91,1,MATCH($B$3,NORMATIVOS!$C$1:$XFD$1,0))="Proyección")+--(INDEX(NORMATIVOS!$C$92:$XFD$92,1,MATCH($B$3,NORMATIVOS!$C$1:$XFD$1,0))="Proyección")+--(INDEX(NORMATIVOS!$C$93:$XFD$93,1,MATCH($B$3,NORMATIVOS!$C$1:$XFD$1,0))="Proyección")+--(INDEX(NORMATIVOS!$C$94:$XFD$94,1,MATCH($B$3,NORMATIVOS!$C$1:$XFD$1,0))="Proyección")+--(INDEX(NORMATIVOS!$C$95:$XFD$95,1,MATCH($B$3,NORMATIVOS!$C$1:$XFD$1,0))="Proyección")+--(INDEX(NORMATIVOS!$C$96:$XFD$96,1,MATCH($B$3,NORMATIVOS!$C$1:$XFD$1,0))="Proyección")+--(INDEX(NORMATIVOS!$C$97:$XFD$97,1,MATCH($B$3,NORMATIVOS!$C$1:$XFD$1,0))="Proyección")+--(INDEX(NORMATIVOS!$C$98:$XFD$98,1,MATCH($B$3,NORMATIVOS!$C$1:$XFD$1,0))="Proyección")+--(INDEX(NORMATIVOS!$C$99:$XFD$99,1,MATCH($B$3,NORMATIVOS!$C$1:$XFD$1,0))="Proyección")+--(INDEX(NORMATIVOS!$C$100:$XFD$100,1,MATCH($B$3,NORMATIVOS!$C$1:$XFD$1,0))="Proyección")+--(INDEX(NORMATIVOS!$C$101:$XFD$101,1,MATCH($B$3,NORMATIVOS!$C$1:$XFD$1,0))="Proyección")+--(INDEX(NORMATIVOS!$C$102:$XFD$102,1,MATCH($B$3,NORMATIVOS!$C$1:$XFD$1,0))="Proyección")+--(INDEX(NORMATIVOS!$C$103:$XFD$103,1,MATCH($B$3,NORMATIVOS!$C$1:$XFD$1,0))="Proyección")+--(INDEX(NORMATIVOS!$C$104:$XFD$104,1,MATCH($B$3,NORMATIVOS!$C$1:$XFD$1,0))="Proyección")+--(INDEX(NORMATIVOS!$C$105:$XFD$105,1,MATCH($B$3,NORMATIVOS!$C$1:$XFD$1,0))="Proyección") -> 3 | H12: =IFERROR(E12/COUNTA(NORMATIVOS!$B$79:$B$105),0) -> 0.88888889
D13: ELEMENTOS DE FUERZA | E13: =--(INDEX(NORMATIVOS!$C$108:$XFD$108,1,MATCH($B$3,NORMATIVOS!$C$1:$XFD$1,0))="Consolidado")+--(INDEX(NORMATIVOS!$C$109:$XFD$109,1,MATCH($B$3,NORMATIVOS!$C$1:$XFD$1,0))="Consolidado")+--(INDEX(NORMATIVOS!$C$110:$XFD$110,1,MATCH($B$3,NORMATIVOS!$C$1:$XFD$1,0))="Consolidado")+--(INDEX(NORMATIVOS!$C$111:$XFD$111,1,MATCH($B$3,NORMATIVOS!$C$1:$XFD$1,0))="Consolidado")+--(INDEX(NORMATIVOS!$C$112:$XFD$112,1,MATCH($B$3,NORMATIVOS!$C$1:$XFD$1,0))="Consolidado")+--(INDEX(NORMATIVOS!$C$113:$XFD$113,1,MATCH($B$3,NORMATIVOS!$C$1:$XFD$1,0))="Consolidado")+--(INDEX(NORMATIVOS!$C$114:$XFD$114,1,MATCH($B$3,NORMATIVOS!$C$1:$XFD$1,0))="Consolidado")+--(INDEX(NORMATIVOS!$C$115:$XFD$115,1,MATCH($B$3,NORMATIVOS!$C$1:$XFD$1,0))="Consolidado")+--(INDEX(NORMATIVOS!$C$116:$XFD$116,1,MATCH($B$3,NORMATIVOS!$C$1:$XFD$1,0))="Consolidado")+--(INDEX(NORMATIVOS!$C$117:$XFD$117,1,MATCH($B$3,NORMATIVOS!$C$1:$XFD$1,0))="Consolidado")+--(INDEX(NORMATIVOS!$C$118:$XFD$118,1,MATCH($B$3,NORMATIVOS!$C$1:$XFD$1,0))="Consolidado")+--(INDEX(NORMATIVOS!$C$119:$XFD$119,1,MATCH($B$3,NORMATIVOS!$C$1:$XFD$1,0))="Consolidado")+--(INDEX(NORMATIVOS!$C$120:$XFD$120,1,MATCH($B$3,NORMATIVOS!$C$1:$XFD$1,0))="Consolidado")+--(INDEX(NORMATIVOS!$C$121:$XFD$121,1,MATCH($B$3,NORMATIVOS!$C$1:$XFD$1,0))="Consolidado")+--(INDEX(NORMATIVOS!$C$122:$XFD$122,1,MATCH($B$3,NORMATIVOS!$C$1:$XFD$1,0))="Consolidado") -> 12 | F13: =--(INDEX(NORMATIVOS!$C$108:$XFD$108,1,MATCH($B$3,NORMATIVOS!$C$1:$XFD$1,0))="En proceso")+--(INDEX(NORMATIVOS!$C$109:$XFD$109,1,MATCH($B$3,NORMATIVOS!$C$1:$XFD$1,0))="En proceso")+--(INDEX(NORMATIVOS!$C$110:$XFD$110,1,MATCH($B$3,NORMATIVOS!$C$1:$XFD$1,0))="En proceso")+--(INDEX(NORMATIVOS!$C$111:$XFD$111,1,MATCH($B$3,NORMATIVOS!$C$1:$XFD$1,0))="En proceso")+--(INDEX(NORMATIVOS!$C$112:$XFD$112,1,MATCH($B$3,NORMATIVOS!$C$1:$XFD$1,0))="En proceso")+--(INDEX(NORMATIVOS!$C$113:$XFD$113,1,MATCH($B$3,NORMATIVOS!$C$1:$XFD$1,0))="En proceso")+--(INDEX(NORMATIVOS!$C$114:$XFD$114,1,MATCH($B$3,NORMATIVOS!$C$1:$XFD$1,0))="En proceso")+--(INDEX(NORMATIVOS!$C$115:$XFD$115,1,MATCH($B$3,NORMATIVOS!$C$1:$XFD$1,0))="En proceso")+--(INDEX(NORMATIVOS!$C$116:$XFD$116,1,MATCH($B$3,NORMATIVOS!$C$1:$XFD$1,0))="En proceso")+--(INDEX(NORMATIVOS!$C$117:$XFD$117,1,MATCH($B$3,NORMATIVOS!$C$1:$XFD$1,0))="En proceso")+--(INDEX(NORMATIVOS!$C$118:$XFD$118,1,MATCH($B$3,NORMATIVOS!$C$1:$XFD$1,0))="En proceso")+--(INDEX(NORMATIVOS!$C$119:$XFD$119,1,MATCH($B$3,NORMATIVOS!$C$1:$XFD$1,0))="En proceso")+--(INDEX(NORMATIVOS!$C$120:$XFD$120,1,MATCH($B$3,NORMATIVOS!$C$1:$XFD$1,0))="En proceso")+--(INDEX(NORMATIVOS!$C$121:$XFD$121,1,MATCH($B$3,NORMATIVOS!$C$1:$XFD$1,0))="En proceso")+--(INDEX(NORMATIVOS!$C$122:$XFD$122,1,MATCH($B$3,NORMATIVOS!$C$1:$XFD$1,0))="En proceso") -> 0 | G13: =--(INDEX(NORMATIVOS!$C$108:$XFD$108,1,MATCH($B$3,NORMATIVOS!$C$1:$XFD$1,0))="Proyección")+--(INDEX(NORMATIVOS!$C$109:$XFD$109,1,MATCH($B$3,NORMATIVOS!$C$1:$XFD$1,0))="Proyección")+--(INDEX(NORMATIVOS!$C$110:$XFD$110,1,MATCH($B$3,NORMATIVOS!$C$1:$XFD$1,0))="Proyección")+--(INDEX(NORMATIVOS!$C$111:$XFD$111,1,MATCH($B$3,NORMATIVOS!$C$1:$XFD$1,0))="Proyección")+--(INDEX(NORMATIVOS!$C$112:$XFD$112,1,MATCH($B$3,NORMATIVOS!$C$1:$XFD$1,0))="Proyección")+--(INDEX(NORMATIVOS!$C$113:$XFD$113,1,MATCH($B$3,NORMATIVOS!$C$1:$XFD$1,0))="Proyección")+--(INDEX(NORMATIVOS!$C$114:$XFD$114,1,MATCH($B$3,NORMATIVOS!$C$1:$XFD$1,0))="Proyección")+--(INDEX(NORMATIVOS!$C$115:$XFD$115,1,MATCH($B$3,NORMATIVOS!$C$1:$XFD$1,0))="Proyección")+--(INDEX(NORMATIVOS!$C$116:$XFD$116,1,MATCH($B$3,NORMATIVOS!$C$1:$XFD$1,0))="Proyección")+--(INDEX(NORMATIVOS!$C$117:$XFD$117,1,MATCH($B$3,NORMATIVOS!$C$1:$XFD$1,0))="Proyección")+--(INDEX(NORMATIVOS!$C$118:$XFD$118,1,MATCH($B$3,NORMATIVOS!$C$1:$XFD$1,0))="Proyección")+--(INDEX(NORMATIVOS!$C$119:$XFD$119,1,MATCH($B$3,NORMATIVOS!$C$1:$XFD$1,0))="Proyección")+--(INDEX(NORMATIVOS!$C$120:$XFD$120,1,MATCH($B$3,NORMATIVOS!$C$1:$XFD$1,0))="Proyección")+--(INDEX(NORMATIVOS!$C$121:$XFD$121,1,MATCH($B$3,NORMATIVOS!$C$1:$XFD$1,0))="Proyección")+--(INDEX(NORMATIVOS!$C$122:$XFD$122,1,MATCH($B$3,NORMATIVOS!$C$1:$XFD$1,0))="Proyección") -> 2 | H13: =IFERROR(E13/COUNTA(NORMATIVOS!$B$108:$B$122),0) -> 0.8
