Workbook
Name ListaAtletas: NORMATIVOS!$C$1:$N$1

Sheet NORMATIVOS
B1: Consolidado = 🟩 Proyeccion = 🟦 En Proceso = 🟨 No Adquirido = 🟥 | C1: Renato Garcia | D1: Krishna Vargas | E1: Adolfo Sochiro | F1: Iker Bonilla | G1: Joseph Cardona | H1: Kevin Gonzalez
A2: PISO
A3: POSICIONES BÁSICAS Y FUERZA | B3: Postura de pie firme | C3: Proyección | D3: Proyección | E3: Proyección | F3: Proyección | G3: Proyección | H3: Proyección | I3: Proyección | J3: Proyección | K3: Proyección | L3: Proyección | M3: Proyección | N3: Proyección | O3: Nivel 3 | P3: Nivel 4 | Q3: Nivel 5 | R3: Nivel 6 | S3: Nivel 7 | T3: Nivel 8 | U3: Nivel 9 | V3: Nivel 10 Jr | W3: Nivel 10 FIG
B4: Parado de hombros | C4: Proyección | D4: Proyección | E4: Proyección | F4: Proyección | G4: Proyección | H4: Proyección | I4: Proyección | J4: Proyección | K4: Proyección | L4: Proyección | M4: Proyección | N4: Proyección
B5: Parado de antebrazos | C5: Proyección | D5: Proyección | E5: Proyección | F5: Proyección | G5: Proyección | H5: Proyección | I5: Proyección | J5: Proyección | K5: Proyección | L5: Proyección | M5: Proyección | N5: Proyección
B6: Parado de cabeza | C6: Proyección | D6: Proyección | E6: Proyección | F6: Proyección | G6: Proyección | H6: Proyección | I6: Proyección | J6: Proyección | K6: Proyección | L6: Proyección | M6: Proyección | N6: Proyección
B7: Parado de manos en apoyo | C7: Proyección | D7: Proyección | E7: Proyección | F7: Proyección | G7: Proyección | H7: Proyección | I7: Proyección | J7: Proyección | K7: Proyección | L7: Proyección | M7: Proyección | N7: Proyección
B8: Parado de Manos | C8: Proyección | D8: Proyección | E8: Proyección | F8: Proyección | G8: Proyección | H8: Proyección | I8: Proyección | J8: Proyección | K8: Proyección | L8: Proyección | M8: Proyección | N8: Proyección
B9: Split | C9: Proyección | D9: Proyección | E9: Proyección | F9: Proyección | G9: Proyección | H9: Proyección | I9: Proyección | J9: Proyección | K9: Proyección | L9: Proyección | M9: Proyección | N9: Proyección
B10: Squat | C10: Proyección | D10: Proyección | E10: Proyección | F10: Proyección | G10: Proyección | H10: Proyección | I10: Proyección | J10: Proyección | K10: Proyección | L10: Proyección | M10: Proyección | N10: Proyección
B11: Equilibrio a un pie (arabesca) | C11: Proyección | D11: Proyección | E11: Proyección | F11: Proyección | G11: Proyección | H11: Proyección | I11: Proyección | J11: Proyección | K11: Proyección | L11: Proyección | M11: Proyección | N11: Proyección
B12: L sit | C12: Proyección | D12: Proyección | E12: Proyección | F12: Proyección | G12: Proyección | H12: Proyección | I12: Proyección | J12: Proyección | K12: Proyección | L12: Proyección | M12: Proyección | N12: Proyección
B13: Sustentación en Arco | C13: Proyección | D13: Proyección | E13: Proyección | F13: Proyección | G13: Proyección | H13: Proyección | I13: Proyección | J13: Proyección | K13: Proyección | L13: Proyección | M13: Proyección | N13: Proyección
B14: Soporte en escuadra endo | C14: Proyección | D14: Proyección | E14: Proyección | F14: Proyección | G14: Proyección | H14: Proyección | I14: Proyección | J14: Proyección | K14: Proyección | L14: Proyección | M14: Proyección | N14: Proyección
B15: Kato de fuerza | C15: Proyección | D15: Proyección | E15: Proyección | F15: Proyección | G15: Proyección | H15: Proyección | I15: Proyección | J15: Proyección | K15: Proyección | L15: Proyección | M15: Proyección | N15: Proyección
B16: Rodada Kato | C16: Proyección | D16: Proyección | E16: Proyección | F16: Proyección | G16: Proyección | H16: Proyección | I16: Proyección | J16: Proyección | K16: Proyección | L16: Proyección | M16: Proyección | N16: Proyección
A17: ACROBATICO HACÍA DELANTE | B17: Rodada adelanté | C17: Proyección | D17: Proyección | E17: Proyección | F17: Proyección | G17: Proyección | H17: Proyección | I17: Proyección | J17: Proyección | K17: Proyección | L17: Proyección | M17: Proyección | N17: Proyección | O17: Nivel 3 | P17: Nivel 4 | Q17: Nivel 5 | R17: Nivel 6 | S17: Nivel 7 | T17: Nivel 8 | U17: Nivel 9 | V17: Nivel 10 Jr | W17: Nivel 10 FIG
B18: Vuelta de carro | C18: Proyección | D18: Proyección | E18: Proyección | F18: Proyección | G18: Proyección | H18: Proyección | I18: Proyección | J18: Proyección | K18: Proyección | L18: Proyección | M18: Proyección | N18: Proyección
B19: Redondilla | C19: Proyección | D19: Proyección | E19: Proyección | F19: Proyección | G19: Proyección | H19: Proyección | I19: Proyección | J19: Proyección | K19: Proyección | L19: Proyección | M19: Proyección | N19: Proyección
B20: Resorte a 2 pies | C20: Proyección | D20: Proyección | E20: Proyección | F20: Proyección | G20: Proyección | H20: Proyección | I20: Proyección | J20: Proyección | K20: Proyección | L20: Proyección | M20: Proyección | N20: Proyección
B21: Resorte a 1 pie | C21: Proyección | D21: Proyección | E21: Proyección | F21: Proyección | G21: Proyección | H21: Proyección | I21: Proyección | J21: Proyección | K21: Proyección | L21: Proyección | M21: Proyección | N21: Proyección
B22: Mortal adelante en C | C22: Proyección | D22: Proyección | E22: Proyección | F22: Proyección | G22: Proyección | H22: Proyección | I22: Proyección | J22: Proyección | K22: Proyección | L22: Proyección | M22: Proyección | N22: Proyección
B23: Resorte 1 a 2 | C23: Proyección | D23: Proyección | E23: Proyección | F23: Proyección | G23: Proyección | H23: Proyección | I23: Proyección | J23: Proyección | K23: Proyección | L23: Proyección | M23: Proyección | N23: Proyección
B24: Mortal adelante en V | C24: Proyección | D24: Proyección | E24: Proyección | F24: Proyección | G24: Proyección | H24: Proyección | I24: Proyección | J24: Proyección | K24: Proyección | L24: Proyección | M24: Proyección | N24: Proyección
B25: Mortal extendido | C25: Proyección | D25: Proyección | E25: Proyección | F25: Proyección | G25: Proyección | H25: Proyección | I25: Proyección | J25: Proyección | K25: Proyección | L25: Proyección | M25: Proyección | N25: Proyección
B26: Mortal rebote mortal | C26: Proyección | D26: Proyección | E26: Proyección | F26: Proyección | G26: Proyección | H26: Proyección | I26: Proyección | J26: Proyección | K26: Proyección | L26: Proyección | M26: Proyección | N26: Proyección
B27: Doble mortal en C adelanté | C27: Proyección | D27: Proyección | E27: Proyección | F27: Proyección | G27: Proyección | H27: Proyección | I27: Proyección | J27: Proyección | K27: Proyección | L27: Proyección | M27: Proyección | N27: Proyección
A28: ACROBATICO HACÍA ATRÁS | B28: Rodada atras | C28: Proyección | D28: Proyección | E28: Proyección | F28: Proyección | G28: Proyección | H28: Proyección | I28: Proyección | J28: Proyección | K28: Proyección | L28: Proyección | M28: Proyección | N28: Proyección | O28: Nivel 3 | P28: Nivel 4 | Q28: Nivel 5 | R28: Nivel 6 | S28: Nivel 7 | T28: Nivel 8 | U28: Nivel 9 | V28: Nivel 10 Jr | W28: Nivel 10 FIG
B29: Rodada atrás a parado de manos | C29: Proyección | D29: Proyección | E29: Proyección | F29: Proyección | G29: Proyección | H29: Proyección | I29: Proyección | J29: Proyección | K29: Proyección | L29: Proyección | M29: Proyección | N29: Proyección
B30: Flic flac | C30: Proyección | D30: Proyección | E30: Proyección | F30: Proyección | G30: Proyección | H30: Proyección | I30: Proyección | J30: Proyección | K30: Proyección | L30: Proyección | M30: Proyección | N30: Proyección
B31: Doble flic | C31: Proyección | D31: Proyección | E31: Proyección | F31: Proyección | G31: Proyección | H31: Proyección | I31: Proyección | J31: Proyección | K31: Proyección | L31: Proyección | M31: Proyección | N31: Proyección
B32: Mortal atras en C desde Redondilla | C32: Proyección | D32: Proyección | E32: Proyección | F32: Proyección | G32: Proyección | H32: Proyección | I32: Proyección | J32: Proyección | K32: Proyección | L32: Proyección | M32: Proyección | N32: Proyección
B33: Mortal atras en C desde Flic flac | C33: Proyección | D33: Proyección | E33: Proyección | F33: Proyección | G33: Proyección | H33: Proyección | I33: Proyección | J33: Proyección | K33: Proyección | L33: Proyección | M33: Proyección | N33: Proyección
B34: Mortal en V atras | C34: Proyección | D34: Proyección | E34: Proyección | F34: Proyección | G34: Proyección | H34: Proyección | I34: Proyección | J34: Proyección | K34: Proyección | L34: Proyección | M34: Proyección | N34: Proyección
B35: Mortal extendido atras | C35: Proyección | D35: Proyección | E35: Proyección | F35: Proyección | G35: Proyección | H35: Proyección | I35: Proyección | J35: Proyección | K35: Proyección | L35: Proyección | M35: Proyección | N35: Proyección
B36: Power flic (Tempo) | C36: Proyección | D36: Proyección | E36: Proyección | F36: Proyección | G36: Proyección | H36: Proyección | I36: Proyección | J36: Proyección | K36: Proyección | L36: Proyección | M36: Proyección | N36: Proyección
B37: Doble mortal atrás en C | C37: Proyección | D37: Proyección | E37: Proyección | F37: Proyección | G37: Proyección | H37: Proyección | I37: Proyección | J37: Proyección | K37: Proyección | L37: Proyección | M37: Proyección | N37: Proyección
A38: ACROBATICO CON GIRO | B38: Mortal extendido atras con 1/2 giro | C38: Proyección | D38: Proyección | E38: Proyección | F38: Proyección | G38: Proyección | H38: Proyección | I38: Proyección | J38: Proyección | K38: Proyección | L38: Proyección | M38: Proyección | N38: Proyección | R38: Nivel 6 | S38: Nivel 7 | T38: Nivel 8 | U38: Nivel 9 | V38: Nivel 10 Jr | W38: Nivel 10 FIG
B39: Mortal extendido atras con un giro | C39: Proyección | D39: Proyección | E39: Proyección | F39: Proyección | G39: Proyección | H39: Proyección | I39: Proyección | J39: Proyección | K39: Proyección | L39: Proyección | M39: Proyección | N39: Proyección
B40: Mortal agrupado adelanté con 1/2 giro | C40: Proyección | D40: Proyección | E40: Proyección | F40: Proyección | G40: Proyección | H40: Proyección | I40: Proyección | J40: Proyección | K40: Proyección | L40: Proyección | M40: Proyección | N40: Proyección
...

Sheet FICHA DEL ATLETA
A1: FICHA INDIVIDUAL DE EVALUACIÓN
A3: Atleta: | B3: Renato Garcia
A5: RESUMEN | D5: Aparato | E5: Consolidado | F5: En proceso | G5: Proyección | H5: % dominio
A6: Elementos evaluados | B6: =INDEX(CONSOLIDADO!$B$4:$B$5,MATCH($B$3,CONSOLIDADO!$A$4:$A$5,0)) -> 264 | D6: POSICIONES BÁSICAS Y FUERZA | E6: =--(INDEX(NORMATIVOS!$C$3:$W$3,1,MATCH($B$3,NORMATIVOS!$C$1:$W$1,0))="Consolidado")+--(INDEX(NORMATIVOS!$C$4:$W$4,1,MATCH($B$3,NORMATIVOS!$C$1:$W$1,0))="Consolidado")+--(INDEX(NORMATIVOS!$C$5:$W$5,1,MATCH($B$3,NORMATIVOS!$C$1:$W$1,0))="Consolidado")+--(INDEX(NORMATIVOS!$C$6:$W$6,1,MATCH($B$3,NORMATIVOS!$C$1:$W$1,0))="Consolidado")+--(INDEX(NORMATIVOS!$C$7:$W$7,1,MATCH($B$3,NORMATIVOS!$C$1:$W$1,0))="Consolidado")+--(INDEX(NORMATIVOS!$C$8:$W$8,1,MATCH($B$3,NORMATIVOS!$C$1:$W$1,0))="Consolidado")+--(INDEX(NORMATIVOS!$C$9:$W$9,1,MATCH($B$3,NORMATIVOS!$C$1:$W$1,0))="Consolidado")+--(INDEX(NORMATIVOS!$C$10:$W$10,1,MATCH($B$3,NORMATIVOS!$C$1:$W$1,0))="Consolidado")+--(INDEX(NORMATIVOS!$C$11:$W$11,1,MATCH($B$3,NORMATIVOS!$C$1:$W$1,0))="Consolidado")+--(INDEX(NORMATIVOS!$C$12:$W$12,1,MATCH($B$3,NORMATIVOS!$C$1:$W$1,0))="Consolidado")+--(INDEX(NORMATIVOS!$C$13:$W$13,1,MATCH($B$3,NORMATIVOS!$C$1:$W$1,0))="Consolidado")+--(INDEX(NORMATIVOS!$C$14:$W$14,1,MATCH($B$3,NORMATIVOS!$C$1:$W$1,0))="Consolidado")+--(INDEX(NORMATIVOS!$C$15:$W$15,1,MATCH($B$3,NORMATIVOS!$C$1:$W$1,0))="Consolidado")+--(INDEX(NORMATIVOS!$C$16:$W$16,1,MATCH($B$3,NORMATIVOS!$C$1:$W$1,0))="Consolidado") -> 0 | F6: =--(INDEX(NORMATIVOS!$C$3:$W$3,1,MATCH($B$3,NORMATIVOS!$C$1:$W$1,0))="En proceso")+--(INDEX(NORMATIVOS!$C$4:$W$4,1,MATCH($B$3,NORMATIVOS!$C$1:$W$1,0))="En proceso")+--(INDEX(NORMATIVOS!$C$5:$W$5,1,MATCH($B$3,NORMATIVOS!$C$1:$W$1,0))="En proceso")+--(INDEX(NORMATIVOS!$C$6:$W$6,1,MATCH($B$3,NORMATIVOS!$C$1:$W$1,0))="En proceso")+--(INDEX(NORMATIVOS!$C$7:$W$7,1,MATCH($B$3,NORMATIVOS!$C$1:$W$1,0))="En proceso")+--(INDEX(NORMATIVOS!$C$8:$W$8,1,MATCH($B$3,NORMATIVOS!$C$1:$W$1,0))="En proceso")+--(INDEX(NORMATIVOS!$C$9:$W$9,1,MATCH($B$3,NORMATIVOS!$C$1:$W$1,0))="En proceso")+--(INDEX(NORMATIVOS!$C$10:$W$10,1,MATCH($B$3,NORMATIVOS!$C$1:$W$1,0))="En proceso")+--(INDEX(NORMATIVOS!$C$11:$W$11,1,MATCH($B$3,NORMATIVOS!$C$1:$W$1,0))="En proceso")+--(INDEX(NORMATIVOS!$C$12:$W$12,1,MATCH($B$3,NORMATIVOS!$C$1:$W$1,0))="En proceso")+--(INDEX(NORMATIVOS!$C$13:$W$13,1,MATCH($B$3,NORMATIVOS!$C$1:$W$1,0))="En proceso")+--(INDEX(NORMATIVOS!$C$14:$W$14,1,MATCH($B$3,NORMATIVOS!$C$1:$W$1,0))="En proceso")+--(INDEX(NORMATIVOS!$C$15:$W$15,1,MATCH($B$3,NORMATIVOS!$C$1:$W$1,0))="En proceso")+--(INDEX(NORMATIVOS!$C$16:$W$16,1,MATCH($B$3,NORMATIVOS!$C$1:$W$1,0))="En proceso") -> 0 | G6: =--(INDEX(NORMATIVOS!$C$3:$W$3,1,MATCH($B$3,NORMATIVOS!$C$1:$W$1,0))="Proyección")+--(INDEX(NORMATIVOS!$C$4:$W$4,1,MATCH($B$3,NORMATIVOS!$C$1:$W$1,0))="Proyección")+--(INDEX(NORMATIVOS!$C$5:$W$5,1,MATCH($B$3,NORMATIVOS!$C$1:$W$1,0))="Proyección")+--(INDEX(NORMATIVOS!$C$6:$W$6,1,MATCH($B$3,NORMATIVOS!$C$1:$W$1,0))="Proyección")+--(INDEX(NORMATIVOS!$C$7:$W$7,1,MATCH($B$3,NORMATIVOS!$C$1:$W$1,0))="Proyección")+--(INDEX(NORMATIVOS!$C$8:$W$8,1,MATCH($B$3,NORMATIVOS!$C$1:$W$1,0))="Proyección")+--(INDEX(NORMATIVOS!$C$9:$W$9,1,MATCH($B$3,NORMATIVOS!$C$1:$W$1,0))="Proyección")+--(INDEX(NORMATIVOS!$C$10:$W$10,1,MATCH($B$3,NORMATIVOS!$C$1:$W$1,0))="Proyección")+--(INDEX(NORMATIVOS!$C$11:$W$11,1,MATCH($B$3,NORMATIVOS!$C$1:$W$1,0))="Proyección")+--(INDEX(NORMATIVOS!$C$12:$W$12,1,MATCH($B$3,NORMATIVOS!$C$1:$W$1,0))="Proyección")+--(INDEX(NORMATIVOS!$C$13:$W$13,1,MATCH($B$3,NORMATIVOS!$C$1:$W$1,0))="Proyección")+--(INDEX(NORMATIVOS!$C$14:$W$14,1,MATCH($B$3,NORMATIVOS!$C$1:$W$1,0))="Proyección")+--(INDEX(NORMATIVOS!$C$15:$W$15,1,MATCH($B$3,NORMATIVOS!$C$1:$W$1,0))="Proyección")+--(INDEX(NORMATIVOS!$C$16:$W$16,1,MATCH($B$3,NORMATIVOS!$C$1:$W$1,0))="Proyección") -> 14 | H6: =IFERROR(E6/(E6+F6+G6),0) -> 0
A7: Consolidados | B7: =INDEX(CONSOLIDADO!$C$4:$C$5,MATCH($B$3,CONSOLIDADO!$A$4:$A$5,0)) -> 0 | D7: ACROBATICO HACÍA DELANTE | E7: =--(INDEX(NORMATIVOS!$C$17:$W$17,1,MATCH($B$3,NORMATIVOS!$C$1:$W$1,0))="Consolidado")+--(INDEX(NORMATIVOS!$C$18:$W$18,1,MATCH($B$3,NORMATIVOS!$C$1:$W$1,0))="Consolidado")+--(INDEX(NORMATIVOS!$C$19:$W$19,1,MATCH($B$3,NORMATIVOS!$C$1:$W$1,0))="Consolidado")+--(INDEX(NORMATIVOS!$C$20:$W$20,1,MATCH($B$3,NORMATIVOS!$C$1:$W$1,0))="Consolidado")+--(INDEX(NORMATIVOS!$C$21:$W$21,1,MATCH($B$3,NORMATIVOS!$C$1:$W$1,0))="Consolidado")+--(INDEX(NORMATIVOS!$C$22:$W$22,1,MATCH($B$3,NORMATIVOS!$C$1:$W$1,0))="Consolidado")+--(INDEX(NORMATIVOS!$C$23:$W$23,1,MATCH($B$3,NORMATIVOS!$C$1:$W$1,0))="Consolidado")+--(INDEX(NORMATIVOS!$C$24:$W$24,1,MATCH($B$3,NORMATIVOS!$C$1:$W$1,0))="Consolidado")+--(INDEX(NORMATIVOS!$C$25:$W$25,1,MATCH($B$3,NORMATIVOS!$C$1:$W$1,0))="Consolidado")+--(INDEX(NORMATIVOS!$C$26:$W$26,1,MATCH($B$3,NORMATIVOS!$C$1:$W$1,0))="Consolidado")+--(INDEX(NORMATIVOS!$C$27:$W$27,1,MATCH($B$3,NORMATIVOS!$C$1:$W$1,0))="Consolidado") -> 0 | F7: =--(INDEX(NORMATIVOS!$C$17:$W$17,1,MATCH($B$3,NORMATIVOS!$C$1:$W$1,0))="En proceso")+--(INDEX(NORMATIVOS!$C$18:$W$18,1,MATCH($B$3,NORMATIVOS!$C$1:$W$1,0))="En proceso")+--(INDEX(NORMATIVOS!$C$19:$W$19,1,MATCH($B$3,NORMATIVOS!$C$1:$W$1,0))="En proceso")+--(INDEX(NORMATIVOS!$C$20:$W$20,1,MATCH($B$3,NORMATIVOS!$C$1:$W$1,0))="En proceso")+--(INDEX(NORMATIVOS!$C$21:$W$21,1,MATCH($B$3,NORMATIVOS!$C$1:$W$1,0))="En proceso")+--(INDEX(NORMATIVOS!$C$22:$W$22,1,MATCH($B$3,NORMATIVOS!$C$1:$W$1,0))="En proceso")+--(INDEX(NORMATIVOS!$C$23:$W$23,1,MATCH($B$3,NORMATIVOS!$C$1:$W$1,0))="En proceso")+--(INDEX(NORMATIVOS!$C$24:$W$24,1,MATCH($B$3,NORMATIVOS!$C$1:$W$1,0))="En proceso")+--(INDEX(NORMATIVOS!$C$25:$W$25,1,MATCH($B$3,NORMATIVOS!$C$1:$W$1,0))="En proceso")+--(INDEX(NORMATIVOS!$C$26:$W$26,1,MATCH($B$3,NORMATIVOS!$C$1:$W$1,0))="En proceso")+--(INDEX(NORMATIVOS!$C$27:$W$27,1,MATCH($B$3,NORMATIVOS!$C$1:$W$1,0))="En proceso") -> 0 | G7: =--(INDEX(NORMATIVOS!$C$17:$W$17,1,MATCH($B$3,NORMATIVOS!$C$1:$W$1,0))="Proyección")+--(INDEX(NORMATIVOS!$C$18:$W$18,1,MATCH($B$3,NORMATIVOS!$C$1:$W$1,0))="Proyección")+--(INDEX(NORMATIVOS!$C$19:$W$19,1,MATCH($B$3,NORMATIVOS!$C$1:$W$1,0))="Proyección")+--(INDEX(NORMATIVOS!$C$20:$W$20,1,MATCH($B$3,NORMATIVOS!$C$1:$W$1,0))="Proyección")+--(INDEX(NORMATIVOS!$C$21:$W$21,1,MATCH($B$3,NORMATIVOS!$C$1:$W$1,0))="Proyección")+--(INDEX(NORMATIVOS!$C$22:$W$22,1,MATCH($B$3,NORMATIVOS!$C$1:$W$1,0))="Proyección")+--(INDEX(NORMATIVOS!$C$23:$W$23,1,MATCH($B$3,NORMATIVOS!$C$1:$W$1,0))="Proyección")+--(INDEX(NORMATIVOS!$C$24:$W$24,1,MATCH($B$3,NORMATIVOS!$C$1:$W$1,0))="Proyección")+--(INDEX(NORMATIVOS!$C$25:$W$25,1,MATCH($B$3,NORMATIVOS!$C$1:$W$1,0))="Proyección")+--(INDEX(NORMATIVOS!$C$26:$W$26,1,MATCH($B$3,NORMATIVOS!$C$1:$W$1,0))="Proyección")+--(INDEX(NORMATIVOS!$C$27:$W$27,1,MATCH($B$3,NORMATIVOS!$C$1:$W$1,0))="Proyección") -> 11 | H7: =IFERROR(E7/(E7+F7+G7),0) -> 0
A8: En proceso | B8: =INDEX(CONSOLIDADO!$D$4:$D$5,MATCH($B$3,CONSOLIDADO!$A$4:$A$5,0)) -> 0 | D8: ACROBATICO HACÍA ATRÁS | E8: =--(INDEX(NORMATIVOS!$C$28:$W$28,1,MATCH($B$3,NORMATIVOS!$C$1:$W$1,0))="Consolidado")+--(INDEX(NORMATIVOS!$C$29:$W$29,1,MATCH($B$3,NORMATIVOS!$C$1:$W$1,0))="Consolidado")+--(INDEX(NORMATIVOS!$C$30:$W$30,1,MATCH($B$3,NORMATIVOS!$C$1:$W$1,0))="Consolidado")+--(INDEX(NORMATIVOS!$C$31:$W$31,1,MATCH($B$3,NORMATIVOS!$C$1:$W$1,0))="Consolidado")+--(INDEX(NORMATIVOS!$C$32:$W$32,1,MATCH($B$3,NORMATIVOS!$C$1:$W$1,0))="Consolidado")+--(INDEX(NORMATIVOS!$C$33:$W$33,1,MATCH($B$3,NORMATIVOS!$C$1:$W$1,0))="Consolidado")+--(INDEX(NORMATIVOS!$C$34:$W$34,1,MATCH($B$3,NORMATIVOS!$C$1:$W$1,0))="Consolidado")+--(INDEX(NORMATIVOS!$C$35:$W$35,1,MATCH($B$3,NORMATIVOS!$C$1:$W$1,0))="Consolidado")+--(INDEX(NORMATIVOS!$C$36:$W$36,1,MATCH($B$3,NORMATIVOS!$C$1:$W$1,0))="Consolidado")+--(INDEX(NORMATIVOS!$C$37:$W$37,1,MATCH($B$3,NORMATIVOS!$C$1:$W$1,0))="Consolidado") -> 0 | F8: =--(INDEX(NORMATIVOS!$C$28:$W$28,1,MATCH($B$3,NORMATIVOS!$C$1:$W$1,0))="En proceso")+--(INDEX(NORMATIVOS!$C$29:$W$29,1,MATCH($B$3,NORMATIVOS!$C$1:$W$1,0))="En proceso")+--(INDEX(NORMATIVOS!$C$30:$W$30,1,MATCH($B$3,NORMATIVOS!$C$1:$W$1,0))="En proceso")+--(INDEX(NORMATIVOS!$C$31:$W$31,1,MATCH($B$3,NORMATIVOS!$C$1:$W$1,0))="En proceso")+--(INDEX(NORMATIVOS!$C$32:$W$32,1,MATCH($B$3,NORMATIVOS!$C$1:$W$1,0))="En proceso")+--(INDEX(NORMATIVOS!$C$33:$W$33,1,MATCH($B$3,NORMATIVOS!$C$1:$W$1,0))="En proceso")+--(INDEX(NORMATIVOS!$C$34:$W$34,1,MATCH($B$3,NORMATIVOS!$C$1:$W$1,0))="En proceso")+--(INDEX(NORMATIVOS!$C$35:$W$35,1,MATCH($B$3,NORMATIVOS!$C$1:$W$1,0))="En proceso")+--(INDEX(NORMATIVOS!$C$36:$W$36,1,MATCH($B$3,NORMATIVOS!$C$1:$W$1,0))="En proceso")+--(INDEX(NORMATIVOS!$C$37:$W$37,1,MATCH($B$3,NORMATIVOS!$C$1:$W$1,0))="En proceso") -> 0 | G8: =--(INDEX(NORMATIVOS!$C$28:$W$28,1,MATCH($B$3,NORMATIVOS!$C$1:$W$1,0))="Proyección")+--(INDEX(NORMATIVOS!$C$29:$W$29,1,MATCH($B$3,NORMATIVOS!$C$1:$W$1,0))="Proyección")+--(INDEX(NORMATIVOS!$C$30:$W$30,1,MATCH($B$3,NORMATIVOS!$C$1:$W$1,0))="Proyección")+--(INDEX(NORMATIVOS!$C$31:$W$31,1,MATCH($B$3,NORMATIVOS!$C$1:$W$1,0))="Proyección")+--(INDEX(NORMATIVOS!$C$32:$W$32,1,MATCH($B$3,NORMATIVOS!$C$1:$W$1,0))="Proyección")+--(INDEX(NORMATIVOS!$C$33:$W$33,1,MATCH($B$3,NORMATIVOS!$C$1:$W$1,0))="Proyección")+--(INDEX(NORMATIVOS!$C$34:$W$34,1,MATCH($B$3,NORMATIVOS!$C$1:$W$1,0))="Proyección")+--(INDEX(NORMATIVOS!$C$35:$W$35,1,MATCH($B$3,NORMATIVOS!$C$1:$W$1,0))="Proyección")+--(INDEX(NORMATIVOS!$C$36:$W$36,1,MATCH($B$3,NORMATIVOS!$C$1:$W$1,0))="Proyección")+--(INDEX(NORMATIVOS!$C$37:$W$37,1,MATCH($B$3,NORMATIVOS!$C$1:$W$1,0))="Proyección") -> 10 | H8: =IFERROR(E8/(E8+F8+G8),0) -> 0
A9: Proyección | B9: =INDEX(CONSOLIDADO!$E$4:$E$5,MATCH($B$3,CONSOLIDADO!$A$4:$A$5,0)) -> 264 | D9: ACROBATICO CON GIRO | E9: =--(INDEX(NORMATIVOS!$C$38:$W$38,1,MATCH($B$3,NORMATIVOS!$C$1:$W$1,0))="Consolidado")+--(INDEX(NORMATIVOS!$C$39:$W$39,1,MATCH($B$3,NORMATIVOS!$C$1:$W$1,0))="Consolidado")+--(INDEX(NORMATIVOS!$C$40:$W$40,1,MATCH($B$3,NORMATIVOS!$C$1:$W$1,0))="Consolidado")+--(INDEX(NORMATIVOS!$C$41:$W$41,1,MATCH($B$3,NORMATIVOS!$C$1:$W$1,0))="Consolidado")+--(INDEX(NORMATIVOS!$C$42:$W$42,1,MATCH($B$3,NORMATIVOS!$C$1:$W$1,0))="Consolidado")+--(INDEX(NORMATIVOS!$C$43:$W$43,1,MATCH($B$3,NORMATIVOS!$C$1:$W$1,0))="Consolidado")+--(INDEX(NORMATIVOS!$C$44:$W$44,1,MATCH($B$3,NORMATIVOS!$C$1:$W$1,0))="Consolidado")+--(INDEX(NORMATIVOS!$C$45:$W$45,1,MATCH($B$3,NORMATIVOS!$C$1:$W$1,0))="Consolidado")+--(INDEX(NORMATIVOS!$C$46:$W$46,1,MATCH($B$3,NORMATIVOS!$C$1:$W$1,0))="Consolidado") -> 0 | F9: =--(INDEX(NORMATIVOS!$C$38:$W$38,1,MATCH($B$3,NORMATIVOS!$C$1:$W$1,0))="En proceso")+--(INDEX(NORMATIVOS!$C$39:$W$39,1,MATCH($B$3,NORMATIVOS!$C$1:$W$1,0))="En proceso")+--(INDEX(NORMATIVOS!$C$40:$W$40,1,MATCH($B$3,NORMATIVOS!$C$1:$W$1,0))="En proceso")+--(INDEX(NORMATIVOS!$C$41:$W$41,1,MATCH($B$3,NORMATIVOS!$C$1:$W$1,0))="En proceso")+--(INDEX(NORMATIVOS!$C$42:$W$42,1,MATCH($B$3,NORMATIVOS!$C$1:$W$1,0))="En proceso")+--(INDEX(NORMATIVOS!$C$43:$W$43,1,MATCH($B$3,NORMATIVOS!$C$1:$W$1,0))="En proceso")+--(INDEX(NORMATIVOS!$C$44:$W$44,1,MATCH($B$3,NORMATIVOS!$C$1:$W$1,0))="En proceso")+--(INDEX(NORMATIVOS!$C$45:$W$45,1,MATCH($B$3,NORMATIVOS!$C$1:$W$1,0))="En proceso")+--(INDEX(NORMATIVOS!$C$46:$W$46,1,MATCH($B$3,NORMATIVOS!$C$1:$W$1,0))="En proceso") -> 0 | G9: =--(INDEX(NORMATIVOS!$C$38:$W$38,1,MATCH($B$3,NORMATIVOS!$C$1:$W$1,0))="Proyección")+--(INDEX(NORMATIVOS!$C$39:$W$39,1,MATCH($B$3,NORMATIVOS!$C$1:$W$1,0))="Proyección")+--(INDEX(NORMATIVOS!$C$40:$W$40,1,MATCH($B$3,NORMATIVOS!$C$1:$W$1,0))="Proyección")+--(INDEX(NORMATIVOS!$C$41:$W$41,1,MATCH($B$3,NORMATIVOS!$C$1:$W$1,0))="Proyección")+--(INDEX(NORMATIVOS!$C$42:$W$42,1,MATCH($B$3,NORMATIVOS!$C$1:$W$1,0))="Proyección")+--(INDEX(NORMATIVOS!$C$43:$W$43,1,MATCH($B$3,NORMATIVOS!$C$1:$W$1,0))="Proyección")+--(INDEX(NORMATIVOS!$C$44:$W$44,1,MATCH($B$3,NORMATIVOS!$C$1:$W$1,0))="Proyección")+--(INDEX(NORMATIVOS!$C$45:$W$45,1,MATCH($B$3,NORMATIVOS!$C$1:$W$1,0))="Proyección")+--(INDEX(NORMATIVOS!$C$46:$W$46,1,MATCH($B$3,NORMATIVOS!$C$1:$W$1,0))="Proyección") -> 9 | H9: =IFERROR(E9/(E9+F9+G9),0) -> 0
A10: N/A | B10: =INDEX(CONSOLIDADO!$F$4:$F$5,MATCH($B$3,CONSOLIDADO!$A$4:$A$5,0)) -> 0 | D10: HONGO | E10: =--(INDEX(NORMATIVOS!$C$49:$W$49,1,MATCH($B$3,NORMATIVOS!$C$1:$W$1,0))="Consolidado")+--(INDEX(NORMATIVOS!$C$50:$W$50,1,MATCH($B$3,NORMATIVOS!$C$1:$W$1,0))="Consolidado")+--(INDEX(NORMATIVOS!$C$51:$W$51,1,MATCH($B$3,NORMATIVOS!$C$1:$W$1,0))="Consolidado")+--(INDEX(NORMATIVOS!$C$52:$W$52,1,MATCH($B$3,NORMATIVOS!$C$1:$W$1,0))="Consolidado")+--(INDEX(NORMATIVOS!$C$53:$W$53,1,MATCH($B$3,NORMATIVOS!$C$1:$W$1,0))="Consolidado")+--(INDEX(NORMATIVOS!$C$54:$W$54,1,MATCH($B$3,NORMATIVOS!$C$1:$W$1,0))="Consolidado")+--(INDEX(NORMATIVOS!$C$55:$W$55,1,MATCH($B$3,NORMATIVOS!$C$1:$W$1,0))="Consolidado")+--(INDEX(NORMATIVOS!$C$56:$W$56,1,MATCH($B$3,NORMATIVOS!$C$1:$W$1,0))="Consolidado")+--(INDEX(NORMATIVOS!$C$57:$W$57,1,MATCH($B$3,NORMATIVOS!$C$1:$W$1,0))="Consolidado")+--(INDEX(NORMATIVOS!$C$58:$W$58,1,MATCH($B$3,NORMATIVOS!$C$1:$W$1,0))="Consolidado")+--(INDEX(NORMATIVOS!$C$59:$W$59,1,MATCH($B$3,NORMATIVOS!$C$1:$W$1,0))="Consolidado")+--(INDEX(NORMATIVOS!$C$60:$W$60,1,MATCH($B$3,NORMATIVOS!$C$1:$W$1,0))="Consolidado")+--(INDEX(NORMATIVOS!$C$61:$W$61,1,MATCH($B$3,NORMATIVOS!$C$1:$W$1,0))="Consolidado")+--(INDEX(NORMATIVOS!$C$62:$W$62,1,MATCH($B$3,NORMATIVOS!$C$1:$W$1,0))="Consolidado")+--(INDEX(NORMATIVOS!$C$63:$W$63,1,MATCH($B$3,NORMATIVOS!$C$1:$W$1,0))="Consolidado")+--(INDEX(NORMATIVOS!$C$64:$W$64,1,MATCH($B$3,NORMATIVOS!$C$1:$W$1,0))="Consolidado") -> 0 | F10: =--(INDEX(NORMATIVOS!$C$49:$W$49,1,MATCH($B$3,NORMATIVOS!$C$1:$W$1,0))="En proceso")+--(INDEX(NORMATIVOS!$C$50:$W$50,1,MATCH($B$3,NORMATIVOS!$C$1:$W$1,0))="En proceso")+--(INDEX(NORMATIVOS!$C$51:$W$51,1,MATCH($B$3,NORMATIVOS!$C$1:$W$1,0))="En proceso")+--(INDEX(NORMATIVOS!$C$52:$W$52,1,MATCH($B$3,NORMATIVOS!$C$1:$W$1,0))="En proceso")+--(INDEX(NORMATIVOS!$C$53:$W$53,1,MATCH($B$3,NORMATIVOS!$C$1:$W$1,0))="En proceso")+--(INDEX(NORMATIVOS!$C$54:$W$54,1,MATCH($B$3,NORMATIVOS!$C$1:$W$1,0))="En proceso")+--(INDEX(NORMATIVOS!$C$55:$W$55,1,MATCH($B$3,NORMATIVOS!$C$1:$W$1,0))="En proceso")+--(INDEX(NORMATIVOS!$C$56:$W$56,1,MATCH($B$3,NORMATIVOS!$C$1:$W$1,0))="En proceso")+--(INDEX(NORMATIVOS!$C$57:$W$57,1,MATCH($B$3,NORMATIVOS!$C$1:$W$1,0))="En proceso")+--(INDEX(NORMATIVOS!$C$58:$W$58,1,MATCH($B$3,NORMATIVOS!$C$1:$W$1,0))="En proceso")+--(INDEX(NORMATIVOS!$C$59:$W$59,1,MATCH($B$3,NORMATIVOS!$C$1:$W$1,0))="En proceso")+--(INDEX(NORMATIVOS!$C$60:$W$60,1,MATCH($B$3,NORMATIVOS!$C$1:$W$1,0))="En proceso")+--(INDEX(NORMATIVOS!$C$61:$W$61,1,MATCH($B$3,NORMATIVOS!$C$1:$W$1,0))="En proceso")+--(INDEX(NORMATIVOS!$C$62:$W$62,1,MATCH($B$3,NORMATIVOS!$C$1:$W$1,0))="En proceso")+--(INDEX(NORMATIVOS!$C$63:$W$63,1,MATCH($B$3,NORMATIVOS!$C$1:$W$1,0))="En proceso")+--(INDEX(NORMATIVOS!$C$64:$W$64,1,MATCH($B$3,NORMATIVOS!$C$1:$W$1,0))="En proceso") -> 0 | G10: =--(INDEX(NORMATIVOS!$C$49:$W$49,1,MATCH($B$3,NORMATIVOS!$C$1:$W$1,0))="Proyección")+--(INDEX(NORMATIVOS!$C$50:$W$50,1,MATCH($B$3,NORMATIVOS!$C$1:$W$1,0))="Proyección")+--(INDEX(NORMATIVOS!$C$51:$W$51,1,MATCH($B$3,NORMATIVOS!$C$1:$W$1,0))="Proyección")+--(INDEX(NORMATIVOS!$C$52:$W$52,1,MATCH($B$3,NORMATIVOS!$C$1:$W$1,0))="Proyección")+--(INDEX(NORMATIVOS!$C$53:$W$53,1,MATCH($B$3,NORMATIVOS!$C$1:$W$1,0))="Proyección")+--(INDEX(NORMATIVOS!$C$54:$W$54,1,MATCH($B$3,NORMATIVOS!$C$1:$W$1,0))="Proyección")+--(INDEX(NORMATIVOS!$C$55:$W$55,1,MATCH($B$3,NORMATIVOS!$C$1:$W$1,0))="Proyección")+--(INDEX(NORMATIVOS!$C$56:$W$56,1,MATCH($B$3,NORMATIVOS!$C$1:$W$1,0))="Proyección")+--(INDEX(NORMATIVOS!$C$57:$W$57,1,MATCH($B$3,NORMATIVOS!$C$1:$W$1,0))="Proyección")+--(INDEX(NORMATIVOS!$C$58:$W$58,1,MATCH($B$3,NORMATIVOS!$C$1:$W$1,0))="Proyección")+--(INDEX(NORMATIVOS!$C$59:$W$59,1,MATCH($B$3,NORMATIVOS!$C$1:$W$1,0))="Proyección")+--(INDEX(NORMATIVOS!$C$60:$W$60,1,MATCH($B$3,NORMATIVOS!$C$1:$W$1,0))="Proyección")+--(INDEX(NORMATIVOS!$C$61:$W$61,1,MATCH($B$3,NORMATIVOS!$C$1:$W$1,0))="Proyección")+--(INDEX(NORMATIVOS!$C$62:$W$62,1,MATCH($B$3,NORMATIVOS!$C$1:$W$1,0))="Proyección")+--(INDEX(NORMATIVOS!$C$63:$W$63,1,MATCH($B$3,NORMATIVOS!$C$1:$W$1,0))="Proyección")+--(INDEX(NORMATIVOS!$C$64:$W$64,1,MATCH($B$3,NORMATIVOS!$C$1:$W$1,0))="Proyección") -> 16 | H10: =IFERROR(E10/(E10+F10+G10),0) -> 0
A11: % dominio | B11: =INDEX(CONSOLIDADO!$G$4:$G$5,MATCH($B$3,CONSOLIDADO!$A$4:$A$5,0)) -> 0 | D11: CABALLO SIN ARZON | E11: =--(INDEX(NORMATIVOS!$C$65:$W$65,1,MATCH($B$3,NORMATIVOS!$C$1:$W$1,0))="Consolidado")+--(INDEX(NORMATIVOS!$C$66:$W$66,1,MATCH($B$3,NORMATIVOS!$C$1:$W$1,0))="Consolidado")+--(INDEX(NORMATIVOS!$C$67:$W$67,1,MATCH($B$3,NORMATIVOS!$C$1:$W$1,0))="Consolidado")+--(INDEX(NORMATIVOS!$C$68:$W$68,1,MATCH($B$3,NORMATIVOS!$C$1:$W$1,0))="Consolidado")+--(INDEX(NORMATIVOS!$C$69:$W$69,1,MATCH($B$3,NORMATIVOS!$C$1:$W$1,0))="Consolidado")+--(INDEX(NORMATIVOS!$C$70:$W$70,1,MATCH($B$3,NORMATIVOS!$C$1:$W$1,0))="Consolidado")+--(INDEX(NORMATIVOS!$C$71:$W$71,1,MATCH($B$3,NORMATIVOS!$C$1:$W$1,0))="Consolidado")+--(INDEX(NORMATIVOS!$C$72:$W$72,1,MATCH($B$3,NORMATIVOS!$C$1:$W$1,0))="Consolidado")+--(INDEX(NORMATIVOS!$C$73:$W$73,1,MATCH($B$3,NORMATIVOS!$C$1:$W$1,0))="Consolidado")+--(INDEX(NORMATIVOS!$C$74:$W$74,1,MATCH($B$3,NORMATIVOS!$C$1:$W$1,0))="Consolidado")+--(INDEX(NORMATIVOS!$C$75:$W$75,1,MATCH($B$3,NORMATIVOS!$C$1:$W$1,0))="Consolidado")+--(INDEX(NORMATIVOS!$C$76:$W$76,1,MATCH($B$3,NORMATIVOS!$C$1:$W$1,0))="Consolidado")+--(INDEX(NORMATIVOS!$C$77:$W$77,1,MATCH($B$3,NORMATIVOS!$C$1:$W$1,0))="Consolidado")+--(INDEX(NORMATIVOS!$C$78:$W$78,1,MATCH($B$3,NORMATIVOS!$C$1:$W$1,0))="Consolidado") -> 0 | F11: =--(INDEX(NORMATIVOS!$C$65:$W$65,1,MATCH($B$3,NORMATIVOS!$C$1:$W$1,0))="En proceso")+--(INDEX(NORMATIVOS!$C$66:$W$66,1,MATCH($B$3,NORMATIVOS!$C$1:$W$1,0))="En proceso")+--(INDEX(NORMATIVOS!$C$67:$W$67,1,MATCH($B$3,NORMATIVOS!$C$1:$W$1,0))="En proceso")+--(INDEX(NORMATIVOS!$C$68:$W$68,1,MATCH($B$3,NORMATIVOS!$C$1:$W$1,0))="En proceso")+--(INDEX(NORMATIVOS!$C$69:$W$69,1,MATCH($B$3,NORMATIVOS!$C$1:$W$1,0))="En proceso")+--(INDEX(NORMATIVOS!$C$70:$W$70,1,MATCH($B$3,NORMATIVOS!$C$1:$W$1,0))="En proceso")+--(INDEX(NORMATIVOS!$C$71:$W$71,1,MATCH($B$3,NORMATIVOS!$C$1:$W$1,0))="En proceso")+--(INDEX(NORMATIVOS!$C$72:$W$72,1,MATCH($B$3,NORMATIVOS!$C$1:$W$1,0))="En proceso")+--(INDEX(NORMATIVOS!$C$73:$W$73,1,MATCH($B$3,NORMATIVOS!$C$1:$W$1,0))="En proceso")+--(INDEX(NORMATIVOS!$C$74:$W$74,1,MATCH($B$3,NORMATIVOS!$C$1:$W$1,0))="En proceso")+--(INDEX(NORMATIVOS!$C$75:$W$75,1,MATCH($B$3,NORMATIVOS!$C$1:$W$1,0))="En proceso")+--(INDEX(NORMATIVOS!$C$76:$W$76,1,MATCH($B$3,NORMATIVOS!$C$1:$W$1,0))="En proceso")+--(INDEX(NORMATIVOS!$C$77:$W$77,1,MATCH($B$3,NORMATIVOS!$C$1:$W$1,0))="En proceso")+--(INDEX(NORMATIVOS!$C$78:$W$78,1,MATCH($B$3,NORMATIVOS!$C$1:$W$1,0))="En proceso") -> 0 | G11: =--(INDEX(NORMATIVOS!$C$65:$W$65,1,MATCH($B$3,NORMATIVOS!$C$1:$W$1,0))="Proyección")+--(INDEX(NORMATIVOS!$C$66:$W$66,1,MATCH($B$3,NORMATIVOS!$C$1:$W$1,0))="Proyección")+--(INDEX(NORMATIVOS!$C$67:$W$67,1,MATCH($B$3,NORMATIVOS!$C$1:$W$1,0))="Proyección")+--(INDEX(NORMATIVOS!$C$68:$W$68,1,MATCH($B$3,NORMATIVOS!$C$1:$W$1,0))="Proyección")+--(INDEX(NORMATIVOS!$C$69:$W$69,1,MATCH($B$3,NORMATIVOS!$C$1:$W$1,0))="Proyección")+--(INDEX(NORMATIVOS!$C$70:$W$70,1,MATCH($B$3,NORMATIVOS!$C$1:$W$1,0))="Proyección")+--(INDEX(NORMATIVOS!$C$71:$W$71,1,MATCH($B$3,NORMATIVOS!$C$1:$W$1,0))="Proyección")+--(INDEX(NORMATIVOS!$C$72:$W$72,1,MATCH($B$3,NORMATIVOS!$C$1:$W$1,0))="Proyección")+--(INDEX(NORMATIVOS!$C$73:$W$73,1,MATCH($B$3,NORMATIVOS!$C$1:$W$1,0))="Proyección")+--(INDEX(NORMATIVOS!$C$74:$W$74,1,MATCH($B$3,NORMATIVOS!$C$1:$W$1,0))="Proyección")+--(INDEX(NORMATIVOS!$C$75:$W$75,1,MATCH($B$3,NORMATIVOS!$C$1:$W$1,0))="Proyección")+--(INDEX(NORMATIVOS!$C$76:$W$76,1,MATCH($B$3,NORMATIVOS!$C$1:$W$1,0))="Proyección")+--(INDEX(NORMATIVOS!$C$77:$W$77,1,MATCH($B$3,NORMATIVOS!$C$1:$W$1,0))="Proyección")+--(INDEX(NORMATIVOS!$C$78:$W$78,1,MATCH($B$3,NORMATIVOS!$C$1:$W$1,0))="Proyección") -> 14 | H11: =IFERROR(E11/(E11+F11+G11),0) -> 0
D12: CABALLO CON ARZONES | E12: =--(INDEX(NORMATIVOS!$C$79:$W$79,1,MATCH($B$3,NORMATIVOS!$C$1:$W$1,0))="Consolidado")+--(INDEX(NORMATIVOS!$C$80:$W$80,1,MATCH($B$3,NORMATIVOS!$C$1:$W$1,0))="Consolidado")+--(INDEX(NORMATIVOS!$C$81:$W$81,1,MATCH($B$3,NORMATIVOS!$C$1:$W$1,0))="Consolidado")+--(INDEX(NORMATIVOS!$C$82:$W$82,1,MATCH($B$3,NORMATIVOS!$C$1:$W$1,0))="Consolidado")+--(INDEX(NORMATIVOS!$C$83:$W$83,1,MATCH($B$3,NORMATIVOS!$C$1:$W$1,0))="Consolidado")+--(INDEX(NORMATIVOS!$C$84:$W$84,1,MATCH($B$3,NORMATIVOS!$C$1:$W$1,0))="Consolidado")+--(INDEX(NORMATIVOS!$C$85:$W$85,1,MATCH($B$3,NORMATIVOS!$C$1:$W$1,0))="Consolidado")+--(INDEX(NORMATIVOS!$C$86:$W$86,1,MATCH($B$3,NORMATIVOS!$C$1:$W$1,0))="Consolidado")+--(INDEX(NORMATIVOS!$C$87:$W$87,1,MATCH($B$3,NORMATIVOS!$C$1:$W$1,0))="Consolidado")+--(INDEX(NORMATIVOS!$C$88:$W$88,1,MATCH($B$3,NORMATIVOS!$C$1:$W$1,0))="Consolidado")+--(INDEX(NORMATIVOS!$C$89:$W$89,1,MATCH($B$3,NORMATIVOS!$C$1:$W$1,0))="Consolidado")+--(INDEX(NORMATIVOS!$C$90:$W$90,1,MATCH($B$3,NORMATIVOS!$C$1:$W$1,0))="Consolidado")+--(INDEX(NORMATIVOS!$C$91:$W$91,1,MATCH($B$3,NORMATIVOS!$C$1:$W$1,0))="Consolidado")+--(INDEX(NORMATIVOS!$C$92:$W$92,1,MATCH($B$3,NORMATIVOS!$C$1:$W$1,0))="Consolidado")+--(INDEX(NORMATIVOS!$C$93:$W$93,1,MATCH($B$3,NORMATIVOS!$C$1:$W$1,0))="Consolidado")+--(INDEX(NORMATIVOS!$C$94:$W$94,1,MATCH($B$3,NORMATIVOS!$C$1:$W$1,0))="Consolidado")+--(INDEX(NORMATIVOS!$C$95:$W$95,1,MATCH($B$3,NORMATIVOS!$C$1:$W$1,0))="Consolidado")+--(INDEX(NORMATIVOS!$C$96:$W$96,1,MATCH($B$3,NORMATIVOS!$C$1:$W$1,0))="Consolidado")+--(INDEX(NORMATIVOS!$C$97:$W$97,1,MATCH($B$3,NORMATIVOS!$C$1:$W$1,0))="Consolidado")+--(INDEX(NORMATIVOS!$C$98:$W$98,1,MATCH($B$3,NORMATIVOS!$C$1:$W$1,0))="Consolidado")+--(INDEX(NORMATIVOS!$C$99:$W$99,1,MATCH($B$3,NORMATIVOS!$C$1:$W$1,0))="Consolidado")+--(INDEX(NORMATIVOS!$C$100:$W$100,1,MATCH($B$3,NORMATIVOS!$C$1:$W$1,0))="Consolidado")+--(INDEX(NORMATIVOS!$C$101:$W$101,1,MATCH($B$3,NORMATIVOS!$C$1:$W$1,0))="Consolidado")+--(INDEX(NORMATIVOS!$C$102:$W$102,1,MATCH($B$3,NORMATIVOS!$C$1:$W$1,0))="Consolidado")+--(INDEX(NORMATIVOS!$C$103:$W$103,1,MATCH($B$3,NORMATIVOS!$C$1:$W$1,0))="Consolidado")+--(INDEX(NORMATIVOS!$C$104:$W$104,1,MATCH($B$3,NORMATIVOS!$C$1:$W$1,0))="Consolidado") -> 0 | F12: =--(INDEX(NORMATIVOS!$C$79:$W$79,1,MATCH($B$3,NORMATIVOS!$C$1:$W$1,0))="En proceso")+--(INDEX(NORMATIVOS!$C$80:$W$80,1,MATCH($B$3,NORMATIVOS!$C$1:$W$1,0))="En proceso")+--(INDEX(NORMATIVOS!$C$81:$W$81,1,MATCH($B$3,NORMATIVOS!$C$1:$W$1,0))="En proceso")+--(INDEX(NORMATIVOS!$C$82:$W$82,1,MATCH($B$3,NORMATIVOS!$C$1:$W$1,0))="En proceso")+--(INDEX(NORMATIVOS!$C$83:$W$83,1,MATCH($B$3,NORMATIVOS!$C$1:$W$1,0))="En proceso")+--(INDEX(NORMATIVOS!$C$84:$W$84,1,MATCH($B$3,NORMATIVOS!$C$1:$W$1,0))="En proceso")+--(INDEX(NORMATIVOS!$C$85:$W$85,1,MATCH($B$3,NORMATIVOS!$C$1:$W$1,0))="En proceso")+--(INDEX(NORMATIVOS!$C$86:$W$86,1,MATCH($B$3,NORMATIVOS!$C$1:$W$1,0))="En proceso")+--(INDEX(NORMATIVOS!$C$87:$W$87,1,MATCH($B$3,NORMATIVOS!$C$1:$W$1,0))="En proceso")+--(INDEX(NORMATIVOS!$C$88:$W$88,1,MATCH($B$3,NORMATIVOS!$C$1:$W$1,0))="En proceso")+--(INDEX(NORMATIVOS!$C$89:$W$89,1,MATCH($B$3,NORMATIVOS!$C$1:$W$1,0))="En proceso")+--(INDEX(NORMATIVOS!$C$90:$W$90,1,MATCH($B$3,NORMATIVOS!$C$1:$W$1,0))="En proceso")+--(INDEX(NORMATIVOS!$C$91:$W$91,1,MATCH($B$3,NORMATIVOS!$C$1:$W$1,0))="En proceso")+--(INDEX(NORMATIVOS!$C$92:$W$92,1,MATCH($B$3,NORMATIVOS!$C$1:$W$1,0))="En proceso")+--(INDEX(NORMATIVOS!$C$93:$W$93,1,MATCH($B$3,NORMATIVOS!$C$1:$W$1,0))="En proceso")+--(INDEX(NORMATIVOS!$C$94:$W$94,1,MATCH($B$3,NORMATIVOS!$C$1:$W$1,0))="En proceso")+--(INDEX(NORMATIVOS!$C$95:$W$95,1,MATCH($B$3,NORMATIVOS!$C$1:$W$1,0))="En proceso")+--(INDEX(NORMATIVOS!$C$96:$W$96,1,MATCH($B$3,NORMATIVOS!$C$1:$W$1,0))="En proceso")+--(INDEX(NORMATIVOS!$C$97:$W$97,1,MATCH($B$3,NORMATIVOS!$C$1:$W$1,0))="En proceso")+--(INDEX(NORMATIVOS!$C$98:$W$98,1,MATCH($B$3,NORMATIVOS!$C$1:$W$1,0))="En proceso")+--(INDEX(NORMATIVOS!$C$99:$W$99,1,MATCH($B$3,NORMATIVOS!$C$1:$W$1,0))="En proceso")+--(INDEX(NORMATIVOS!$C$100:$W$100,1,MATCH($B$3,NORMATIVOS!$C$1:$W$1,0))="En proceso")+--(INDEX(NORMATIVOS!$C$101:$W$101,1,MATCH($B$3,NORMATIVOS!$C$1:$W$1,0))="En proceso")+--(INDEX(NORMATIVOS!$C$102:$W$102,1,MATCH($B$3,NORMATIVOS!$C$1:$W$1,0))="En proceso")+--(INDEX(NORMATIVOS!$C$103:$W$103,1,MATCH($B$3,NORMATIVOS!$C$1:$W$1,0))="En proceso")+--(INDEX(NORMATIVOS!$C$104:$W$104,1,MATCH($B$3,NORMATIVOS!$C$1:$W$1,0))="En proceso") -> 0 | G12: =--(INDEX(NORMATIVOS!$C$79:$W$79,1,MATCH($B$3,NORMATIVOS!$C$1:$W$1,0))="Proyección")+--(INDEX(NORMATIVOS!$C$80:$W$80,1,MATCH($B$3,NORMATIVOS!$C$1:$W$1,0))="Proyección")+--(INDEX(NORMATIVOS!$C$81:$W$81,1,MATCH($B$3,NORMATIVOS!$C$1:$W$1,0))="Proyección")+--(INDEX(NORMATIVOS!$C$82:$W$82,1,MATCH($B$3,NORMATIVOS!$C$1:$W$1,0))="Proyección")+--(INDEX(NORMATIVOS!$C$83:$W$83,1,MATCH($B$3,NORMATIVOS!$C$1:$W$1,0))="Proyección")+--(INDEX(NORMATIVOS!$C$84:$W$84,1,MATCH($B$3,NORMATIVOS!$C$1:$W$1,0))="Proyección")+--(INDEX(NORMATIVOS!$C$85:$W$85,1,MATCH($B$3,NORMATIVOS!$C$1:$W$1,0))="Proyección")+--(INDEX(NORMATIVOS!$C$86:$W$86,1,MATCH($B$3,NORMATIVOS!$C$1:$W$1,0))="Proyección")+--(INDEX(NORMATIVOS!$C$87:$W$87,1,MATCH($B$3,NORMATIVOS!$C$1:$W$1,0))="Proyección")+--(INDEX(NORMATIVOS!$C$88:$W$88,1,MATCH($B$3,NORMATIVOS!$C$1:$W$1,0))="Proyección")+--(INDEX(NORMATIVOS!$C$89:$W$89,1,MATCH($B$3,NORMATIVOS!$C$1:$W$1,0))="Proyección")+--(INDEX(NORMATIVOS!$C$90:$W$90,1,MATCH($B$3,NORMATIVOS!$C$1:$W$1,0))="Proyección")+--(INDEX(NORMATIVOS!$C$91:$W$91,1,MATCH($B$3,NORMATIVOS!$C$1:$W$1,0))="Proyección")+--(INDEX(NORMATIVOS!$C$92:$W$92,1,MATCH($B$3,NORMATIVOS!$C$1:$W$1,0))="Proyección")+--(INDEX(NORMATIVOS!$C$93:$W$93,1,MATCH($B$3,NORMATIVOS!$C$1:$W$1,0))="Proyección")+--(INDEX(NORMATIVOS!$C$94:$W$94,1,MATCH($B$3,NORMATIVOS!$C$1:$W$1,0))="Proyección")+--(INDEX(NORMATIVOS!$C$95:$W$95,1,MATCH($B$3,NORMATIVOS!$C$1:$W$1,0))="Proyección")+--(INDEX(NORMATIVOS!$C$96:$W$96,1,MATCH($B$3,NORMATIVOS!$C$1:$W$1,0))="Proyección")+--(INDEX(NORMATIVOS!$C$97:$W$97,1,MATCH($B$3,NORMATIVOS!$C$1:$W$1,0))="Proyección")+--(INDEX(NORMATIVOS!$C$98:$W$98,1,MATCH($B$3,NORMATIVOS!$C$1:$W$1,0))="Proyección")+--(INDEX(NORMATIVOS!$C$99:$W$99,1,MATCH($B$3,NORMATIVOS!$C$1:$W$1,0))="Proyección")+--(INDEX(NORMATIVOS!$C$100:$W$100,1,MATCH($B$3,NORMATIVOS!$C$1:$W$1,0))="Proyección")+--(INDEX(NORMATIVOS!$C$101:$W$101,1,MATCH($B$3,NORMATIVOS!$C$1:$W$1,0))="Proyección")+--(INDEX(NORMATIVOS!$C$102:$W$102,1,MATCH($B$3,NORMATIVOS!$C$1:$W$1,0))="Proyección")+--(INDEX(NORMATIVOS!$C$103:$W$103,1,MATCH($B$3,NORMATIVOS!$C$1:$W$1,0))="Proyección")+--(INDEX(NORMATIVOS!$C$104:$W$104,1,MATCH($B$3,NORMATIVOS!$C$1:$W$1,0))="Proyección") -> 26 | H12: =IFERROR(E12/(E12+F12+G12),0) -> 0
D13: ELEMENTOS DE FUERZA | E13: =--(INDEX(NORMATIVOS!$C$107:$N$107,1,MATCH($B$3,NORMATIVOS!$C$1:$W$1,0))="Consolidado")+--(INDEX(NORMATIVOS!$C$108:$W$108,1,MATCH($B$3,NORMATIVOS!$C$1:$W$1,0))="Consolidado")+--(INDEX(NORMATIVOS!$C$109:$W$109,1,MATCH($B$3,NORMATIVOS!$C$1:$W$1,0))="Consolidado")+--(INDEX(NORMATIVOS!$C$110:$W$110,1,MATCH($B$3,NORMATIVOS!$C$1:$W$1,0))="Consolidado")+--(INDEX(NORMATIVOS!$C$111:$W$111,1,MATCH($B$3,NORMATIVOS!$C$1:$W$1,0))="Consolidado")+--(INDEX(NORMATIVOS!$C$112:$W$112,1,MATCH($B$3,NORMATIVOS!$C$1:$W$1,0))="Consolidado")+--(INDEX(NORMATIVOS!$C$113:$W$113,1,MATCH($B$3,NORMATIVOS!$C$1:$W$1,0))="Consolidado")+--(INDEX(NORMATIVOS!$C$114:$W$114,1,MATCH($B$3,NORMATIVOS!$C$1:$W$1,0))="Consolidado")+--(INDEX(NORMATIVOS!$C$115:$W$115,1,MATCH($B$3,NORMATIVOS!$C$1:$W$1,0))="Consolidado")+--(INDEX(NORMATIVOS!$C$116:$W$116,1,MATCH($B$3,NORMATIVOS!$C$1:$W$1,0))="Consolidado")+--(INDEX(NORMATIVOS!$C$117:$W$117,1,MATCH($B$3,NORMATIVOS!$C$1:$W$1,0))="Consolidado")+--(INDEX(NORMATIVOS!$C$118:$W$118,1,MATCH($B$3,NORMATIVOS!$C$1:$W$1,0))="Consolidado")+--(INDEX(NORMATIVOS!$C$119:$W$119,1,MATCH($B$3,NORMATIVOS!$C$1:$W$1,0))="Consolidado")+--(INDEX(NORMATIVOS!$C$120:$W$120,1,MATCH($B$3,NORMATIVOS!$C$1:$W$1,0))="Consolidado")+--(INDEX(NORMATIVOS!$C$121:$W$121,1,MATCH($B$3,NORMATIVOS!$C$1:$W$1,0))="Consolidado") -> 0 | F13: =--(INDEX(NORMATIVOS!$C$107:$N$107,1,MATCH($B$3,NORMATIVOS!$C$1:$W$1,0))="En proceso")+--(INDEX(NORMATIVOS!$C$108:$W$108,1,MATCH($B$3,NORMATIVOS!$C$1:$W$1,0))="En proceso")+--(INDEX(NORMATIVOS!$C$109:$W$109,1,MATCH($B$3,NORMATIVOS!$C$1:$W$1,0))="En proceso")+--(INDEX(NORMATIVOS!$C$110:$W$110,1,MATCH($B$3,NORMATIVOS!$C$1:$W$1,0))="En proceso")+--(INDEX(NORMATIVOS!$C$111:$W$111,1,MATCH($B$3,NORMATIVOS!$C$1:$W$1,0))="En proceso")+--(INDEX(NORMATIVOS!$C$112:$W$112,1,MATCH($B$3,NORMATIVOS!$C$1:$W$1,0))="En proceso")+--(INDEX(NORMATIVOS!$C$113:$W$113,1,MATCH($B$3,NORMATIVOS!$C$1:$W$1,0))="En proceso")+--(INDEX(NORMATIVOS!$C$114:$W$114,1,MATCH($B$3,NORMATIVOS!$C$1:$W$1,0))="En proceso")+--(INDEX(NORMATIVOS!$C$115:$W$115,1,MATCH($B$3,NORMATIVOS!$C$1:$W$1,0))="En proceso")+--(INDEX(NORMATIVOS!$C$116:$W$116,1,MATCH($B$3,NORMATIVOS!$C$1:$W$1,0))="En proceso")+--(INDEX(NORMATIVOS!$C$117:$W$117,1,MATCH($B$3,NORMATIVOS!$C$1:$W$1,0))="En proceso")+--(INDEX(NORMATIVOS!$C$118:$W$118,1,MATCH($B$3,NORMATIVOS!$C$1:$W$1,0))="En proceso")+--(INDEX(NORMATIVOS!$C$119:$W$119,1,MATCH($B$3,NORMATIVOS!$C$1:$W$1,0))="En proceso")+--(INDEX(NORMATIVOS!$C$120:$W$120,1,MATCH($B$3,NORMATIVOS!$C$1:$W$1,0))="En proceso")+--(INDEX(NORMATIVOS!$C$121:$W$121,1,MATCH($B$3,NORMATIVOS!$C$1:$W$1,0))="En proceso") -> 0 | G13: =--(INDEX(NORMATIVOS!$C$107:$N$107,1,MATCH($B$3,NORMATIVOS!$C$1:$W$1,0))="Proyección")+--(INDEX(NORMATIVOS!$C$108:$W$108,1,MATCH($B$3,NORMATIVOS!$C$1:$W$1,0))="Proyección")+--(INDEX(NORMATIVOS!$C$109:$W$109,1,MATCH($B$3,NORMATIVOS!$C$1:$W$1,0))="Proyección")+--(INDEX(NORMATIVOS!$C$110:$W$110,1,MATCH($B$3,NORMATIVOS!$C$1:$W$1,0))="Proyección")+--(INDEX(NORMATIVOS!$C$111:$W$111,1,MATCH($B$3,NORMATIVOS!$C$1:$W$1,0))="Proyección")+--(INDEX(NORMATIVOS!$C$112:$W$112,1,MATCH($B$3,NORMATIVOS!$C$1:$W$1,0))="Proyección")+--(INDEX(NORMATIVOS!$C$113:$W$113,1,MATCH($B$3,NORMATIVOS!$C$1:$W$1,0))="Proyección")+--(INDEX(NORMATIVOS!$C$114:$W$114,1,MATCH($B$3,NORMATIVOS!$C$1:$W$1,0))="Proyección")+--(INDEX(NORMATIVOS!$C$115:$W$115,1,MATCH($B$3,NORMATIVOS!$C$1:$W$1,0))="Proyección")+--(INDEX(NORMATIVOS!$C$116:$W$116,1,MATCH($B$3,NORMATIVOS!$C$1:$W$1,0))="Proyección")+--(INDEX(NORMATIVOS!$C$117:$W$117,1,MATCH($B$3,NORMATIVOS!$C$1:$W$1,0))="Proyección")+--(INDEX(NORMATIVOS!$C$118:$W$118,1,MATCH($B$3,NORMATIVOS!$C$1:$W$1,0))="Proyección")+--(INDEX(NORMATIVOS!$C$119:$W$119,1,MATCH($B$3,NORMATIVOS!$C$1:$W$1,0))="Proyección")+--(INDEX(NORMATIVOS!$C$120:$W$120,1,MATCH($B$3,NORMATIVOS!$C$1:$W$1,0))="Proyección")+--(INDEX(NORMATIVOS!$C$121:$W$121,1,MATCH($B$3,NORMATIVOS!$C$1:$W$1,0))="Proyección") -> 15 | H13: =IFERROR(E13/(E13+F13+G13),0) -> 0
D14: ELEMENTOS DE VUELO | E14: =--(INDEX(NORMATIVOS!$C$122:$W$122,1,MATCH($B$3,NORMATIVOS!$C$1:$W$1,0))="Consolidado")+--(INDEX(NORMATIVOS!$C$123:$W$123,1,MATCH($B$3,NORMATIVOS!$C$1:$W$1,0))="Consolidado")+--(INDEX(NORMATIVOS!$C$124:$W$124,1,MATCH($B$3,NORMATIVOS!$C$1:$W$1,0))="Consolidado")+--(INDEX(NORMATIVOS!$C$125:$W$125,1,MATCH($B$3,NORMATIVOS!$C$1:$W$1,0))="Consolidado")+--(INDEX(NORMATIVOS!$C$126:$W$126,1,MATCH($B$3,NORMATIVOS!$C$1:$W$1,0))="Consolidado")+--(INDEX(NORMATIVOS!$C$127:$W$127,1,MATCH($B$3,NORMATIVOS!$C$1:$W$1,0))="Consolidado")+--(INDEX(NORMATIVOS!$C$128:$W$128,1,MATCH($B$3,NORMATIVOS!$C$1:$W$1,0))="Consolidado")+--(INDEX(NORMATIVOS!$C$129:$W$129,1,MATCH($B$3,NORMATIVOS!$C$1:$W$1,0))="Consolidado")+--(INDEX(NORMATIVOS!$C$130:$W$130,1,MATCH($B$3,NORMATIVOS!$C$1:$W$1,0))="Consolidado")+--(INDEX(NORMATIVOS!$C$131:$W$131,1,MATCH($B$3,NORMATIVOS!$C$1:$W$1,0))="Consolidado")+--(INDEX(NORMATIVOS!$C$132:$W$132,1,MATCH($B$3,NORMATIVOS!$C$1:$W$1,0))="Consolidado")+--(INDEX(NORMATIVOS!$C$133:$W$133,1,MATCH($B$3,NORMATIVOS!$C$1:$W$1,0))="Consolidado")+--(INDEX(NORMATIVOS!$C$134:$W$134,1,MATCH($B$3,NORMATIVOS!$C$1:$W$1,0))="Consolidado")+--(INDEX(NORMATIVOS!$C$135:$W$135,1,MATCH($B$3,NORMATIVOS!$C$1:$W$1,0))="Consolidado")+--(INDEX(NORMATIVOS!$C$136:$W$136,1,MATCH($B$3,NORMATIVOS!$C$1:$W$1,0))="Consolidado")+--(INDEX(NORMATIVOS!$C$137:$W$137,1,MATCH($B$3,NORMATIVOS!$C$1:$W$1,0))="Consolidado")+--(INDEX(NORMATIVOS!$C$138:$W$138,1,MATCH($B$3,NORMATIVOS!$C$1:$W$1,0))="Consolidado")+--(INDEX(NORMATIVOS!$C$139:$W$139,1,MATCH($B$3,NORMATIVOS!$C$1:$W$1,0))="Consolidado")+--(INDEX(NORMATIVOS!$C$140:$W$140,1,MATCH($B$3,NORMATIVOS!$C$1:$W$1,0))="Consolidado")+--(INDEX(NORMATIVOS!$C$141:$W$141,1,MATCH($B$3,NORMATIVOS!$C$1:$W$1,0))="Consolidado") -> 0 | F14: =--(INDEX(NORMATIVOS!$C$122:$W$122,1,MATCH($B$3,NORMATIVOS!$C$1:$W$1,0))="En proceso")+--(INDEX(NORMATIVOS!$C$123:$W$123,1,MATCH($B$3,NORMATIVOS!$C$1:$W$1,0))="En proceso")+--(INDEX(NORMATIVOS!$C$124:$W$124,1,MATCH($B$3,NORMATIVOS!$C$1:$W$1,0))="En proceso")+--(INDEX(NORMATIVOS!$C$125:$W$125,1,MATCH($B$3,NORMATIVOS!$C$1:$W$1,0))="En proceso")+--(INDEX(NORMATIVOS!$C$126:$W$126,1,MATCH($B$3,NORMATIVOS!$C$1:$W$1,0))="En proceso")+--(INDEX(NORMATIVOS!$C$127:$W$127,1,MATCH($B$3,NORMATIVOS!$C$1:$W$1,0))="En proceso")+--(INDEX(NORMATIVOS!$C$128:$W$128,1,MATCH($B$3,NORMATIVOS!$C$1:$W$1,0))="En proceso")+--(INDEX(NORMATIVOS!$C$129:$W$129,1,MATCH($B$3,NORMATIVOS!$C$1:$W$1,0))="En proceso")+--(INDEX(NORMATIVOS!$C$130:$W$130,1,MATCH($B$3,NORMATIVOS!$C$1:$W$1,0))="En proceso")+--(INDEX(NORMATIVOS!$C$131:$W$131,1,MATCH($B$3,NORMATIVOS!$C$1:$W$1,0))="En proceso")+--(INDEX(NORMATIVOS!$C$132:$W$132,1,MATCH($B$3,NORMATIVOS!$C$1:$W$1,0))="En proceso")+--(INDEX(NORMATIVOS!$C$133:$W$133,1,MATCH($B$3,NORMATIVOS!$C$1:$W$1,0))="En proceso")+--(INDEX(NORMATIVOS!$C$134:$W$134,1,MATCH($B$3,NORMATIVOS!$C$1:$W$1,0))="En proceso")+--(INDEX(NORMATIVOS!$C$135:$W$135,1,MATCH($B$3,NORMATIVOS!$C$1:$W$1,0))="En proceso")+--(INDEX(NORMATIVOS!$C$136:$W$136,1,MATCH($B$3,NORMATIVOS!$C$1:$W$1,0))="En proceso")+--(INDEX(NORMATIVOS!$C$137:$W$137,1,MATCH($B$3,NORMATIVOS!$C$1:$W$1,0))="En proceso")+--(INDEX(NORMATIVOS!$C$138:$W$138,1,MATCH($B$3,NORMATIVOS!$C$1:$W$1,0))="En proceso")+--(INDEX(NORMATIVOS!$C$139:$W$139,1,MATCH($B$3,NORMATIVOS!$C$1:$W$1,0))="En proceso")+--(INDEX(NORMATIVOS!$C$140:$W$140,1,MATCH($B$3,NORMATIVOS!$C$1:$W$1,0))="En proceso")+--(INDEX(NORMATIVOS!$C$141:$W$141,1,MATCH($B$3,NORMATIVOS!$C$1:$W$1,0))="En proceso") -> 0 | G14: =--(INDEX(NORMATIVOS!$C$122:$W$122,1,MATCH($B$3,NORMATIVOS!$C$1:$W$1,0))="Proyección")+--(INDEX(NORMATIVOS!$C$123:$W$123,1,MATCH($B$3,NORMATIVOS!$C$1:$W$1,0))="Proyección")+--(INDEX(NORMATIVOS!$C$124:$W$124,1,MATCH($B$3,NORMATIVOS!$C$1:$W$1,0))="Proyección")+--(INDEX(NORMATIVOS!$C$125:$W$125,1,MATCH($B$3,NORMATIVOS!$C$1:$W$1,0))="Proyección")+--(INDEX(NORMATIVOS!$C$126:$W$126,1,MATCH($B$3,NORMATIVOS!$C$1:$W$1,0))="Proyección")+--(INDEX(NORMATIVOS!$C$127:$W$127,1,MATCH($B$3,NORMATIVOS!$C$1:$W$1,0))="Proyección")+--(INDEX(NORMATIVOS!$C$128:$W$128,1,MATCH($B$3,NORMATIVOS!$C$1:$W$1,0))="Proyección")+--(INDEX(NORMATIVOS!$C$129:$W$129,1,MATCH($B$3,NORMATIVOS!$C$1:$W$1,0))="Proyección")+--(INDEX(NORMATIVOS!$C$130:$W$130,1,MATCH($B$3,NORMATIVOS!$C$1:$W$1,0))="Proyección")+--(INDEX(NORMATIVOS!$C$131:$W$131,1,MATCH($B$3,NORMATIVOS!$C$1:$W$1,0))="Proyección")+--(INDEX(NORMATIVOS!$C$132:$W$132,1,MATCH($B$3,NORMATIVOS!$C$1:$W$1,0))="Proyección")+--(INDEX(NORMATIVOS!$C$133:$W$133,1,MATCH($B$3,NORMATIVOS!$C$1:$W$1,0))="Proyección")+--(INDEX(NORMATIVOS!$C$134:$W$134,1,MATCH($B$3,NORMATIVOS!$C$1:$W$1,0))="Proyección")+--(INDEX(NORMATIVOS!$C$135:$W$135,1,MATCH($B$3,NORMATIVOS!$C$1:$W$1,0))="Proyección")+--(INDEX(NORMATIVOS!$C$136:$W$136,1,MATCH($B$3,NORMATIVOS!$C$1:$W$1,0))="Proyección")+--(INDEX(NORMATIVOS!$C$137:$W$137,1,MATCH($B$3,NORMATIVOS!$C$1:$W$1,0))="Proyección")+--(INDEX(NORMATIVOS!$C$138:$W$138,1,MATCH($B$3,NORMATIVOS!$C$1:$W$1,0))="Proyección")+--(INDEX(NORMATIVOS!$C$139:$W$139,1,MATCH($B$3,NORMATIVOS!$C$1:$W$1,0))="Proyección")+--(INDEX(NORMATIVOS!$C$140:$W$140,1,MATCH($B$3,NORMATIVOS!$C$1:$W$1,0))="Proyección")+--(INDEX(NORMATIVOS!$C$141:$W$141,1,MATCH($B$3,NORMATIVOS!$C$1:$W$1,0))="Proyección") -> 20 | H14: =IFERROR(E14/(E14+F14+G14),0) -> 0
D15: ACCIONES SIN TABLA DE SALTO | E15: =--(INDEX(NORMATIVOS!$C$144:$W$144,1,MATCH($B$3,NORMATIVOS!$C$1:$W$1,0))="Consolidado")+--(INDEX(NORMATIVOS!$C$145:$W$145,1,MATCH($B$3,NORMATIVOS!$C$1:$W$1,0))="Consolidado")+--(INDEX(NORMATIVOS!$C$146:$W$146,1,MATCH($B$3,NORMATIVOS!$C$1:$W$1,0))="Consolidado")+--(INDEX(NORMATIVOS!$C$147:$W$147,1,MATCH($B$3,NORMATIVOS!$C$1:$W$1,0))="Consolidado")+--(INDEX(NORMATIVOS!$C$148:$W$148,1,MATCH($B$3,NORMATIVOS!$C$1:$W$1,0))="Consolidado")+--(INDEX(NORMATIVOS!$C$149:$W$149,1,MATCH($B$3,NORMATIVOS!$C$1:$W$1,0))="Consolidado")+--(INDEX(NORMATIVOS!$C$150:$W$150,1,MATCH($B$3,NORMATIVOS!$C$1:$W$1,0))="Consolidado") -> 0 | F15: =--(INDEX(NORMATIVOS!$C$144:$W$144,1,MATCH($B$3,NORMATIVOS!$C$1:$W$1,0))="En proceso")+--(INDEX(NORMATIVOS!$C$145:$W$145,1,MATCH($B$3,NORMATIVOS!$C$1:$W$1,0))="En proceso")+--(INDEX(NORMATIVOS!$C$146:$W$146,1,MATCH($B$3,NORMATIVOS!$C$1:$W$1,0))="En proceso")+--(INDEX(NORMATIVOS!$C$147:$W$147,1,MATCH($B$3,NORMATIVOS!$C$1:$W$1,0))="En proceso")+--(INDEX(NORMATIVOS!$C$148:$W$148,1,MATCH($B$3,NORMATIVOS!$C$1:$W$1,0))="En proceso")+--(INDEX(NORMATIVOS!$C$149:$W$149,1,MATCH($B$3,NORMATIVOS!$C$1:$W$1,0))="En proceso")+--(INDEX(NORMATIVOS!$C$150:$W$150,1,MATCH($B$3,NORMATIVOS!$C$1:$W$1,0))="En proceso") -> 0 | G15: =--(INDEX(NORMATIVOS!$C$144:$W$144,1,MATCH($B$3,NORMATIVOS!$C$1:$W$1,0))="Proyección")+--(INDEX(NORMATIVOS!$C$145:$W$145,1,MATCH($B$3,NORMATIVOS!$C$1:$W$1,0))="Proyección")+--(INDEX(NORMATIVOS!$C$146:$W$146,1,MATCH($B$3,NORMATIVOS!$C$1:$W$1,0))="Proyección")+--(INDEX(NORMATIVOS!$C$147:$W$147,1,MATCH($B$3,NORMATIVOS!$C$1:$W$1,0))="Proyección")+--(INDEX(NORMATIVOS!$C$148:$W$148,1,MATCH($B$3,NORMATIVOS!$C$1:$W$1,0))="Proyección")+--(INDEX(NORMATIVOS!$C$149:$W$149,1,MATCH($B$3,NORMATIVOS!$C$1:$W$1,0))="Proyección")+--(INDEX(NORMATIVOS!$C$150:$W$150,1,MATCH($B$3,NORMATIVOS!$C$1:$W$1,0))="Proyección") -> 7 | H15: =IFERROR(E15/(E15+F15+G15),0) -> 0
D16: SALTOS | E16: =--(INDEX(NORMATIVOS!$C$151:$W$151,1,MATCH($B$3,NORMATIVOS!$C$1:$W$1,0))="Consolidado")+--(INDEX(NORMATIVOS!$C$152:$W$152,1,MATCH($B$3,NORMATIVOS!$C$1:$W$1,0))="Consolidado")+--(INDEX(NORMATIVOS!$C$153:$W$153,1,MATCH($B$3,NORMATIVOS!$C$1:$W$1,0))="Consolidado")+--(INDEX(NORMATIVOS!$C$154:$W$154,1,MATCH($B$3,NORMATIVOS!$C$1:$W$1,0))="Consolidado")+--(INDEX(NORMATIVOS!$C$155:$W$155,1,MATCH($B$3,NORMATIVOS!$C$1:$W$1,0))="Consolidado")+--(INDEX(NORMATIVOS!$C$156:$W$156,1,MATCH($B$3,NORMATIVOS!$C$1:$W$1,0))="Consolidado")+--(INDEX(NORMATIVOS!$C$157:$W$157,1,MATCH($B$3,NORMATIVOS!$C$1:$W$1,0))="Consolidado")+--(INDEX(NORMATIVOS!$C$158:$W$158,1,MATCH($B$3,NORMATIVOS!$C$1:$W$1,0))="Consolidado")+--(INDEX(NORMATIVOS!$C$159:$W$159,1,MATCH($B$3,NORMATIVOS!$C$1:$W$1,0))="Consolidado")+--(INDEX(NORMATIVOS!$C$160:$W$160,1,MATCH($B$3,NORMATIVOS!$C$1:$W$1,0))="Consolidado")+--(INDEX(NORMATIVOS!$C$161:$W$161,1,MATCH($B$3,NORMATIVOS!$C$1:$W$1,0))="Consolidado")+--(INDEX(NORMATIVOS!$C$162:$W$162,1,MATCH($B$3,NORMATIVOS!$C$1:$W$1,0))="Consolidado")+--(INDEX(NORMATIVOS!$C$163:$W$163,1,MATCH($B$3,NORMATIVOS!$C$1:$W$1,0))="Consolidado")+--(INDEX(NORMATIVOS!$C$164:$W$164,1,MATCH($B$3,NORMATIVOS!$C$1:$W$1,0))="Consolidado")+--(INDEX(NORMATIVOS!$C$165:$W$165,1,MATCH($B$3,NORMATIVOS!$C$1:$W$1,0))="Consolidado")+--(INDEX(NORMATIVOS!$C$166:$W$166,1,MATCH($B$3,NORMATIVOS!$C$1:$W$1,0))="Consolidado")+--(INDEX(NORMATIVOS!$C$167:$W$167,1,MATCH($B$3,NORMATIVOS!$C$1:$W$1,0))="Consolidado")+--(INDEX(NORMATIVOS!$C$168:$W$168,1,MATCH($B$3,NORMATIVOS!$C$1:$W$1,0))="Consolidado")+--(INDEX(NORMATIVOS!$C$169:$W$169,1,MATCH($B$3,NORMATIVOS!$C$1:$W$1,0))="Consolidado")+--(INDEX(NORMATIVOS!$C$170:$W$170,1,MATCH($B$3,NORMATIVOS!$C$1:$W$1,0))="Consolidado")+--(INDEX(NORMATIVOS!$C$171:$W$171,1,MATCH($B$3,NORMATIVOS!$C$1:$W$1,0))="Consolidado")+--(INDEX(NORMATIVOS!$C$172:$W$172,1,MATCH($B$3,NORMATIVOS!$C$1:$W$1,0))="Consolidado") -> 0 | F16: =--(INDEX(NORMATIVOS!$C$151:$W$151,1,MATCH($B$3,NORMATIVOS!$C$1:$W$1,0))="En proceso")+--(INDEX(NORMATIVOS!$C$152:$W$152,1,MATCH($B$3,NORMATIVOS!$C$1:$W$1,0))="En proceso")+--(INDEX(NORMATIVOS!$C$153:$W$153,1,MATCH($B$3,NORMATIVOS!$C$1:$W$1,0))="En proceso")+--(INDEX(NORMATIVOS!$C$154:$W$154,1,MATCH($B$3,NORMATIVOS!$C$1:$W$1,0))="En proceso")+--(INDEX(NORMATIVOS!$C$155:$W$155,1,MATCH($B$3,NORMATIVOS!$C$1:$W$1,0))="En proceso")+--(INDEX(NORMATIVOS!$C$156:$W$156,1,MATCH($B$3,NORMATIVOS!$C$1:$W$1,0))="En proceso")+--(INDEX(NORMATIVOS!$C$157:$W$157,1,MATCH($B$3,NORMATIVOS!$C$1:$W$1,0))="En proceso")+--(INDEX(NORMATIVOS!$C$158:$W$158,1,MATCH($B$3,NORMATIVOS!$C$1:$W$1,0))="En proceso")+--(INDEX(NORMATIVOS!$C$159:$W$159,1,MATCH($B$3,NORMATIVOS!$C$1:$W$1,0))="En proceso")+--(INDEX(NORMATIVOS!$C$160:$W$160,1,MATCH($B$3,NORMATIVOS!$C$1:$W$1,0))="En proceso")+--(INDEX(NORMATIVOS!$C$161:$W$161,1,MATCH($B$3,NORMATIVOS!$C$1:$W$1,0))="En proceso")+--(INDEX(NORMATIVOS!$C$162:$W$162,1,MATCH($B$3,NORMATIVOS!$C$1:$W$1,0))="En proceso")+--(INDEX(NORMATIVOS!$C$163:$W$163,1,MATCH($B$3,NORMATIVOS!$C$1:$W$1,0))="En proceso")+--(INDEX(NORMATIVOS!$C$164:$W$164,1,MATCH($B$3,NORMATIVOS!$C$1:$W$1,0))="En proceso")+--(INDEX(NORMATIVOS!$C$165:$W$165,1,MATCH($B$3,NORMATIVOS!$C$1:$W$1,0))="En proceso")+--(INDEX(NORMATIVOS!$C$166:$W$166,1,MATCH($B$3,NORMATIVOS!$C$1:$W$1,0))="En proceso")+--(INDEX(NORMATIVOS!$C$167:$W$167,1,MATCH($B$3,NORMATIVOS!$C$1:$W$1,0))="En proceso")+--(INDEX(NORMATIVOS!$C$168:$W$168,1,MATCH($B$3,NORMATIVOS!$C$1:$W$1,0))="En proceso")+--(INDEX(NORMATIVOS!$C$169:$W$169,1,MATCH($B$3,NORMATIVOS!$C$1:$W$1,0))="En proceso")+--(INDEX(NORMATIVOS!$C$170:$W$170,1,MATCH($B$3,NORMATIVOS!$C$1:$W$1,0))="En proceso")+--(INDEX(NORMATIVOS!$C$171:$W$171,1,MATCH($B$3,NORMATIVOS!$C$1:$W$1,0))="En proceso")+--(INDEX(NORMATIVOS!$C$172:$W$172,1,MATCH($B$3,NORMATIVOS!$C$1:$W$1,0))="En proceso") -> 0 | G16: =--(INDEX(NORMATIVOS!$C$151:$W$151,1,MATCH($B$3,NORMATIVOS!$C$1:$W$1,0))="Proyección")+--(INDEX(NORMATIVOS!$C$152:$W$152,1,MATCH($B$3,NORMATIVOS!$C$1:$W$1,0))="Proyección")+--(INDEX(NORMATIVOS!$C$153:$W$153,1,MATCH($B$3,NORMATIVOS!$C$1:$W$1,0))="Proyección")+--(INDEX(NORMATIVOS!$C$154:$W$154,1,MATCH($B$3,NORMATIVOS!$C$1:$W$1,0))="Proyección")+--(INDEX(NORMATIVOS!$C$155:$W$155,1,MATCH($B$3,NORMATIVOS!$C$1:$W$1,0))="Proyección")+--(INDEX(NORMATIVOS!$C$156:$W$156,1,MATCH($B$3,NORMATIVOS!$C$1:$W$1,0))="Proyección")+--(INDEX(NORMATIVOS!$C$157:$W$157,1,MATCH($B$3,NORMATIVOS!$C$1:$W$1,0))="Proyección")+--(INDEX(NORMATIVOS!$C$158:$W$158,1,MATCH($B$3,NORMATIVOS!$C$1:$W$1,0))="Proyección")+--(INDEX(NORMATIVOS!$C$159:$W$159,1,MATCH($B$3,NORMATIVOS!$C$1:$W$1,0))="Proyección")+--(INDEX(NORMATIVOS!$C$160:$W$160,1,MATCH($B$3,NORMATIVOS!$C$1:$W$1,0))="Proyección")+--(INDEX(NORMATIVOS!$C$161:$W$161,1,MATCH($B$3,NORMATIVOS!$C$1:$W$1,0))="Proyección")+--(INDEX(NORMATIVOS!$C$162:$W$162,1,MATCH($B$3,NORMATIVOS!$C$1:$W$1,0))="Proyección")+--(INDEX(NORMATIVOS!$C$163:$W$163,1,MATCH($B$3,NORMATIVOS!$C$1:$W$1,0))="Proyección")+--(INDEX(NORMATIVOS!$C$164:$W$164,1,MATCH($B$3,NORMATIVOS!$C$1:$W$1,0))="Proyección")+--(INDEX(NORMATIVOS!$C$165:$W$165,1,MATCH($B$3,NORMATIVOS!$C$1:$W$1,0))="Proyección")+--(INDEX(NORMATIVOS!$C$166:$W$166,1,MATCH($B$3,NORMATIVOS!$C$1:$W$1,0))="Proyección")+--(INDEX(NORMATIVOS!$C$167:$W$167,1,MATCH($B$3,NORMATIVOS!$C$1:$W$1,0))="Proyección")+--(INDEX(NORMATIVOS!$C$168:$W$168,1,MATCH($B$3,NORMATIVOS!$C$1:$W$1,0))="Proyección")+--(INDEX(NORMATIVOS!$C$169:$W$169,1,MATCH($B$3,NORMATIVOS!$C$1:$W$1,0))="Proyección")+--(INDEX(NORMATIVOS!$C$170:$W$170,1,MATCH($B$3,NORMATIVOS!$C$1:$W$1,0))="Proyección")+--(INDEX(NORMATIVOS!$C$171:$W$171,1,MATCH($B$3,NORMATIVOS!$C$1:$W$1,0))="Proyección")+--(INDEX(NORMATIVOS!$C$172:$W$172,1,MATCH($B$3,NORMATIVOS!$C$1:$W$1,0))="Proyección") -> 22 | H16: =IFERROR(E16/(E16+F16+G16),0) -> 0
D17: ELEMENTOS EN SUSPENSION | E17: =--(INDEX(NORMATIVOS!$C$175:$W$175,1,MATCH($B$3,NORMATIVOS!$C$1:$W$1,0))="Consolidado")+--(INDEX(NORMATIVOS!$C$176:$W$176,1,MATCH($B$3,NORMATIVOS!$C$1:$W$1,0))="Consolidado")+--(INDEX(NORMATIVOS!$C$177:$W$177,1,MATCH($B$3,NORMATIVOS!$C$1:$W$1,0))="Consolidado")+--(INDEX(NORMATIVOS!$C$178:$W$178,1,MATCH($B$3,NORMATIVOS!$C$1:$W$1,0))="Consolidado")+--(INDEX(NORMATIVOS!$C$179:$W$179,1,MATCH($B$3,NORMATIVOS!$C$1:$W$1,0))="Consolidado")+--(INDEX(NORMATIVOS!$C$180:$W$180,1,MATCH($B$3,NORMATIVOS!$C$1:$W$1,0))="Consolidado")+--(INDEX(NORMATIVOS!$C$181:$W$181,1,MATCH($B$3,NORMATIVOS!$C$1:$W$1,0))="Consolidado")+--(INDEX(NORMATIVOS!$C$182:$W$182,1,MATCH($B$3,NORMATIVOS!$C$1:$W$1,0))="Consolidado")+--(INDEX(NORMATIVOS!$C$183:$W$183,1,MATCH($B$3,NORMATIVOS!$C$1:$W$1,0))="Consolidado")+--(INDEX(NORMATIVOS!$C$184:$W$184,1,MATCH($B$3,NORMATIVOS!$C$1:$W$1,0))="Consolidado")+--(INDEX(NORMATIVOS!$C$185:$W$185,1,MATCH($B$3,NORMATIVOS!$C$1:$W$1,0))="Consolidado")+--(INDEX(NORMATIVOS!$C$186:$W$186,1,MATCH($B$3,NORMATIVOS!$C$1:$W$1,0))="Consolidado")+--(INDEX(NORMATIVOS!$C$187:$W$187,1,MATCH($B$3,NORMATIVOS!$C$1:$W$1,0))="Consolidado")+--(INDEX(NORMATIVOS!$C$188:$W$188,1,MATCH($B$3,NORMATIVOS!$C$1:$W$1,0))="Consolidado")+--(INDEX(NORMATIVOS!$C$189:$W$189,1,MATCH($B$3,NORMATIVOS!$C$1:$W$1,0))="Consolidado")+--(INDEX(NORMATIVOS!$C$190:$W$190,1,MATCH($B$3,NORMATIVOS!$C$1:$W$1,0))="Consolidado")+--(INDEX(NORMATIVOS!$C$191:$W$191,1,MATCH($B$3,NORMATIVOS!$C$1:$W$1,0))="Consolidado")+--(INDEX(NORMATIVOS!$C$192:$W$192,1,MATCH($B$3,NORMATIVOS!$C$1:$W$1,0))="Consolidado") -> 0 | F17: =--(INDEX(NORMATIVOS!$C$175:$W$175,1,MATCH($B$3,NORMATIVOS!$C$1:$W$1,0))="En proceso")+--(INDEX(NORMATIVOS!$C$176:$W$176,1,MATCH($B$3,NORMATIVOS!$C$1:$W$1,0))="En proceso")+--(INDEX(NORMATIVOS!$C$177:$W$177,1,MATCH($B$3,NORMATIVOS!$C$1:$W$1,0))="En proceso")+--(INDEX(NORMATIVOS!$C$178:$W$178,1,MATCH($B$3,NORMATIVOS!$C$1:$W$1,0))="En proceso")+--(INDEX(NORMATIVOS!$C$179:$W$179,1,MATCH($B$3,NORMATIVOS!$C$1:$W$1,0))="En proceso")+--(INDEX(NORMATIVOS!$C$180:$W$180,1,MATCH($B$3,NORMATIVOS!$C$1:$W$1,0))="En proceso")+--(INDEX(NORMATIVOS!$C$181:$W$181,1,MATCH($B$3,NORMATIVOS!$C$1:$W$1,0))="En proceso")+--(INDEX(NORMATIVOS!$C$182:$W$182,1,MATCH($B$3,NORMATIVOS!$C$1:$W$1,0))="En proceso")+--(INDEX(NORMATIVOS!$C$183:$W$183,1,MATCH($B$3,NORMATIVOS!$C$1:$W$1,0))="En proceso")+--(INDEX(NORMATIVOS!$C$184:$W$184,1,MATCH($B$3,NORMATIVOS!$C$1:$W$1,0))="En proceso")+--(INDEX(NORMATIVOS!$C$185:$W$185,1,MATCH($B$3,NORMATIVOS!$C$1:$W$1,0))="En proceso")+--(INDEX(NORMATIVOS!$C$186:$W$186,1,MATCH($B$3,NORMATIVOS!$C$1:$W$1,0))="En proceso")+--(INDEX(NORMATIVOS!$C$187:$W$187,1,MATCH($B$3,NORMATIVOS!$C$1:$W$1,0))="En proceso")+--(INDEX(NORMATIVOS!$C$188:$W$188,1,MATCH($B$3,NORMATIVOS!$C$1:$W$1,0))="En proceso")+--(INDEX(NORMATIVOS!$C$189:$W$189,1,MATCH($B$3,NORMATIVOS!$C$1:$W$1,0))="En proceso")+--(INDEX(NORMATIVOS!$C$190:$W$190,1,MATCH($B$3,NORMATIVOS!$C$1:$W$1,0))="En proceso")+--(INDEX(NORMATIVOS!$C$191:$W$191,1,MATCH($B$3,NORMATIVOS!$C$1:$W$1,0))="En proceso")+--(INDEX(NORMATIVOS!$C$192:$W$192,1,MATCH($B$3,NORMATIVOS!$C$1:$W$1,0))="En proceso") -> 0 | G17: =--(INDEX(NORMATIVOS!$C$175:$W$175,1,MATCH($B$3,NORMATIVOS!$C$1:$W$1,0))="Proyección")+--(INDEX(NORMATIVOS!$C$176:$W$176,1,MATCH($B$3,NORMATIVOS!$C$1:$W$1,0))="Proyección")+--(INDEX(NORMATIVOS!$C$177:$W$177,1,MATCH($B$3,NORMATIVOS!$C$1:$W$1,0))="Proyección")+--(INDEX(NORMATIVOS!$C$178:$W$178,1,MATCH($B$3,NORMATIVOS!$C$1:$W$1,0))="Proyección")+--(INDEX(NORMATIVOS!$C$179:$W$179,1,MATCH($B$3,NORMATIVOS!$C$1:$W$1,0))="Proyección")+--(INDEX(NORMATIVOS!$C$180:$W$180,1,MATCH($B$3,NORMATIVOS!$C$1:$W$1,0))="Proyección")+--(INDEX(NORMATIVOS!$C$181:$W$181,1,MATCH($B$3,NORMATIVOS!$C$1:$W$1,0))="Proyección")+--(INDEX(NORMATIVOS!$C$182:$W$182,1,MATCH($B$3,NORMATIVOS!$C$1:$W$1,0))="Proyección")+--(INDEX(NORMATIVOS!$C$183:$W$183,1,MATCH($B$3,NORMATIVOS!$C$1:$W$1,0))="Proyección")+--(INDEX(NORMATIVOS!$C$184:$W$184,1,MATCH($B$3,NORMATIVOS!$C$1:$W$1,0))="Proyección")+--(INDEX(NORMATIVOS!$C$185:$W$185,1,MATCH($B$3,NORMATIVOS!$C$1:$W$1,0))="Proyección")+--(INDEX(NORMATIVOS!$C$186:$W$186,1,MATCH($B$3,NORMATIVOS!$C$1:$W$1,0))="Proyección")+--(INDEX(NORMATIVOS!$C$187:$W$187,1,MATCH($B$3,NORMATIVOS!$C$1:$W$1,0))="Proyección")+--(INDEX(NORMATIVOS!$C$188:$W$188,1,MATCH($B$3,NORMATIVOS!$C$1:$W$1,0))="Proyección")+--(INDEX(NORMATIVOS!$C$189:$W$189,1,MATCH($B$3,NORMATIVOS!$C$1:$W$1,0))="Proyección")+--(INDEX(NORMATIVOS!$C$190:$W$190,1,MATCH($B$3,NORMATIVOS!$C$1:$W$1,0))="Proyección")+--(INDEX(NORMATIVOS!$C$191:$W$191,1,MATCH($B$3,NORMATIVOS!$C$1:$W$1,0))="Proyección")+--(INDEX(NORMATIVOS!$C$192:$W$192,1,MATCH($B$3,NORMATIVOS!$C$1:$W$1,0))="Proyección") -> 18 | H17: =IFERROR(E17/(E17+F17+G17),0) -> 0
